2021-05-18 23:33:57,015 - WARNING - telegram.vendor.ptb_urllib3.urllib3.connectionpool - Retrying (Retry(total=2, connect=None, read=None, redirect=None)) after connection broken by 'NewConnectionError('<telegram.vendor.ptb_urllib3.urllib3.connection.VerifiedHTTPSConnection object at 0x114597e10>: Failed to establish a new connection: [Errno 50] Network is down')': /bot1836642794:AAFZGQTSM4Z4zoNUoqf5uYXhofjg0V9i9bI/getUpdates
2021-05-18 23:35:10,247 - WARNING - telegram.vendor.ptb_urllib3.urllib3.connectionpool - Retrying (Retry(total=2, connect=None, read=None, redirect=None)) after connection broken by 'NewConnectionError('<telegram.vendor.ptb_urllib3.urllib3.connection.VerifiedHTTPSConnection object at 0x113d63150>: Failed to establish a new connection: [Errno 50] Network is down')': /bot1836642794:AAFZGQTSM4Z4zoNUoqf5uYXhofjg0V9i9bI/getUpdates
2021-05-18 23:35:10,251 - WARNING - telegram.vendor.ptb_urllib3.urllib3.connectionpool - Retrying (Retry(total=1, connect=None, read=None, redirect=None)) after connection broken by 'NewConnectionError('<telegram.vendor.ptb_urllib3.urllib3.connection.VerifiedHTTPSConnection object at 0x114468090>: Failed to establish a new connection: [Errno 50] Network is down')': /bot1836642794:AAFZGQTSM4Z4zoNUoqf5uYXhofjg0V9i9bI/getUpdates
2021-05-18 23:35:10,255 - WARNING - telegram.vendor.ptb_urllib3.urllib3.connectionpool - Retrying (Retry(total=0, connect=None, read=None, redirect=None)) after connection broken by 'NewConnectionError('<telegram.vendor.ptb_urllib3.urllib3.connection.VerifiedHTTPSConnection object at 0x107b3b710>: Failed to establish a new connection: [Errno 50] Network is down')': /bot1836642794:AAFZGQTSM4Z4zoNUoqf5uYXhofjg0V9i9bI/getUpdates
2021-05-18 23:35:10,259 - ERROR - telegram.ext.updater - Error while getting Updates: urllib3 HTTPError HTTPSConnectionPool(host='api.telegram.org', port=443): Max retries exceeded with url: /bot1836642794:AAFZGQTSM4Z4zoNUoqf5uYXhofjg0V9i9bI/getUpdates (Caused by NewConnectionError('<telegram.vendor.ptb_urllib3.urllib3.connection.VerifiedHTTPSConnection object at 0x107b3b850>: Failed to establish a new connection: [Errno 50] Network is down'))
2021-05-18 23:35:10,259 - ERROR - root - urllib3 HTTPError HTTPSConnectionPool(host='api.telegram.org', port=443): Max retries exceeded with url: /bot1836642794:AAFZGQTSM4Z4zoNUoqf5uYXhofjg0V9i9bI/getUpdates (Caused by NewConnectionError('<telegram.vendor.ptb_urllib3.urllib3.connection.VerifiedHTTPSConnection object at 0x107b3b850>: Failed to establish a new connection: [Errno 50] Network is down')) - Class: TelegramBot - None
2021-05-18 23:36:18,024 - WARNING - telegram.vendor.ptb_urllib3.urllib3.connectionpool - Retrying (Retry(total=2, connect=None, read=None, redirect=None)) after connection broken by 'NewConnectionError('<telegram.vendor.ptb_urllib3.urllib3.connection.VerifiedHTTPSConnection object at 0x114585890>: Failed to establish a new connection: [Errno 50] Network is down')': /bot1836642794:AAFZGQTSM4Z4zoNUoqf5uYXhofjg0V9i9bI/getUpdates
2021-05-18 23:36:18,029 - WARNING - telegram.vendor.ptb_urllib3.urllib3.connectionpool - Retrying (Retry(total=1, connect=None, read=None, redirect=None)) after connection broken by 'NewConnectionError('<telegram.vendor.ptb_urllib3.urllib3.connection.VerifiedHTTPSConnection object at 0x114585e10>: Failed to establish a new connection: [Errno 50] Network is down')': /bot1836642794:AAFZGQTSM4Z4zoNUoqf5uYXhofjg0V9i9bI/getUpdates
2021-05-18 23:36:18,037 - WARNING - telegram.vendor.ptb_urllib3.urllib3.connectionpool - Retrying (Retry(total=0, connect=None, read=None, redirect=None)) after connection broken by 'NewConnectionError('<telegram.vendor.ptb_urllib3.urllib3.connection.VerifiedHTTPSConnection object at 0x114585f10>: Failed to establish a new connection: [Errno 50] Network is down')': /bot1836642794:AAFZGQTSM4Z4zoNUoqf5uYXhofjg0V9i9bI/getUpdates
2021-05-18 23:36:18,172 - ERROR - telegram.ext.updater - Error while getting Updates: urllib3 HTTPError HTTPSConnectionPool(host='api.telegram.org', port=443): Max retries exceeded with url: /bot1836642794:AAFZGQTSM4Z4zoNUoqf5uYXhofjg0V9i9bI/getUpdates (Caused by NewConnectionError('<telegram.vendor.ptb_urllib3.urllib3.connection.VerifiedHTTPSConnection object at 0x114585a90>: Failed to establish a new connection: [Errno 50] Network is down'))
2021-05-18 23:36:18,173 - ERROR - root - urllib3 HTTPError HTTPSConnectionPool(host='api.telegram.org', port=443): Max retries exceeded with url: /bot1836642794:AAFZGQTSM4Z4zoNUoqf5uYXhofjg0V9i9bI/getUpdates (Caused by NewConnectionError('<telegram.vendor.ptb_urllib3.urllib3.connection.VerifiedHTTPSConnection object at 0x114585a90>: Failed to establish a new connection: [Errno 50] Network is down')) - Class: TelegramBot - None
2021-05-18 23:38:08,015 - WARNING - telegram.vendor.ptb_urllib3.urllib3.connectionpool - Retrying (Retry(total=2, connect=None, read=None, redirect=None)) after connection broken by 'NewConnectionError('<telegram.vendor.ptb_urllib3.urllib3.connection.VerifiedHTTPSConnection object at 0x114471310>: Failed to establish a new connection: [Errno 50] Network is down')': /bot1836642794:AAFZGQTSM4Z4zoNUoqf5uYXhofjg0V9i9bI/getUpdates
2021-05-18 23:38:08,019 - WARNING - telegram.vendor.ptb_urllib3.urllib3.connectionpool - Retrying (Retry(total=1, connect=None, read=None, redirect=None)) after connection broken by 'NewConnectionError('<telegram.vendor.ptb_urllib3.urllib3.connection.VerifiedHTTPSConnection object at 0x114471d10>: Failed to establish a new connection: [Errno 50] Network is down')': /bot1836642794:AAFZGQTSM4Z4zoNUoqf5uYXhofjg0V9i9bI/getUpdates
2021-05-18 23:38:08,035 - WARNING - telegram.vendor.ptb_urllib3.urllib3.connectionpool - Retrying (Retry(total=0, connect=None, read=None, redirect=None)) after connection broken by 'NewConnectionError('<telegram.vendor.ptb_urllib3.urllib3.connection.VerifiedHTTPSConnection object at 0x114471c50>: Failed to establish a new connection: [Errno 50] Network is down')': /bot1836642794:AAFZGQTSM4Z4zoNUoqf5uYXhofjg0V9i9bI/getUpdates
2021-05-18 23:38:08,039 - ERROR - telegram.ext.updater - Error while getting Updates: urllib3 HTTPError HTTPSConnectionPool(host='api.telegram.org', port=443): Max retries exceeded with url: /bot1836642794:AAFZGQTSM4Z4zoNUoqf5uYXhofjg0V9i9bI/getUpdates (Caused by NewConnectionError('<telegram.vendor.ptb_urllib3.urllib3.connection.VerifiedHTTPSConnection object at 0x114471350>: Failed to establish a new connection: [Errno 50] Network is down'))
2021-05-18 23:38:08,040 - ERROR - root - urllib3 HTTPError HTTPSConnectionPool(host='api.telegram.org', port=443): Max retries exceeded with url: /bot1836642794:AAFZGQTSM4Z4zoNUoqf5uYXhofjg0V9i9bI/getUpdates (Caused by NewConnectionError('<telegram.vendor.ptb_urllib3.urllib3.connection.VerifiedHTTPSConnection object at 0x114471350>: Failed to establish a new connection: [Errno 50] Network is down')) - Class: TelegramBot - None
