2021-05-18 18:09:36,365 - ERROR - root - Timed out - {'update_id': 406256825, 'message': {'message_id': 7917, 'date': 1620332165, 'chat': {'id': -1001216334216, 'type': 'supergroup', 'title': 'KRİPTO PUSULA', 'username': 'kriptopusulasi'}, 'text': '/p btc', 'entities': [{'type': 'bot_command', 'offset': 0, 'length': 3}, {'type': 'bot_command', 'offset': 9, 'length': 2}], 'caption_entities': [], 'photo': [], 'new_chat_members': [], 'new_chat_photo': [], 'delete_chat_photo': False, 'group_chat_created': False, 'supergroup_chat_created': False, 'channel_chat_created': False, 'from': {'id': 1087968824, 'first_name': 'Group', 'is_bot': True, 'username': 'GroupAnonymousBot'}}}
2021-05-18 18:09:36,367 - ERROR - JobQueue - An uncaught error was raised while executing job _send_msg
Traceback (most recent call last):
  File "/Users/ahmetcnd/.local/share/virtualenvs/openCryptoBot-D8P4_yx3/lib/python3.7/site-packages/telegram/vendor/ptb_urllib3/urllib3/connectionpool.py", line 402, in _make_request
    six.raise_from(e, None)
  File "<string>", line 2, in raise_from
  File "/Users/ahmetcnd/.local/share/virtualenvs/openCryptoBot-D8P4_yx3/lib/python3.7/site-packages/telegram/vendor/ptb_urllib3/urllib3/connectionpool.py", line 398, in _make_request
    httplib_response = conn.getresponse()
  File "/Users/ahmetcnd/.pyenv/versions/3.7.10/lib/python3.7/http/client.py", line 1369, in getresponse
    response.begin()
  File "/Users/ahmetcnd/.pyenv/versions/3.7.10/lib/python3.7/http/client.py", line 310, in begin
    version, status, reason = self._read_status()
  File "/Users/ahmetcnd/.pyenv/versions/3.7.10/lib/python3.7/http/client.py", line 271, in _read_status
    line = str(self.fp.readline(_MAXLINE + 1), "iso-8859-1")
  File "/Users/ahmetcnd/.pyenv/versions/3.7.10/lib/python3.7/socket.py", line 589, in readinto
    return self._sock.recv_into(b)
  File "/Users/ahmetcnd/.pyenv/versions/3.7.10/lib/python3.7/ssl.py", line 1071, in recv_into
    return self.read(nbytes, buffer)
  File "/Users/ahmetcnd/.pyenv/versions/3.7.10/lib/python3.7/ssl.py", line 929, in read
    return self._sslobj.read(len, buffer)
socket.timeout: The read operation timed out

During handling of the above exception, another exception occurred:

Traceback (most recent call last):
  File "/Users/ahmetcnd/.local/share/virtualenvs/openCryptoBot-D8P4_yx3/lib/python3.7/site-packages/telegram/utils/request.py", line 203, in _request_wrapper
    resp = self._con_pool.request(*args, **kwargs)
  File "/Users/ahmetcnd/.local/share/virtualenvs/openCryptoBot-D8P4_yx3/lib/python3.7/site-packages/telegram/vendor/ptb_urllib3/urllib3/request.py", line 70, in request
    **urlopen_kw)
  File "/Users/ahmetcnd/.local/share/virtualenvs/openCryptoBot-D8P4_yx3/lib/python3.7/site-packages/telegram/vendor/ptb_urllib3/urllib3/request.py", line 148, in request_encode_body
    return self.urlopen(method, url, **extra_kw)
  File "/Users/ahmetcnd/.local/share/virtualenvs/openCryptoBot-D8P4_yx3/lib/python3.7/site-packages/telegram/vendor/ptb_urllib3/urllib3/poolmanager.py", line 244, in urlopen
    response = conn.urlopen(method, u.request_uri, **kw)
  File "/Users/ahmetcnd/.local/share/virtualenvs/openCryptoBot-D8P4_yx3/lib/python3.7/site-packages/telegram/vendor/ptb_urllib3/urllib3/connectionpool.py", line 666, in urlopen
    _stacktrace=sys.exc_info()[2])
  File "/Users/ahmetcnd/.local/share/virtualenvs/openCryptoBot-D8P4_yx3/lib/python3.7/site-packages/telegram/vendor/ptb_urllib3/urllib3/util/retry.py", line 347, in increment
    raise six.reraise(type(error), error, _stacktrace)
  File "/Users/ahmetcnd/.local/share/virtualenvs/openCryptoBot-D8P4_yx3/lib/python3.7/site-packages/telegram/vendor/ptb_urllib3/urllib3/packages/six.py", line 686, in reraise
    raise value
  File "/Users/ahmetcnd/.local/share/virtualenvs/openCryptoBot-D8P4_yx3/lib/python3.7/site-packages/telegram/vendor/ptb_urllib3/urllib3/connectionpool.py", line 617, in urlopen
    chunked=chunked)
  File "/Users/ahmetcnd/.local/share/virtualenvs/openCryptoBot-D8P4_yx3/lib/python3.7/site-packages/telegram/vendor/ptb_urllib3/urllib3/connectionpool.py", line 405, in _make_request
    exc_cls=ReadTimeoutError)
  File "/Users/ahmetcnd/.local/share/virtualenvs/openCryptoBot-D8P4_yx3/lib/python3.7/site-packages/telegram/vendor/ptb_urllib3/urllib3/connectionpool.py", line 321, in _raise_timeout
    raise exc_cls(*args)
telegram.vendor.ptb_urllib3.urllib3.exceptions.ReadTimeoutError: HTTPSConnectionPool(host='api.telegram.org', port=443): Read timed out. (read timeout=5.0)

During handling of the above exception, another exception occurred:

Traceback (most recent call last):
  File "/Users/ahmetcnd/Documents/telegrambot/openCryptoBot/opencryptobot/plugins/repeat.py", line 169, in _send_msg
    plgn.get_action(bot, updt, args=args)
  File "/Users/ahmetcnd/Documents/telegrambot/openCryptoBot/opencryptobot/plugin.py", line 106, in _save_data
    return func(self, bot, update, **kwargs)
  File "/Users/ahmetcnd/Documents/telegrambot/openCryptoBot/opencryptobot/plugin.py", line 73, in _send_typing_action
    return func(self, bot, update, **kwargs)
  File "/Users/ahmetcnd/Documents/telegrambot/openCryptoBot/opencryptobot/plugins/price.py", line 149, in get_action
    self.send_msg(msg, update, keywords)
  File "/Users/ahmetcnd/Documents/telegrambot/openCryptoBot/opencryptobot/plugin.py", line 144, in send_msg
    disable_notification=not notify)
  File "/Users/ahmetcnd/.local/share/virtualenvs/openCryptoBot-D8P4_yx3/lib/python3.7/site-packages/telegram/message.py", line 455, in reply_text
    return self.bot.send_message(self.chat_id, *args, **kwargs)
  File "/Users/ahmetcnd/.local/share/virtualenvs/openCryptoBot-D8P4_yx3/lib/python3.7/site-packages/telegram/bot.py", line 65, in decorator
    result = func(self, *args, **kwargs)
  File "/Users/ahmetcnd/.local/share/virtualenvs/openCryptoBot-D8P4_yx3/lib/python3.7/site-packages/telegram/bot.py", line 90, in decorator
    result = self._request.post(url, data, timeout=kwargs.get('timeout'))
  File "/Users/ahmetcnd/.local/share/virtualenvs/openCryptoBot-D8P4_yx3/lib/python3.7/site-packages/telegram/utils/request.py", line 309, in post
    headers={'Content-Type': 'application/json'})
  File "/Users/ahmetcnd/.local/share/virtualenvs/openCryptoBot-D8P4_yx3/lib/python3.7/site-packages/telegram/utils/request.py", line 205, in _request_wrapper
    raise TimedOut()
telegram.error.TimedOut: Timed out

During handling of the above exception, another exception occurred:

Traceback (most recent call last):
  File "/Users/ahmetcnd/.local/share/virtualenvs/openCryptoBot-D8P4_yx3/lib/python3.7/site-packages/telegram/ext/jobqueue.py", line 245, in tick
    job.run(self.bot)
  File "/Users/ahmetcnd/.local/share/virtualenvs/openCryptoBot-D8P4_yx3/lib/python3.7/site-packages/telegram/ext/jobqueue.py", line 372, in run
    self.callback(bot, self)
  File "/Users/ahmetcnd/Documents/telegrambot/openCryptoBot/opencryptobot/plugins/repeat.py", line 172, in _send_msg
    self.tgb.db.delete_rep(rep)
  File "/Users/ahmetcnd/Documents/telegrambot/openCryptoBot/opencryptobot/database.py", line 194, in delete_rep
    [repeater_id])
sqlite3.InterfaceError: Error binding parameter 0 - probably unsupported type.
2021-05-18 18:09:37,285 - ERROR - root - Replied message not found - {'update_id': 406256827, 'message': {'message_id': 7920, 'date': 1620332268, 'chat': {'id': -1001216334216, 'type': 'supergroup', 'title': 'KRİPTO PUSULA', 'username': 'kriptopusulasi'}, 'text': '/p eth', 'entities': [{'type': 'bot_command', 'offset': 0, 'length': 3}, {'type': 'bot_command', 'offset': 9, 'length': 2}], 'caption_entities': [], 'photo': [], 'new_chat_members': [], 'new_chat_photo': [], 'delete_chat_photo': False, 'group_chat_created': False, 'supergroup_chat_created': False, 'channel_chat_created': False, 'from': {'id': 1087968824, 'first_name': 'Group', 'is_bot': True, 'username': 'GroupAnonymousBot'}}}
2021-05-18 18:09:37,286 - ERROR - JobQueue - An uncaught error was raised while executing job _send_msg
Traceback (most recent call last):
  File "/Users/ahmetcnd/Documents/telegrambot/openCryptoBot/opencryptobot/plugins/repeat.py", line 169, in _send_msg
    plgn.get_action(bot, updt, args=args)
  File "/Users/ahmetcnd/Documents/telegrambot/openCryptoBot/opencryptobot/plugin.py", line 106, in _save_data
    return func(self, bot, update, **kwargs)
  File "/Users/ahmetcnd/Documents/telegrambot/openCryptoBot/opencryptobot/plugin.py", line 73, in _send_typing_action
    return func(self, bot, update, **kwargs)
  File "/Users/ahmetcnd/Documents/telegrambot/openCryptoBot/opencryptobot/plugins/price.py", line 149, in get_action
    self.send_msg(msg, update, keywords)
  File "/Users/ahmetcnd/Documents/telegrambot/openCryptoBot/opencryptobot/plugin.py", line 144, in send_msg
    disable_notification=not notify)
  File "/Users/ahmetcnd/.local/share/virtualenvs/openCryptoBot-D8P4_yx3/lib/python3.7/site-packages/telegram/message.py", line 455, in reply_text
    return self.bot.send_message(self.chat_id, *args, **kwargs)
  File "/Users/ahmetcnd/.local/share/virtualenvs/openCryptoBot-D8P4_yx3/lib/python3.7/site-packages/telegram/bot.py", line 65, in decorator
    result = func(self, *args, **kwargs)
  File "/Users/ahmetcnd/.local/share/virtualenvs/openCryptoBot-D8P4_yx3/lib/python3.7/site-packages/telegram/bot.py", line 90, in decorator
    result = self._request.post(url, data, timeout=kwargs.get('timeout'))
  File "/Users/ahmetcnd/.local/share/virtualenvs/openCryptoBot-D8P4_yx3/lib/python3.7/site-packages/telegram/utils/request.py", line 309, in post
    headers={'Content-Type': 'application/json'})
  File "/Users/ahmetcnd/.local/share/virtualenvs/openCryptoBot-D8P4_yx3/lib/python3.7/site-packages/telegram/utils/request.py", line 223, in _request_wrapper
    raise BadRequest(message)
telegram.error.BadRequest: Replied message not found

During handling of the above exception, another exception occurred:

Traceback (most recent call last):
  File "/Users/ahmetcnd/.local/share/virtualenvs/openCryptoBot-D8P4_yx3/lib/python3.7/site-packages/telegram/ext/jobqueue.py", line 245, in tick
    job.run(self.bot)
  File "/Users/ahmetcnd/.local/share/virtualenvs/openCryptoBot-D8P4_yx3/lib/python3.7/site-packages/telegram/ext/jobqueue.py", line 372, in run
    self.callback(bot, self)
  File "/Users/ahmetcnd/Documents/telegrambot/openCryptoBot/opencryptobot/plugins/repeat.py", line 172, in _send_msg
    self.tgb.db.delete_rep(rep)
  File "/Users/ahmetcnd/Documents/telegrambot/openCryptoBot/opencryptobot/database.py", line 194, in delete_rep
    [repeater_id])
sqlite3.InterfaceError: Error binding parameter 0 - probably unsupported type.
2021-05-18 18:22:12,167 - WARNING - telegram.vendor.ptb_urllib3.urllib3.connectionpool - Retrying (Retry(total=2, connect=None, read=None, redirect=None)) after connection broken by 'NewConnectionError('<telegram.vendor.ptb_urllib3.urllib3.connection.VerifiedHTTPSConnection object at 0x1145852d0>: Failed to establish a new connection: [Errno 50] Network is down')': /bot1836642794:AAFZGQTSM4Z4zoNUoqf5uYXhofjg0V9i9bI/getUpdates
2021-05-18 18:22:12,174 - WARNING - telegram.vendor.ptb_urllib3.urllib3.connectionpool - Retrying (Retry(total=1, connect=None, read=None, redirect=None)) after connection broken by 'NewConnectionError('<telegram.vendor.ptb_urllib3.urllib3.connection.VerifiedHTTPSConnection object at 0x114585490>: Failed to establish a new connection: [Errno 50] Network is down')': /bot1836642794:AAFZGQTSM4Z4zoNUoqf5uYXhofjg0V9i9bI/getUpdates
2021-05-18 18:22:12,176 - WARNING - telegram.vendor.ptb_urllib3.urllib3.connectionpool - Retrying (Retry(total=0, connect=None, read=None, redirect=None)) after connection broken by 'NewConnectionError('<telegram.vendor.ptb_urllib3.urllib3.connection.VerifiedHTTPSConnection object at 0x114585cd0>: Failed to establish a new connection: [Errno 50] Network is down')': /bot1836642794:AAFZGQTSM4Z4zoNUoqf5uYXhofjg0V9i9bI/getUpdates
2021-05-18 18:22:12,179 - ERROR - telegram.ext.updater - Error while getting Updates: urllib3 HTTPError HTTPSConnectionPool(host='api.telegram.org', port=443): Max retries exceeded with url: /bot1836642794:AAFZGQTSM4Z4zoNUoqf5uYXhofjg0V9i9bI/getUpdates (Caused by NewConnectionError('<telegram.vendor.ptb_urllib3.urllib3.connection.VerifiedHTTPSConnection object at 0x114585390>: Failed to establish a new connection: [Errno 50] Network is down'))
2021-05-18 18:22:12,179 - ERROR - root - urllib3 HTTPError HTTPSConnectionPool(host='api.telegram.org', port=443): Max retries exceeded with url: /bot1836642794:AAFZGQTSM4Z4zoNUoqf5uYXhofjg0V9i9bI/getUpdates (Caused by NewConnectionError('<telegram.vendor.ptb_urllib3.urllib3.connection.VerifiedHTTPSConnection object at 0x114585390>: Failed to establish a new connection: [Errno 50] Network is down')) - Class: TelegramBot - None
2021-05-18 18:29:32,024 - WARNING - telegram.vendor.ptb_urllib3.urllib3.connectionpool - Retrying (Retry(total=2, connect=None, read=None, redirect=None)) after connection broken by 'NewConnectionError('<telegram.vendor.ptb_urllib3.urllib3.connection.VerifiedHTTPSConnection object at 0x113d63cd0>: Failed to establish a new connection: [Errno 50] Network is down')': /bot1836642794:AAFZGQTSM4Z4zoNUoqf5uYXhofjg0V9i9bI/getUpdates
2021-05-18 18:29:32,173 - WARNING - telegram.vendor.ptb_urllib3.urllib3.connectionpool - Retrying (Retry(total=1, connect=None, read=None, redirect=None)) after connection broken by 'NewConnectionError('<telegram.vendor.ptb_urllib3.urllib3.connection.VerifiedHTTPSConnection object at 0x114431890>: Failed to establish a new connection: [Errno 50] Network is down')': /bot1836642794:AAFZGQTSM4Z4zoNUoqf5uYXhofjg0V9i9bI/getUpdates
2021-05-18 18:29:32,175 - WARNING - telegram.vendor.ptb_urllib3.urllib3.connectionpool - Retrying (Retry(total=0, connect=None, read=None, redirect=None)) after connection broken by 'NewConnectionError('<telegram.vendor.ptb_urllib3.urllib3.connection.VerifiedHTTPSConnection object at 0x114431710>: Failed to establish a new connection: [Errno 50] Network is down')': /bot1836642794:AAFZGQTSM4Z4zoNUoqf5uYXhofjg0V9i9bI/getUpdates
2021-05-18 18:29:32,177 - ERROR - telegram.ext.updater - Error while getting Updates: urllib3 HTTPError HTTPSConnectionPool(host='api.telegram.org', port=443): Max retries exceeded with url: /bot1836642794:AAFZGQTSM4Z4zoNUoqf5uYXhofjg0V9i9bI/getUpdates (Caused by NewConnectionError('<telegram.vendor.ptb_urllib3.urllib3.connection.VerifiedHTTPSConnection object at 0x114431590>: Failed to establish a new connection: [Errno 50] Network is down'))
2021-05-18 18:29:32,177 - ERROR - root - urllib3 HTTPError HTTPSConnectionPool(host='api.telegram.org', port=443): Max retries exceeded with url: /bot1836642794:AAFZGQTSM4Z4zoNUoqf5uYXhofjg0V9i9bI/getUpdates (Caused by NewConnectionError('<telegram.vendor.ptb_urllib3.urllib3.connection.VerifiedHTTPSConnection object at 0x114431590>: Failed to establish a new connection: [Errno 50] Network is down')) - Class: TelegramBot - None
2021-05-18 18:37:09,017 - WARNING - telegram.vendor.ptb_urllib3.urllib3.connectionpool - Retrying (Retry(total=2, connect=None, read=None, redirect=None)) after connection broken by 'NewConnectionError('<telegram.vendor.ptb_urllib3.urllib3.connection.VerifiedHTTPSConnection object at 0x114585810>: Failed to establish a new connection: [Errno 50] Network is down')': /bot1836642794:AAFZGQTSM4Z4zoNUoqf5uYXhofjg0V9i9bI/getUpdates
2021-05-18 18:37:09,170 - WARNING - telegram.vendor.ptb_urllib3.urllib3.connectionpool - Retrying (Retry(total=1, connect=None, read=None, redirect=None)) after connection broken by 'NewConnectionError('<telegram.vendor.ptb_urllib3.urllib3.connection.VerifiedHTTPSConnection object at 0x107b3b910>: Failed to establish a new connection: [Errno 50] Network is down')': /bot1836642794:AAFZGQTSM4Z4zoNUoqf5uYXhofjg0V9i9bI/getUpdates
2021-05-18 18:37:09,179 - WARNING - telegram.vendor.ptb_urllib3.urllib3.connectionpool - Retrying (Retry(total=0, connect=None, read=None, redirect=None)) after connection broken by 'NewConnectionError('<telegram.vendor.ptb_urllib3.urllib3.connection.VerifiedHTTPSConnection object at 0x107b3b610>: Failed to establish a new connection: [Errno 50] Network is down')': /bot1836642794:AAFZGQTSM4Z4zoNUoqf5uYXhofjg0V9i9bI/getUpdates
2021-05-18 18:37:09,182 - ERROR - telegram.ext.updater - Error while getting Updates: urllib3 HTTPError HTTPSConnectionPool(host='api.telegram.org', port=443): Max retries exceeded with url: /bot1836642794:AAFZGQTSM4Z4zoNUoqf5uYXhofjg0V9i9bI/getUpdates (Caused by NewConnectionError('<telegram.vendor.ptb_urllib3.urllib3.connection.VerifiedHTTPSConnection object at 0x107b3b850>: Failed to establish a new connection: [Errno 50] Network is down'))
2021-05-18 18:37:09,183 - ERROR - root - urllib3 HTTPError HTTPSConnectionPool(host='api.telegram.org', port=443): Max retries exceeded with url: /bot1836642794:AAFZGQTSM4Z4zoNUoqf5uYXhofjg0V9i9bI/getUpdates (Caused by NewConnectionError('<telegram.vendor.ptb_urllib3.urllib3.connection.VerifiedHTTPSConnection object at 0x107b3b850>: Failed to establish a new connection: [Errno 50] Network is down')) - Class: TelegramBot - None
2021-05-18 18:59:32,584 - WARNING - telegram.vendor.ptb_urllib3.urllib3.connectionpool - Retrying (Retry(total=2, connect=None, read=None, redirect=None)) after connection broken by 'NewConnectionError('<telegram.vendor.ptb_urllib3.urllib3.connection.VerifiedHTTPSConnection object at 0x1144317d0>: Failed to establish a new connection: [Errno 50] Network is down')': /bot1836642794:AAFZGQTSM4Z4zoNUoqf5uYXhofjg0V9i9bI/getUpdates
2021-05-18 18:59:32,587 - WARNING - telegram.vendor.ptb_urllib3.urllib3.connectionpool - Retrying (Retry(total=1, connect=None, read=None, redirect=None)) after connection broken by 'NewConnectionError('<telegram.vendor.ptb_urllib3.urllib3.connection.VerifiedHTTPSConnection object at 0x1144f0b10>: Failed to establish a new connection: [Errno 50] Network is down')': /bot1836642794:AAFZGQTSM4Z4zoNUoqf5uYXhofjg0V9i9bI/getUpdates
2021-05-18 18:59:32,590 - WARNING - telegram.vendor.ptb_urllib3.urllib3.connectionpool - Retrying (Retry(total=0, connect=None, read=None, redirect=None)) after connection broken by 'NewConnectionError('<telegram.vendor.ptb_urllib3.urllib3.connection.VerifiedHTTPSConnection object at 0x107ae22d0>: Failed to establish a new connection: [Errno 50] Network is down')': /bot1836642794:AAFZGQTSM4Z4zoNUoqf5uYXhofjg0V9i9bI/getUpdates
2021-05-18 18:59:32,592 - ERROR - telegram.ext.updater - Error while getting Updates: urllib3 HTTPError HTTPSConnectionPool(host='api.telegram.org', port=443): Max retries exceeded with url: /bot1836642794:AAFZGQTSM4Z4zoNUoqf5uYXhofjg0V9i9bI/getUpdates (Caused by NewConnectionError('<telegram.vendor.ptb_urllib3.urllib3.connection.VerifiedHTTPSConnection object at 0x107ae2f10>: Failed to establish a new connection: [Errno 50] Network is down'))
2021-05-18 18:59:32,593 - ERROR - root - urllib3 HTTPError HTTPSConnectionPool(host='api.telegram.org', port=443): Max retries exceeded with url: /bot1836642794:AAFZGQTSM4Z4zoNUoqf5uYXhofjg0V9i9bI/getUpdates (Caused by NewConnectionError('<telegram.vendor.ptb_urllib3.urllib3.connection.VerifiedHTTPSConnection object at 0x107ae2f10>: Failed to establish a new connection: [Errno 50] Network is down')) - Class: TelegramBot - None
