2021-05-19 15:47:53,060 - WARNING - telegram.vendor.ptb_urllib3.urllib3.connectionpool - Retrying (Retry(total=2, connect=None, read=None, redirect=None)) after connection broken by 'NewConnectionError('<telegram.vendor.ptb_urllib3.urllib3.connection.VerifiedHTTPSConnection object at 0x1145ab190>: Failed to establish a new connection: [Errno 50] Network is down')': /bot1836642794:AAFZGQTSM4Z4zoNUoqf5uYXhofjg0V9i9bI/getUpdates
2021-05-19 16:03:32,604 - ERROR - root - Timed out - {'update_id': 406258921, 'message': {'message_id': 482, 'date': 1621429401, 'chat': {'id': 1062954233, 'type': 'private', 'username': 'paemmisyon', 'first_name': 'Paemisyon'}, 'text': '/p btc', 'entities': [{'type': 'bot_command', 'offset': 0, 'length': 2}], 'caption_entities': [], 'photo': [], 'new_chat_members': [], 'new_chat_photo': [], 'delete_chat_photo': False, 'group_chat_created': False, 'supergroup_chat_created': False, 'channel_chat_created': False, 'from': {'id': 1062954233, 'first_name': 'Paemisyon', 'is_bot': False, 'username': 'paemmisyon', 'language_code': 'tr'}}}
2021-05-19 16:03:45,620 - INFO - root - Plugin 'Start' added
2021-05-19 16:03:45,622 - INFO - root - Plugin 'Feedback' added
2021-05-19 16:03:45,623 - INFO - root - Plugin 'Admin' added
2021-05-19 16:03:45,631 - INFO - root - Plugin 'Events' added
2021-05-19 16:03:45,631 - INFO - root - Plugin 'Market' added
2021-05-19 16:03:45,634 - INFO - root - Plugin 'Decentralized' added
2021-05-19 16:03:45,637 - INFO - root - Plugin 'Description' added
2021-05-19 16:03:45,640 - INFO - root - Plugin 'Roi' added
2021-05-19 16:03:45,658 - INFO - root - Plugin 'Compare' added
2021-05-19 16:03:45,658 - INFO - root - Plugin 'Shutdown' added
2021-05-19 16:03:45,660 - INFO - root - Plugin 'Bpmn' added
2021-05-19 16:03:45,662 - INFO - root - Plugin 'Change' added
2021-05-19 16:03:45,664 - INFO - root - Plugin 'Ico' added
2021-05-19 16:03:45,666 - INFO - root - Plugin 'Developer' added
2021-05-19 16:03:45,667 - INFO - root - Plugin 'Team' added
2021-05-19 16:03:45,668 - INFO - root - Plugin 'Social' added
2021-05-19 16:03:45,668 - INFO - root - Plugin 'Manual' added
2021-05-19 16:03:45,670 - INFO - root - Plugin 'Top' added
2021-05-19 16:03:45,673 - INFO - root - Plugin 'Search' added
2021-05-19 16:03:45,673 - WARNING - root - File 'alert.py' can't be loaded as a plugin: module 'opencryptobot.plugins.alert' has no attribute 'Alert'
2021-05-19 16:03:45,675 - INFO - root - Plugin 'Wallets' added
2021-05-19 16:03:45,676 - INFO - root - Plugin 'Marketcap' added
2021-05-19 16:03:45,676 - INFO - root - Plugin 'Donate' added
2021-05-19 16:03:45,679 - INFO - root - Plugin 'Alltimehigh' added
2021-05-19 16:03:45,681 - INFO - root - Plugin 'Help' added
2021-05-19 16:03:45,681 - INFO - root - Plugin 'Value' added
2021-05-19 16:03:45,685 - INFO - root - Plugin 'Logfile' added
2021-05-19 16:03:45,694 - INFO - root - Plugin 'Pools' added
2021-05-19 16:03:45,695 - INFO - root - Plugin 'Repeat' added
2021-05-19 16:03:45,697 - INFO - root - Plugin 'Restart' added
2021-05-19 16:03:45,698 - INFO - root - Plugin 'Volume' added
2021-05-19 16:03:45,698 - INFO - root - Plugin 'Update' added
2021-05-19 16:03:45,702 - INFO - root - Plugin 'Fiftyone' added
2021-05-19 16:03:45,704 - INFO - root - Plugin 'People' added
2021-05-19 16:03:45,709 - INFO - root - Plugin 'Best' added
2021-05-19 16:03:45,711 - INFO - root - Plugin 'Worst' added
2021-05-19 16:03:45,772 - INFO - root - Plugin 'Backup' added
2021-05-19 16:03:45,772 - INFO - root - Plugin 'Info' added
2021-05-19 16:03:45,774 - INFO - root - Plugin 'About' added
2021-05-19 16:03:45,775 - INFO - root - Plugin 'Price' added
2021-05-19 16:03:45,779 - INFO - root - Plugin 'Exchanges' added
2021-05-19 16:03:45,780 - INFO - root - Plugin 'News' added
2021-05-19 16:03:45,782 - INFO - root - Plugin 'Stats' added
2021-05-19 16:03:53,687 - INFO - root - Plugin 'Whitepaper' added
2021-05-19 16:03:53,971 - INFO - root - Plugin 'Twitter' added
2021-05-19 16:03:59,910 - INFO - root - Plugin 'Global' added
2021-05-19 16:03:59,912 - INFO - root - Plugin 'Chart' added
2021-05-19 16:03:59,918 - INFO - root - Plugin 'Trends' added
2021-05-19 16:04:00,025 - INFO - root - Plugin 'Candlestick' added
2021-05-19 16:04:00,030 - INFO - root - Starting Caching
2021-05-19 16:04:03,468 - ERROR - telegram.ext.updater - Error while getting Updates: Conflict: terminated by other getUpdates request; make sure that only one bot instance is running (409)
2021-05-19 16:04:04,501 - ERROR - root - Conflict: terminated by other getUpdates request; make sure that only one bot instance is running (409) - Class: TelegramBot - None
2021-05-19 16:04:07,666 - ERROR - telegram.ext.updater - Error while getting Updates: Conflict: terminated by other getUpdates request; make sure that only one bot instance is running (409)
2021-05-19 16:04:07,668 - ERROR - root - Conflict: terminated by other getUpdates request; make sure that only one bot instance is running (409) - Class: TelegramBot - None
2021-05-19 16:04:09,627 - ERROR - telegram.ext.updater - Error while getting Updates: Conflict: terminated by other getUpdates request; make sure that only one bot instance is running (409)
2021-05-19 16:04:09,627 - ERROR - root - Conflict: terminated by other getUpdates request; make sure that only one bot instance is running (409) - Class: TelegramBot - None
2021-05-19 16:04:10,741 - ERROR - JobQueue - An uncaught error was raised while executing job refresh
Traceback (most recent call last):
  File "/Users/ahmetcnd/.local/share/virtualenvs/openCryptoBot-D8P4_yx3/lib/python3.7/site-packages/telegram/ext/jobqueue.py", line 245, in tick
    job.run(self.bot)
  File "/Users/ahmetcnd/.local/share/virtualenvs/openCryptoBot-D8P4_yx3/lib/python3.7/site-packages/telegram/ext/jobqueue.py", line 372, in run
    self.callback(bot, self)
  File "/Users/ahmetcnd/Documents/telegrambot/openCryptoBot/opencryptobot/api/apicache.py", line 23, in refresh
    APICache.refresh_coinmarketcap_coin_list()
  File "/Users/ahmetcnd/Documents/telegrambot/openCryptoBot/opencryptobot/api/apicache.py", line 39, in refresh_coinmarketcap_coin_list
    APICache.cmc_coin_list = Market().listings()["data"]
TypeError: 'JSONDecodeError' object is not subscriptable
2021-05-19 16:04:12,847 - ERROR - root - HTTPError('404 Client Error: Not Found for url: https://api.github.com/repos/None/None/releases/latest')
2021-05-19 16:04:14,859 - ERROR - telegram.ext.updater - Error while getting Updates: Conflict: terminated by other getUpdates request; make sure that only one bot instance is running (409)
2021-05-19 16:04:14,859 - ERROR - root - Conflict: terminated by other getUpdates request; make sure that only one bot instance is running (409) - Class: TelegramBot - None
2021-05-19 16:04:16,962 - ERROR - telegram.ext.updater - Error while getting Updates: Conflict: terminated by other getUpdates request; make sure that only one bot instance is running (409)
2021-05-19 16:04:16,964 - ERROR - root - Conflict: terminated by other getUpdates request; make sure that only one bot instance is running (409) - Class: TelegramBot - None
2021-05-19 16:04:23,018 - ERROR - telegram.ext.updater - Error while getting Updates: Conflict: terminated by other getUpdates request; make sure that only one bot instance is running (409)
2021-05-19 16:04:23,019 - ERROR - root - Conflict: terminated by other getUpdates request; make sure that only one bot instance is running (409) - Class: TelegramBot - None
2021-05-19 16:04:26,064 - ERROR - telegram.ext.updater - Error while getting Updates: Conflict: terminated by other getUpdates request; make sure that only one bot instance is running (409)
2021-05-19 16:04:26,064 - ERROR - root - Conflict: terminated by other getUpdates request; make sure that only one bot instance is running (409) - Class: TelegramBot - None
2021-05-19 16:04:30,141 - ERROR - telegram.ext.updater - Error while getting Updates: Conflict: terminated by other getUpdates request; make sure that only one bot instance is running (409)
2021-05-19 16:04:30,144 - ERROR - root - Conflict: terminated by other getUpdates request; make sure that only one bot instance is running (409) - Class: TelegramBot - None
2021-05-19 16:04:34,212 - ERROR - telegram.ext.updater - Error while getting Updates: Conflict: terminated by other getUpdates request; make sure that only one bot instance is running (409)
2021-05-19 16:04:34,213 - ERROR - root - Conflict: terminated by other getUpdates request; make sure that only one bot instance is running (409) - Class: TelegramBot - None
2021-05-19 16:04:39,386 - ERROR - telegram.ext.updater - Error while getting Updates: Conflict: terminated by other getUpdates request; make sure that only one bot instance is running (409)
2021-05-19 16:04:41,002 - ERROR - root - Conflict: terminated by other getUpdates request; make sure that only one bot instance is running (409) - Class: TelegramBot - None
2021-05-19 16:04:43,490 - ERROR - telegram.ext.updater - Error while getting Updates: Conflict: terminated by other getUpdates request; make sure that only one bot instance is running (409)
2021-05-19 16:04:43,491 - ERROR - root - Conflict: terminated by other getUpdates request; make sure that only one bot instance is running (409) - Class: TelegramBot - None
2021-05-19 16:04:51,606 - ERROR - telegram.ext.updater - Error while getting Updates: Conflict: terminated by other getUpdates request; make sure that only one bot instance is running (409)
2021-05-19 16:04:51,608 - ERROR - root - Conflict: terminated by other getUpdates request; make sure that only one bot instance is running (409) - Class: TelegramBot - None
2021-05-19 16:04:55,775 - ERROR - telegram.ext.updater - Error while getting Updates: Conflict: terminated by other getUpdates request; make sure that only one bot instance is running (409)
2021-05-19 16:04:55,775 - ERROR - root - Conflict: terminated by other getUpdates request; make sure that only one bot instance is running (409) - Class: TelegramBot - None
2021-05-19 16:05:08,066 - ERROR - telegram.ext.updater - Error while getting Updates: Conflict: terminated by other getUpdates request; make sure that only one bot instance is running (409)
2021-05-19 16:05:08,066 - ERROR - root - Conflict: terminated by other getUpdates request; make sure that only one bot instance is running (409) - Class: TelegramBot - None
2021-05-19 16:05:12,163 - ERROR - telegram.ext.updater - Error while getting Updates: Conflict: terminated by other getUpdates request; make sure that only one bot instance is running (409)
2021-05-19 16:05:12,164 - ERROR - root - Conflict: terminated by other getUpdates request; make sure that only one bot instance is running (409) - Class: TelegramBot - None
2021-05-19 16:05:32,737 - ERROR - telegram.ext.updater - Error while getting Updates: Conflict: terminated by other getUpdates request; make sure that only one bot instance is running (409)
2021-05-19 16:05:32,737 - ERROR - root - Conflict: terminated by other getUpdates request; make sure that only one bot instance is running (409) - Class: TelegramBot - None
2021-05-19 16:05:59,269 - ERROR - telegram.ext.updater - Error while getting Updates: Conflict: terminated by other getUpdates request; make sure that only one bot instance is running (409)
2021-05-19 16:05:59,269 - ERROR - root - Conflict: terminated by other getUpdates request; make sure that only one bot instance is running (409) - Class: TelegramBot - None
2021-05-19 16:06:03,359 - ERROR - telegram.ext.updater - Error while getting Updates: Conflict: terminated by other getUpdates request; make sure that only one bot instance is running (409)
2021-05-19 16:06:03,360 - ERROR - root - Conflict: terminated by other getUpdates request; make sure that only one bot instance is running (409) - Class: TelegramBot - None
2021-05-19 16:06:42,292 - ERROR - telegram.ext.updater - Error while getting Updates: Conflict: terminated by other getUpdates request; make sure that only one bot instance is running (409)
2021-05-19 16:06:42,293 - ERROR - root - Conflict: terminated by other getUpdates request; make sure that only one bot instance is running (409) - Class: TelegramBot - None
2021-05-19 16:06:46,367 - ERROR - telegram.ext.updater - Error while getting Updates: Conflict: terminated by other getUpdates request; make sure that only one bot instance is running (409)
2021-05-19 16:06:46,367 - ERROR - root - Conflict: terminated by other getUpdates request; make sure that only one bot instance is running (409) - Class: TelegramBot - None
2021-05-19 16:07:17,098 - ERROR - telegram.ext.updater - Error while getting Updates: Conflict: terminated by other getUpdates request; make sure that only one bot instance is running (409)
2021-05-19 16:07:17,099 - ERROR - root - Conflict: terminated by other getUpdates request; make sure that only one bot instance is running (409) - Class: TelegramBot - None
2021-05-19 16:07:19,690 - ERROR - root - Timed out - {'update_id': 406256825, 'message': {'message_id': 7917, 'date': 1620332165, 'chat': {'id': -1001216334216, 'type': 'supergroup', 'title': 'KRİPTO PUSULA', 'username': 'kriptopusulasi'}, 'text': '/p btc', 'entities': [{'type': 'bot_command', 'offset': 0, 'length': 3}, {'type': 'bot_command', 'offset': 9, 'length': 2}], 'caption_entities': [], 'photo': [], 'new_chat_members': [], 'new_chat_photo': [], 'delete_chat_photo': False, 'group_chat_created': False, 'supergroup_chat_created': False, 'channel_chat_created': False, 'from': {'id': 1087968824, 'first_name': 'Group', 'is_bot': True, 'username': 'GroupAnonymousBot'}}}
2021-05-19 16:07:19,691 - ERROR - JobQueue - An uncaught error was raised while executing job _send_msg
Traceback (most recent call last):
  File "/Users/ahmetcnd/.local/share/virtualenvs/openCryptoBot-D8P4_yx3/lib/python3.7/site-packages/telegram/vendor/ptb_urllib3/urllib3/connectionpool.py", line 402, in _make_request
    six.raise_from(e, None)
  File "<string>", line 2, in raise_from
  File "/Users/ahmetcnd/.local/share/virtualenvs/openCryptoBot-D8P4_yx3/lib/python3.7/site-packages/telegram/vendor/ptb_urllib3/urllib3/connectionpool.py", line 398, in _make_request
    httplib_response = conn.getresponse()
  File "/Users/ahmetcnd/.pyenv/versions/3.7.10/lib/python3.7/http/client.py", line 1369, in getresponse
    response.begin()
  File "/Users/ahmetcnd/.pyenv/versions/3.7.10/lib/python3.7/http/client.py", line 310, in begin
    version, status, reason = self._read_status()
  File "/Users/ahmetcnd/.pyenv/versions/3.7.10/lib/python3.7/http/client.py", line 271, in _read_status
    line = str(self.fp.readline(_MAXLINE + 1), "iso-8859-1")
  File "/Users/ahmetcnd/.pyenv/versions/3.7.10/lib/python3.7/socket.py", line 589, in readinto
    return self._sock.recv_into(b)
  File "/Users/ahmetcnd/.pyenv/versions/3.7.10/lib/python3.7/ssl.py", line 1071, in recv_into
    return self.read(nbytes, buffer)
  File "/Users/ahmetcnd/.pyenv/versions/3.7.10/lib/python3.7/ssl.py", line 929, in read
    return self._sslobj.read(len, buffer)
socket.timeout: The read operation timed out

During handling of the above exception, another exception occurred:

Traceback (most recent call last):
  File "/Users/ahmetcnd/.local/share/virtualenvs/openCryptoBot-D8P4_yx3/lib/python3.7/site-packages/telegram/utils/request.py", line 203, in _request_wrapper
    resp = self._con_pool.request(*args, **kwargs)
  File "/Users/ahmetcnd/.local/share/virtualenvs/openCryptoBot-D8P4_yx3/lib/python3.7/site-packages/telegram/vendor/ptb_urllib3/urllib3/request.py", line 70, in request
    **urlopen_kw)
  File "/Users/ahmetcnd/.local/share/virtualenvs/openCryptoBot-D8P4_yx3/lib/python3.7/site-packages/telegram/vendor/ptb_urllib3/urllib3/request.py", line 148, in request_encode_body
    return self.urlopen(method, url, **extra_kw)
  File "/Users/ahmetcnd/.local/share/virtualenvs/openCryptoBot-D8P4_yx3/lib/python3.7/site-packages/telegram/vendor/ptb_urllib3/urllib3/poolmanager.py", line 244, in urlopen
    response = conn.urlopen(method, u.request_uri, **kw)
  File "/Users/ahmetcnd/.local/share/virtualenvs/openCryptoBot-D8P4_yx3/lib/python3.7/site-packages/telegram/vendor/ptb_urllib3/urllib3/connectionpool.py", line 666, in urlopen
    _stacktrace=sys.exc_info()[2])
  File "/Users/ahmetcnd/.local/share/virtualenvs/openCryptoBot-D8P4_yx3/lib/python3.7/site-packages/telegram/vendor/ptb_urllib3/urllib3/util/retry.py", line 347, in increment
    raise six.reraise(type(error), error, _stacktrace)
  File "/Users/ahmetcnd/.local/share/virtualenvs/openCryptoBot-D8P4_yx3/lib/python3.7/site-packages/telegram/vendor/ptb_urllib3/urllib3/packages/six.py", line 686, in reraise
    raise value
  File "/Users/ahmetcnd/.local/share/virtualenvs/openCryptoBot-D8P4_yx3/lib/python3.7/site-packages/telegram/vendor/ptb_urllib3/urllib3/connectionpool.py", line 617, in urlopen
    chunked=chunked)
  File "/Users/ahmetcnd/.local/share/virtualenvs/openCryptoBot-D8P4_yx3/lib/python3.7/site-packages/telegram/vendor/ptb_urllib3/urllib3/connectionpool.py", line 405, in _make_request
    exc_cls=ReadTimeoutError)
  File "/Users/ahmetcnd/.local/share/virtualenvs/openCryptoBot-D8P4_yx3/lib/python3.7/site-packages/telegram/vendor/ptb_urllib3/urllib3/connectionpool.py", line 321, in _raise_timeout
    raise exc_cls(*args)
telegram.vendor.ptb_urllib3.urllib3.exceptions.ReadTimeoutError: HTTPSConnectionPool(host='api.telegram.org', port=443): Read timed out. (read timeout=5.0)

During handling of the above exception, another exception occurred:

Traceback (most recent call last):
  File "/Users/ahmetcnd/Documents/telegrambot/openCryptoBot/opencryptobot/plugins/repeat.py", line 169, in _send_msg
    plgn.get_action(bot, updt, args=args)
  File "/Users/ahmetcnd/Documents/telegrambot/openCryptoBot/opencryptobot/plugin.py", line 106, in _save_data
    return func(self, bot, update, **kwargs)
  File "/Users/ahmetcnd/Documents/telegrambot/openCryptoBot/opencryptobot/plugin.py", line 73, in _send_typing_action
    return func(self, bot, update, **kwargs)
  File "/Users/ahmetcnd/Documents/telegrambot/openCryptoBot/opencryptobot/plugins/price.py", line 149, in get_action
    self.send_msg(msg, update, keywords)
  File "/Users/ahmetcnd/Documents/telegrambot/openCryptoBot/opencryptobot/plugin.py", line 144, in send_msg
    disable_notification=not notify)
  File "/Users/ahmetcnd/.local/share/virtualenvs/openCryptoBot-D8P4_yx3/lib/python3.7/site-packages/telegram/message.py", line 455, in reply_text
    return self.bot.send_message(self.chat_id, *args, **kwargs)
  File "/Users/ahmetcnd/.local/share/virtualenvs/openCryptoBot-D8P4_yx3/lib/python3.7/site-packages/telegram/bot.py", line 65, in decorator
    result = func(self, *args, **kwargs)
  File "/Users/ahmetcnd/.local/share/virtualenvs/openCryptoBot-D8P4_yx3/lib/python3.7/site-packages/telegram/bot.py", line 90, in decorator
    result = self._request.post(url, data, timeout=kwargs.get('timeout'))
  File "/Users/ahmetcnd/.local/share/virtualenvs/openCryptoBot-D8P4_yx3/lib/python3.7/site-packages/telegram/utils/request.py", line 309, in post
    headers={'Content-Type': 'application/json'})
  File "/Users/ahmetcnd/.local/share/virtualenvs/openCryptoBot-D8P4_yx3/lib/python3.7/site-packages/telegram/utils/request.py", line 205, in _request_wrapper
    raise TimedOut()
telegram.error.TimedOut: Timed out

During handling of the above exception, another exception occurred:

Traceback (most recent call last):
  File "/Users/ahmetcnd/.local/share/virtualenvs/openCryptoBot-D8P4_yx3/lib/python3.7/site-packages/telegram/ext/jobqueue.py", line 245, in tick
    job.run(self.bot)
  File "/Users/ahmetcnd/.local/share/virtualenvs/openCryptoBot-D8P4_yx3/lib/python3.7/site-packages/telegram/ext/jobqueue.py", line 372, in run
    self.callback(bot, self)
  File "/Users/ahmetcnd/Documents/telegrambot/openCryptoBot/opencryptobot/plugins/repeat.py", line 172, in _send_msg
    self.tgb.db.delete_rep(rep)
  File "/Users/ahmetcnd/Documents/telegrambot/openCryptoBot/opencryptobot/database.py", line 194, in delete_rep
    [repeater_id])
sqlite3.InterfaceError: Error binding parameter 0 - probably unsupported type.
2021-05-19 16:07:21,287 - ERROR - telegram.ext.updater - Error while getting Updates: Conflict: terminated by other getUpdates request; make sure that only one bot instance is running (409)
2021-05-19 16:07:21,288 - ERROR - root - Conflict: terminated by other getUpdates request; make sure that only one bot instance is running (409) - Class: TelegramBot - None
2021-05-19 16:07:29,711 - ERROR - root - Timed out - {'update_id': 406256825, 'message': {'message_id': 7917, 'date': 1620332165, 'chat': {'id': -1001216334216, 'type': 'supergroup', 'title': 'KRİPTO PUSULA', 'username': 'kriptopusulasi'}, 'text': '/p btc', 'entities': [{'type': 'bot_command', 'offset': 0, 'length': 3}, {'type': 'bot_command', 'offset': 9, 'length': 2}], 'caption_entities': [], 'photo': [], 'new_chat_members': [], 'new_chat_photo': [], 'delete_chat_photo': False, 'group_chat_created': False, 'supergroup_chat_created': False, 'channel_chat_created': False, 'from': {'id': 1087968824, 'first_name': 'Group', 'is_bot': True, 'username': 'GroupAnonymousBot'}}}
2021-05-19 16:07:42,660 - ERROR - root - Replied message not found - {'update_id': 406256827, 'message': {'message_id': 7920, 'date': 1620332268, 'chat': {'id': -1001216334216, 'type': 'supergroup', 'title': 'KRİPTO PUSULA', 'username': 'kriptopusulasi'}, 'text': '/p eth', 'entities': [{'type': 'bot_command', 'offset': 0, 'length': 3}, {'type': 'bot_command', 'offset': 9, 'length': 2}], 'caption_entities': [], 'photo': [], 'new_chat_members': [], 'new_chat_photo': [], 'delete_chat_photo': False, 'group_chat_created': False, 'supergroup_chat_created': False, 'channel_chat_created': False, 'from': {'id': 1087968824, 'first_name': 'Group', 'is_bot': True, 'username': 'GroupAnonymousBot'}}}
2021-05-19 16:07:42,662 - ERROR - JobQueue - An uncaught error was raised while executing job _send_msg
Traceback (most recent call last):
  File "/Users/ahmetcnd/Documents/telegrambot/openCryptoBot/opencryptobot/plugins/repeat.py", line 169, in _send_msg
    plgn.get_action(bot, updt, args=args)
  File "/Users/ahmetcnd/Documents/telegrambot/openCryptoBot/opencryptobot/plugin.py", line 106, in _save_data
    return func(self, bot, update, **kwargs)
  File "/Users/ahmetcnd/Documents/telegrambot/openCryptoBot/opencryptobot/plugin.py", line 73, in _send_typing_action
    return func(self, bot, update, **kwargs)
  File "/Users/ahmetcnd/Documents/telegrambot/openCryptoBot/opencryptobot/plugins/price.py", line 149, in get_action
    self.send_msg(msg, update, keywords)
  File "/Users/ahmetcnd/Documents/telegrambot/openCryptoBot/opencryptobot/plugin.py", line 144, in send_msg
    disable_notification=not notify)
  File "/Users/ahmetcnd/.local/share/virtualenvs/openCryptoBot-D8P4_yx3/lib/python3.7/site-packages/telegram/message.py", line 455, in reply_text
    return self.bot.send_message(self.chat_id, *args, **kwargs)
  File "/Users/ahmetcnd/.local/share/virtualenvs/openCryptoBot-D8P4_yx3/lib/python3.7/site-packages/telegram/bot.py", line 65, in decorator
    result = func(self, *args, **kwargs)
  File "/Users/ahmetcnd/.local/share/virtualenvs/openCryptoBot-D8P4_yx3/lib/python3.7/site-packages/telegram/bot.py", line 90, in decorator
    result = self._request.post(url, data, timeout=kwargs.get('timeout'))
  File "/Users/ahmetcnd/.local/share/virtualenvs/openCryptoBot-D8P4_yx3/lib/python3.7/site-packages/telegram/utils/request.py", line 309, in post
    headers={'Content-Type': 'application/json'})
  File "/Users/ahmetcnd/.local/share/virtualenvs/openCryptoBot-D8P4_yx3/lib/python3.7/site-packages/telegram/utils/request.py", line 223, in _request_wrapper
    raise BadRequest(message)
telegram.error.BadRequest: Replied message not found

During handling of the above exception, another exception occurred:

Traceback (most recent call last):
  File "/Users/ahmetcnd/.local/share/virtualenvs/openCryptoBot-D8P4_yx3/lib/python3.7/site-packages/telegram/ext/jobqueue.py", line 245, in tick
    job.run(self.bot)
  File "/Users/ahmetcnd/.local/share/virtualenvs/openCryptoBot-D8P4_yx3/lib/python3.7/site-packages/telegram/ext/jobqueue.py", line 372, in run
    self.callback(bot, self)
  File "/Users/ahmetcnd/Documents/telegrambot/openCryptoBot/opencryptobot/plugins/repeat.py", line 172, in _send_msg
    self.tgb.db.delete_rep(rep)
  File "/Users/ahmetcnd/Documents/telegrambot/openCryptoBot/opencryptobot/database.py", line 194, in delete_rep
    [repeater_id])
sqlite3.InterfaceError: Error binding parameter 0 - probably unsupported type.
2021-05-19 16:07:50,830 - ERROR - root - Timed out - {'update_id': 406256828, 'message': {'message_id': 7922, 'date': 1620332306, 'chat': {'id': -1001216334216, 'type': 'supergroup', 'title': 'KRİPTO PUSULA', 'username': 'kriptopusulasi'}, 'text': '/p doge', 'entities': [{'type': 'bot_command', 'offset': 0, 'length': 3}, {'type': 'bot_command', 'offset': 9, 'length': 2}], 'caption_entities': [], 'photo': [], 'new_chat_members': [], 'new_chat_photo': [], 'delete_chat_photo': False, 'group_chat_created': False, 'supergroup_chat_created': False, 'channel_chat_created': False, 'from': {'id': 1087968824, 'first_name': 'Group', 'is_bot': True, 'username': 'GroupAnonymousBot'}}}
2021-05-19 16:07:50,831 - ERROR - JobQueue - An uncaught error was raised while executing job _send_msg
Traceback (most recent call last):
  File "/Users/ahmetcnd/.local/share/virtualenvs/openCryptoBot-D8P4_yx3/lib/python3.7/site-packages/telegram/vendor/ptb_urllib3/urllib3/connectionpool.py", line 402, in _make_request
    six.raise_from(e, None)
  File "<string>", line 2, in raise_from
  File "/Users/ahmetcnd/.local/share/virtualenvs/openCryptoBot-D8P4_yx3/lib/python3.7/site-packages/telegram/vendor/ptb_urllib3/urllib3/connectionpool.py", line 398, in _make_request
    httplib_response = conn.getresponse()
  File "/Users/ahmetcnd/.pyenv/versions/3.7.10/lib/python3.7/http/client.py", line 1369, in getresponse
    response.begin()
  File "/Users/ahmetcnd/.pyenv/versions/3.7.10/lib/python3.7/http/client.py", line 310, in begin
    version, status, reason = self._read_status()
  File "/Users/ahmetcnd/.pyenv/versions/3.7.10/lib/python3.7/http/client.py", line 271, in _read_status
    line = str(self.fp.readline(_MAXLINE + 1), "iso-8859-1")
  File "/Users/ahmetcnd/.pyenv/versions/3.7.10/lib/python3.7/socket.py", line 589, in readinto
    return self._sock.recv_into(b)
  File "/Users/ahmetcnd/.pyenv/versions/3.7.10/lib/python3.7/ssl.py", line 1071, in recv_into
    return self.read(nbytes, buffer)
  File "/Users/ahmetcnd/.pyenv/versions/3.7.10/lib/python3.7/ssl.py", line 929, in read
    return self._sslobj.read(len, buffer)
socket.timeout: The read operation timed out

During handling of the above exception, another exception occurred:

Traceback (most recent call last):
  File "/Users/ahmetcnd/.local/share/virtualenvs/openCryptoBot-D8P4_yx3/lib/python3.7/site-packages/telegram/utils/request.py", line 203, in _request_wrapper
    resp = self._con_pool.request(*args, **kwargs)
  File "/Users/ahmetcnd/.local/share/virtualenvs/openCryptoBot-D8P4_yx3/lib/python3.7/site-packages/telegram/vendor/ptb_urllib3/urllib3/request.py", line 70, in request
    **urlopen_kw)
  File "/Users/ahmetcnd/.local/share/virtualenvs/openCryptoBot-D8P4_yx3/lib/python3.7/site-packages/telegram/vendor/ptb_urllib3/urllib3/request.py", line 148, in request_encode_body
    return self.urlopen(method, url, **extra_kw)
  File "/Users/ahmetcnd/.local/share/virtualenvs/openCryptoBot-D8P4_yx3/lib/python3.7/site-packages/telegram/vendor/ptb_urllib3/urllib3/poolmanager.py", line 244, in urlopen
    response = conn.urlopen(method, u.request_uri, **kw)
  File "/Users/ahmetcnd/.local/share/virtualenvs/openCryptoBot-D8P4_yx3/lib/python3.7/site-packages/telegram/vendor/ptb_urllib3/urllib3/connectionpool.py", line 666, in urlopen
    _stacktrace=sys.exc_info()[2])
  File "/Users/ahmetcnd/.local/share/virtualenvs/openCryptoBot-D8P4_yx3/lib/python3.7/site-packages/telegram/vendor/ptb_urllib3/urllib3/util/retry.py", line 347, in increment
    raise six.reraise(type(error), error, _stacktrace)
  File "/Users/ahmetcnd/.local/share/virtualenvs/openCryptoBot-D8P4_yx3/lib/python3.7/site-packages/telegram/vendor/ptb_urllib3/urllib3/packages/six.py", line 686, in reraise
    raise value
  File "/Users/ahmetcnd/.local/share/virtualenvs/openCryptoBot-D8P4_yx3/lib/python3.7/site-packages/telegram/vendor/ptb_urllib3/urllib3/connectionpool.py", line 617, in urlopen
    chunked=chunked)
  File "/Users/ahmetcnd/.local/share/virtualenvs/openCryptoBot-D8P4_yx3/lib/python3.7/site-packages/telegram/vendor/ptb_urllib3/urllib3/connectionpool.py", line 405, in _make_request
    exc_cls=ReadTimeoutError)
  File "/Users/ahmetcnd/.local/share/virtualenvs/openCryptoBot-D8P4_yx3/lib/python3.7/site-packages/telegram/vendor/ptb_urllib3/urllib3/connectionpool.py", line 321, in _raise_timeout
    raise exc_cls(*args)
telegram.vendor.ptb_urllib3.urllib3.exceptions.ReadTimeoutError: HTTPSConnectionPool(host='api.telegram.org', port=443): Read timed out. (read timeout=5.0)

During handling of the above exception, another exception occurred:

Traceback (most recent call last):
  File "/Users/ahmetcnd/Documents/telegrambot/openCryptoBot/opencryptobot/plugins/repeat.py", line 169, in _send_msg
    plgn.get_action(bot, updt, args=args)
  File "/Users/ahmetcnd/Documents/telegrambot/openCryptoBot/opencryptobot/plugin.py", line 106, in _save_data
    return func(self, bot, update, **kwargs)
  File "/Users/ahmetcnd/Documents/telegrambot/openCryptoBot/opencryptobot/plugin.py", line 73, in _send_typing_action
    return func(self, bot, update, **kwargs)
  File "/Users/ahmetcnd/Documents/telegrambot/openCryptoBot/opencryptobot/plugins/price.py", line 149, in get_action
    self.send_msg(msg, update, keywords)
  File "/Users/ahmetcnd/Documents/telegrambot/openCryptoBot/opencryptobot/plugin.py", line 144, in send_msg
    disable_notification=not notify)
  File "/Users/ahmetcnd/.local/share/virtualenvs/openCryptoBot-D8P4_yx3/lib/python3.7/site-packages/telegram/message.py", line 455, in reply_text
    return self.bot.send_message(self.chat_id, *args, **kwargs)
  File "/Users/ahmetcnd/.local/share/virtualenvs/openCryptoBot-D8P4_yx3/lib/python3.7/site-packages/telegram/bot.py", line 65, in decorator
    result = func(self, *args, **kwargs)
  File "/Users/ahmetcnd/.local/share/virtualenvs/openCryptoBot-D8P4_yx3/lib/python3.7/site-packages/telegram/bot.py", line 90, in decorator
    result = self._request.post(url, data, timeout=kwargs.get('timeout'))
  File "/Users/ahmetcnd/.local/share/virtualenvs/openCryptoBot-D8P4_yx3/lib/python3.7/site-packages/telegram/utils/request.py", line 309, in post
    headers={'Content-Type': 'application/json'})
  File "/Users/ahmetcnd/.local/share/virtualenvs/openCryptoBot-D8P4_yx3/lib/python3.7/site-packages/telegram/utils/request.py", line 205, in _request_wrapper
    raise TimedOut()
telegram.error.TimedOut: Timed out

During handling of the above exception, another exception occurred:

Traceback (most recent call last):
  File "/Users/ahmetcnd/.local/share/virtualenvs/openCryptoBot-D8P4_yx3/lib/python3.7/site-packages/telegram/ext/jobqueue.py", line 245, in tick
    job.run(self.bot)
  File "/Users/ahmetcnd/.local/share/virtualenvs/openCryptoBot-D8P4_yx3/lib/python3.7/site-packages/telegram/ext/jobqueue.py", line 372, in run
    self.callback(bot, self)
  File "/Users/ahmetcnd/Documents/telegrambot/openCryptoBot/opencryptobot/plugins/repeat.py", line 172, in _send_msg
    self.tgb.db.delete_rep(rep)
  File "/Users/ahmetcnd/Documents/telegrambot/openCryptoBot/opencryptobot/database.py", line 194, in delete_rep
    [repeater_id])
sqlite3.InterfaceError: Error binding parameter 0 - probably unsupported type.
2021-05-19 16:07:50,835 - INFO - root - Starting Caching
2021-05-19 16:07:55,076 - ERROR - telegram.ext.updater - Error while getting Updates: Conflict: terminated by other getUpdates request; make sure that only one bot instance is running (409)
2021-05-19 16:07:55,076 - ERROR - root - Conflict: terminated by other getUpdates request; make sure that only one bot instance is running (409) - Class: TelegramBot - None
2021-05-19 16:08:04,216 - ERROR - JobQueue - An uncaught error was raised while executing job refresh
Traceback (most recent call last):
  File "/Users/ahmetcnd/.local/share/virtualenvs/openCryptoBot-D8P4_yx3/lib/python3.7/site-packages/telegram/ext/jobqueue.py", line 245, in tick
    job.run(self.bot)
  File "/Users/ahmetcnd/.local/share/virtualenvs/openCryptoBot-D8P4_yx3/lib/python3.7/site-packages/telegram/ext/jobqueue.py", line 372, in run
    self.callback(bot, self)
  File "/Users/ahmetcnd/Documents/telegrambot/openCryptoBot/opencryptobot/api/apicache.py", line 23, in refresh
    APICache.refresh_coinmarketcap_coin_list()
  File "/Users/ahmetcnd/Documents/telegrambot/openCryptoBot/opencryptobot/api/apicache.py", line 39, in refresh_coinmarketcap_coin_list
    APICache.cmc_coin_list = Market().listings()["data"]
TypeError: 'JSONDecodeError' object is not subscriptable
2021-05-19 16:08:14,398 - ERROR - root - Replied message not found - {'update_id': 406256827, 'message': {'message_id': 7920, 'date': 1620332268, 'chat': {'id': -1001216334216, 'type': 'supergroup', 'title': 'KRİPTO PUSULA', 'username': 'kriptopusulasi'}, 'text': '/p eth', 'entities': [{'type': 'bot_command', 'offset': 0, 'length': 3}, {'type': 'bot_command', 'offset': 9, 'length': 2}], 'caption_entities': [], 'photo': [], 'new_chat_members': [], 'new_chat_photo': [], 'delete_chat_photo': False, 'group_chat_created': False, 'supergroup_chat_created': False, 'channel_chat_created': False, 'from': {'id': 1087968824, 'first_name': 'Group', 'is_bot': True, 'username': 'GroupAnonymousBot'}}}
2021-05-19 16:08:14,399 - ERROR - JobQueue - An uncaught error was raised while executing job _send_msg
Traceback (most recent call last):
  File "/Users/ahmetcnd/Documents/telegrambot/openCryptoBot/opencryptobot/plugins/repeat.py", line 169, in _send_msg
    plgn.get_action(bot, updt, args=args)
  File "/Users/ahmetcnd/Documents/telegrambot/openCryptoBot/opencryptobot/plugin.py", line 106, in _save_data
    return func(self, bot, update, **kwargs)
  File "/Users/ahmetcnd/Documents/telegrambot/openCryptoBot/opencryptobot/plugin.py", line 73, in _send_typing_action
    return func(self, bot, update, **kwargs)
  File "/Users/ahmetcnd/Documents/telegrambot/openCryptoBot/opencryptobot/plugins/price.py", line 149, in get_action
    self.send_msg(msg, update, keywords)
  File "/Users/ahmetcnd/Documents/telegrambot/openCryptoBot/opencryptobot/plugin.py", line 144, in send_msg
    disable_notification=not notify)
  File "/Users/ahmetcnd/.local/share/virtualenvs/openCryptoBot-D8P4_yx3/lib/python3.7/site-packages/telegram/message.py", line 455, in reply_text
    return self.bot.send_message(self.chat_id, *args, **kwargs)
  File "/Users/ahmetcnd/.local/share/virtualenvs/openCryptoBot-D8P4_yx3/lib/python3.7/site-packages/telegram/bot.py", line 65, in decorator
    result = func(self, *args, **kwargs)
  File "/Users/ahmetcnd/.local/share/virtualenvs/openCryptoBot-D8P4_yx3/lib/python3.7/site-packages/telegram/bot.py", line 90, in decorator
    result = self._request.post(url, data, timeout=kwargs.get('timeout'))
  File "/Users/ahmetcnd/.local/share/virtualenvs/openCryptoBot-D8P4_yx3/lib/python3.7/site-packages/telegram/utils/request.py", line 309, in post
    headers={'Content-Type': 'application/json'})
  File "/Users/ahmetcnd/.local/share/virtualenvs/openCryptoBot-D8P4_yx3/lib/python3.7/site-packages/telegram/utils/request.py", line 223, in _request_wrapper
    raise BadRequest(message)
telegram.error.BadRequest: Replied message not found

During handling of the above exception, another exception occurred:

Traceback (most recent call last):
  File "/Users/ahmetcnd/.local/share/virtualenvs/openCryptoBot-D8P4_yx3/lib/python3.7/site-packages/telegram/ext/jobqueue.py", line 245, in tick
    job.run(self.bot)
  File "/Users/ahmetcnd/.local/share/virtualenvs/openCryptoBot-D8P4_yx3/lib/python3.7/site-packages/telegram/ext/jobqueue.py", line 372, in run
    self.callback(bot, self)
  File "/Users/ahmetcnd/Documents/telegrambot/openCryptoBot/opencryptobot/plugins/repeat.py", line 172, in _send_msg
    self.tgb.db.delete_rep(rep)
  File "/Users/ahmetcnd/Documents/telegrambot/openCryptoBot/opencryptobot/database.py", line 194, in delete_rep
    [repeater_id])
sqlite3.InterfaceError: Error binding parameter 0 - probably unsupported type.
2021-05-19 16:08:25,683 - ERROR - telegram.ext.updater - Error while getting Updates: Conflict: terminated by other getUpdates request; make sure that only one bot instance is running (409)
2021-05-19 16:08:25,684 - ERROR - root - Conflict: terminated by other getUpdates request; make sure that only one bot instance is running (409) - Class: TelegramBot - None
2021-05-19 16:08:29,754 - ERROR - telegram.ext.updater - Error while getting Updates: Conflict: terminated by other getUpdates request; make sure that only one bot instance is running (409)
2021-05-19 16:08:29,754 - ERROR - root - Conflict: terminated by other getUpdates request; make sure that only one bot instance is running (409) - Class: TelegramBot - None
2021-05-19 16:09:00,544 - ERROR - telegram.ext.updater - Error while getting Updates: Conflict: terminated by other getUpdates request; make sure that only one bot instance is running (409)
2021-05-19 16:09:00,545 - ERROR - root - Conflict: terminated by other getUpdates request; make sure that only one bot instance is running (409) - Class: TelegramBot - None
2021-05-19 16:09:04,614 - ERROR - telegram.ext.updater - Error while getting Updates: Conflict: terminated by other getUpdates request; make sure that only one bot instance is running (409)
2021-05-19 16:09:04,615 - ERROR - root - Conflict: terminated by other getUpdates request; make sure that only one bot instance is running (409) - Class: TelegramBot - None
2021-05-19 16:09:20,881 - ERROR - root - Timed out - {'update_id': 406256829, 'message': {'message_id': 7924, 'date': 1620332356, 'chat': {'id': -1001216334216, 'type': 'supergroup', 'title': 'KRİPTO PUSULA', 'username': 'kriptopusulasi'}, 'text': '/p btt', 'entities': [{'type': 'bot_command', 'offset': 0, 'length': 3}, {'type': 'bot_command', 'offset': 9, 'length': 2}], 'caption_entities': [], 'photo': [], 'new_chat_members': [], 'new_chat_photo': [], 'delete_chat_photo': False, 'group_chat_created': False, 'supergroup_chat_created': False, 'channel_chat_created': False, 'from': {'id': 1087968824, 'first_name': 'Group', 'is_bot': True, 'username': 'GroupAnonymousBot'}}}
2021-05-19 16:09:20,883 - ERROR - JobQueue - An uncaught error was raised while executing job _send_msg
Traceback (most recent call last):
  File "/Users/ahmetcnd/.local/share/virtualenvs/openCryptoBot-D8P4_yx3/lib/python3.7/site-packages/telegram/vendor/ptb_urllib3/urllib3/connectionpool.py", line 402, in _make_request
    six.raise_from(e, None)
  File "<string>", line 2, in raise_from
  File "/Users/ahmetcnd/.local/share/virtualenvs/openCryptoBot-D8P4_yx3/lib/python3.7/site-packages/telegram/vendor/ptb_urllib3/urllib3/connectionpool.py", line 398, in _make_request
    httplib_response = conn.getresponse()
  File "/Users/ahmetcnd/.pyenv/versions/3.7.10/lib/python3.7/http/client.py", line 1369, in getresponse
    response.begin()
  File "/Users/ahmetcnd/.pyenv/versions/3.7.10/lib/python3.7/http/client.py", line 310, in begin
    version, status, reason = self._read_status()
  File "/Users/ahmetcnd/.pyenv/versions/3.7.10/lib/python3.7/http/client.py", line 271, in _read_status
    line = str(self.fp.readline(_MAXLINE + 1), "iso-8859-1")
  File "/Users/ahmetcnd/.pyenv/versions/3.7.10/lib/python3.7/socket.py", line 589, in readinto
    return self._sock.recv_into(b)
  File "/Users/ahmetcnd/.pyenv/versions/3.7.10/lib/python3.7/ssl.py", line 1071, in recv_into
    return self.read(nbytes, buffer)
  File "/Users/ahmetcnd/.pyenv/versions/3.7.10/lib/python3.7/ssl.py", line 929, in read
    return self._sslobj.read(len, buffer)
socket.timeout: The read operation timed out

During handling of the above exception, another exception occurred:

Traceback (most recent call last):
  File "/Users/ahmetcnd/.local/share/virtualenvs/openCryptoBot-D8P4_yx3/lib/python3.7/site-packages/telegram/utils/request.py", line 203, in _request_wrapper
    resp = self._con_pool.request(*args, **kwargs)
  File "/Users/ahmetcnd/.local/share/virtualenvs/openCryptoBot-D8P4_yx3/lib/python3.7/site-packages/telegram/vendor/ptb_urllib3/urllib3/request.py", line 70, in request
    **urlopen_kw)
  File "/Users/ahmetcnd/.local/share/virtualenvs/openCryptoBot-D8P4_yx3/lib/python3.7/site-packages/telegram/vendor/ptb_urllib3/urllib3/request.py", line 148, in request_encode_body
    return self.urlopen(method, url, **extra_kw)
  File "/Users/ahmetcnd/.local/share/virtualenvs/openCryptoBot-D8P4_yx3/lib/python3.7/site-packages/telegram/vendor/ptb_urllib3/urllib3/poolmanager.py", line 244, in urlopen
    response = conn.urlopen(method, u.request_uri, **kw)
  File "/Users/ahmetcnd/.local/share/virtualenvs/openCryptoBot-D8P4_yx3/lib/python3.7/site-packages/telegram/vendor/ptb_urllib3/urllib3/connectionpool.py", line 666, in urlopen
    _stacktrace=sys.exc_info()[2])
  File "/Users/ahmetcnd/.local/share/virtualenvs/openCryptoBot-D8P4_yx3/lib/python3.7/site-packages/telegram/vendor/ptb_urllib3/urllib3/util/retry.py", line 347, in increment
    raise six.reraise(type(error), error, _stacktrace)
  File "/Users/ahmetcnd/.local/share/virtualenvs/openCryptoBot-D8P4_yx3/lib/python3.7/site-packages/telegram/vendor/ptb_urllib3/urllib3/packages/six.py", line 686, in reraise
    raise value
  File "/Users/ahmetcnd/.local/share/virtualenvs/openCryptoBot-D8P4_yx3/lib/python3.7/site-packages/telegram/vendor/ptb_urllib3/urllib3/connectionpool.py", line 617, in urlopen
    chunked=chunked)
  File "/Users/ahmetcnd/.local/share/virtualenvs/openCryptoBot-D8P4_yx3/lib/python3.7/site-packages/telegram/vendor/ptb_urllib3/urllib3/connectionpool.py", line 405, in _make_request
    exc_cls=ReadTimeoutError)
  File "/Users/ahmetcnd/.local/share/virtualenvs/openCryptoBot-D8P4_yx3/lib/python3.7/site-packages/telegram/vendor/ptb_urllib3/urllib3/connectionpool.py", line 321, in _raise_timeout
    raise exc_cls(*args)
telegram.vendor.ptb_urllib3.urllib3.exceptions.ReadTimeoutError: HTTPSConnectionPool(host='api.telegram.org', port=443): Read timed out. (read timeout=5.0)

During handling of the above exception, another exception occurred:

Traceback (most recent call last):
  File "/Users/ahmetcnd/Documents/telegrambot/openCryptoBot/opencryptobot/plugins/repeat.py", line 169, in _send_msg
    plgn.get_action(bot, updt, args=args)
  File "/Users/ahmetcnd/Documents/telegrambot/openCryptoBot/opencryptobot/plugin.py", line 106, in _save_data
    return func(self, bot, update, **kwargs)
  File "/Users/ahmetcnd/Documents/telegrambot/openCryptoBot/opencryptobot/plugin.py", line 73, in _send_typing_action
    return func(self, bot, update, **kwargs)
  File "/Users/ahmetcnd/Documents/telegrambot/openCryptoBot/opencryptobot/plugins/price.py", line 149, in get_action
    self.send_msg(msg, update, keywords)
  File "/Users/ahmetcnd/Documents/telegrambot/openCryptoBot/opencryptobot/plugin.py", line 144, in send_msg
    disable_notification=not notify)
  File "/Users/ahmetcnd/.local/share/virtualenvs/openCryptoBot-D8P4_yx3/lib/python3.7/site-packages/telegram/message.py", line 455, in reply_text
    return self.bot.send_message(self.chat_id, *args, **kwargs)
  File "/Users/ahmetcnd/.local/share/virtualenvs/openCryptoBot-D8P4_yx3/lib/python3.7/site-packages/telegram/bot.py", line 65, in decorator
    result = func(self, *args, **kwargs)
  File "/Users/ahmetcnd/.local/share/virtualenvs/openCryptoBot-D8P4_yx3/lib/python3.7/site-packages/telegram/bot.py", line 90, in decorator
    result = self._request.post(url, data, timeout=kwargs.get('timeout'))
  File "/Users/ahmetcnd/.local/share/virtualenvs/openCryptoBot-D8P4_yx3/lib/python3.7/site-packages/telegram/utils/request.py", line 309, in post
    headers={'Content-Type': 'application/json'})
  File "/Users/ahmetcnd/.local/share/virtualenvs/openCryptoBot-D8P4_yx3/lib/python3.7/site-packages/telegram/utils/request.py", line 205, in _request_wrapper
    raise TimedOut()
telegram.error.TimedOut: Timed out

During handling of the above exception, another exception occurred:

Traceback (most recent call last):
  File "/Users/ahmetcnd/.local/share/virtualenvs/openCryptoBot-D8P4_yx3/lib/python3.7/site-packages/telegram/ext/jobqueue.py", line 245, in tick
    job.run(self.bot)
  File "/Users/ahmetcnd/.local/share/virtualenvs/openCryptoBot-D8P4_yx3/lib/python3.7/site-packages/telegram/ext/jobqueue.py", line 372, in run
    self.callback(bot, self)
  File "/Users/ahmetcnd/Documents/telegrambot/openCryptoBot/opencryptobot/plugins/repeat.py", line 172, in _send_msg
    self.tgb.db.delete_rep(rep)
  File "/Users/ahmetcnd/Documents/telegrambot/openCryptoBot/opencryptobot/database.py", line 194, in delete_rep
    [repeater_id])
sqlite3.InterfaceError: Error binding parameter 0 - probably unsupported type.
2021-05-19 16:09:27,137 - ERROR - root - Replied message not found - {'update_id': 406256828, 'message': {'message_id': 7922, 'date': 1620332306, 'chat': {'id': -1001216334216, 'type': 'supergroup', 'title': 'KRİPTO PUSULA', 'username': 'kriptopusulasi'}, 'text': '/p doge', 'entities': [{'type': 'bot_command', 'offset': 0, 'length': 3}, {'type': 'bot_command', 'offset': 9, 'length': 2}], 'caption_entities': [], 'photo': [], 'new_chat_members': [], 'new_chat_photo': [], 'delete_chat_photo': False, 'group_chat_created': False, 'supergroup_chat_created': False, 'channel_chat_created': False, 'from': {'id': 1087968824, 'first_name': 'Group', 'is_bot': True, 'username': 'GroupAnonymousBot'}}}
2021-05-19 16:09:27,138 - ERROR - JobQueue - An uncaught error was raised while executing job _send_msg
Traceback (most recent call last):
  File "/Users/ahmetcnd/Documents/telegrambot/openCryptoBot/opencryptobot/plugins/repeat.py", line 169, in _send_msg
    plgn.get_action(bot, updt, args=args)
  File "/Users/ahmetcnd/Documents/telegrambot/openCryptoBot/opencryptobot/plugin.py", line 106, in _save_data
    return func(self, bot, update, **kwargs)
  File "/Users/ahmetcnd/Documents/telegrambot/openCryptoBot/opencryptobot/plugin.py", line 73, in _send_typing_action
    return func(self, bot, update, **kwargs)
  File "/Users/ahmetcnd/Documents/telegrambot/openCryptoBot/opencryptobot/plugins/price.py", line 149, in get_action
    self.send_msg(msg, update, keywords)
  File "/Users/ahmetcnd/Documents/telegrambot/openCryptoBot/opencryptobot/plugin.py", line 144, in send_msg
    disable_notification=not notify)
  File "/Users/ahmetcnd/.local/share/virtualenvs/openCryptoBot-D8P4_yx3/lib/python3.7/site-packages/telegram/message.py", line 455, in reply_text
    return self.bot.send_message(self.chat_id, *args, **kwargs)
  File "/Users/ahmetcnd/.local/share/virtualenvs/openCryptoBot-D8P4_yx3/lib/python3.7/site-packages/telegram/bot.py", line 65, in decorator
    result = func(self, *args, **kwargs)
  File "/Users/ahmetcnd/.local/share/virtualenvs/openCryptoBot-D8P4_yx3/lib/python3.7/site-packages/telegram/bot.py", line 90, in decorator
    result = self._request.post(url, data, timeout=kwargs.get('timeout'))
  File "/Users/ahmetcnd/.local/share/virtualenvs/openCryptoBot-D8P4_yx3/lib/python3.7/site-packages/telegram/utils/request.py", line 309, in post
    headers={'Content-Type': 'application/json'})
  File "/Users/ahmetcnd/.local/share/virtualenvs/openCryptoBot-D8P4_yx3/lib/python3.7/site-packages/telegram/utils/request.py", line 223, in _request_wrapper
    raise BadRequest(message)
telegram.error.BadRequest: Replied message not found

During handling of the above exception, another exception occurred:

Traceback (most recent call last):
  File "/Users/ahmetcnd/.local/share/virtualenvs/openCryptoBot-D8P4_yx3/lib/python3.7/site-packages/telegram/ext/jobqueue.py", line 245, in tick
    job.run(self.bot)
  File "/Users/ahmetcnd/.local/share/virtualenvs/openCryptoBot-D8P4_yx3/lib/python3.7/site-packages/telegram/ext/jobqueue.py", line 372, in run
    self.callback(bot, self)
  File "/Users/ahmetcnd/Documents/telegrambot/openCryptoBot/opencryptobot/plugins/repeat.py", line 172, in _send_msg
    self.tgb.db.delete_rep(rep)
  File "/Users/ahmetcnd/Documents/telegrambot/openCryptoBot/opencryptobot/database.py", line 194, in delete_rep
    [repeater_id])
sqlite3.InterfaceError: Error binding parameter 0 - probably unsupported type.
2021-05-19 16:09:35,297 - ERROR - telegram.ext.updater - Error while getting Updates: Conflict: terminated by other getUpdates request; make sure that only one bot instance is running (409)
2021-05-19 16:09:35,300 - ERROR - root - Conflict: terminated by other getUpdates request; make sure that only one bot instance is running (409) - Class: TelegramBot - None
2021-05-19 16:09:39,424 - ERROR - telegram.ext.updater - Error while getting Updates: Conflict: terminated by other getUpdates request; make sure that only one bot instance is running (409)
2021-05-19 16:09:39,425 - ERROR - root - Conflict: terminated by other getUpdates request; make sure that only one bot instance is running (409) - Class: TelegramBot - None
2021-05-19 16:10:10,063 - ERROR - telegram.ext.updater - Error while getting Updates: Conflict: terminated by other getUpdates request; make sure that only one bot instance is running (409)
2021-05-19 16:10:10,064 - ERROR - root - Conflict: terminated by other getUpdates request; make sure that only one bot instance is running (409) - Class: TelegramBot - None
2021-05-19 16:10:14,161 - ERROR - telegram.ext.updater - Error while getting Updates: Conflict: terminated by other getUpdates request; make sure that only one bot instance is running (409)
2021-05-19 16:10:14,162 - ERROR - root - Conflict: terminated by other getUpdates request; make sure that only one bot instance is running (409) - Class: TelegramBot - None
2021-05-19 16:10:33,761 - ERROR - root - Replied message not found - {'update_id': 406256827, 'message': {'message_id': 7920, 'date': 1620332268, 'chat': {'id': -1001216334216, 'type': 'supergroup', 'title': 'KRİPTO PUSULA', 'username': 'kriptopusulasi'}, 'text': '/p eth', 'entities': [{'type': 'bot_command', 'offset': 0, 'length': 3}, {'type': 'bot_command', 'offset': 9, 'length': 2}], 'caption_entities': [], 'photo': [], 'new_chat_members': [], 'new_chat_photo': [], 'delete_chat_photo': False, 'group_chat_created': False, 'supergroup_chat_created': False, 'channel_chat_created': False, 'from': {'id': 1087968824, 'first_name': 'Group', 'is_bot': True, 'username': 'GroupAnonymousBot'}}}
2021-05-19 16:10:33,762 - ERROR - JobQueue - An uncaught error was raised while executing job _send_msg
Traceback (most recent call last):
  File "/Users/ahmetcnd/Documents/telegrambot/openCryptoBot/opencryptobot/plugins/repeat.py", line 169, in _send_msg
    plgn.get_action(bot, updt, args=args)
  File "/Users/ahmetcnd/Documents/telegrambot/openCryptoBot/opencryptobot/plugin.py", line 106, in _save_data
    return func(self, bot, update, **kwargs)
  File "/Users/ahmetcnd/Documents/telegrambot/openCryptoBot/opencryptobot/plugin.py", line 73, in _send_typing_action
    return func(self, bot, update, **kwargs)
  File "/Users/ahmetcnd/Documents/telegrambot/openCryptoBot/opencryptobot/plugins/price.py", line 149, in get_action
    self.send_msg(msg, update, keywords)
  File "/Users/ahmetcnd/Documents/telegrambot/openCryptoBot/opencryptobot/plugin.py", line 144, in send_msg
    disable_notification=not notify)
  File "/Users/ahmetcnd/.local/share/virtualenvs/openCryptoBot-D8P4_yx3/lib/python3.7/site-packages/telegram/message.py", line 455, in reply_text
    return self.bot.send_message(self.chat_id, *args, **kwargs)
  File "/Users/ahmetcnd/.local/share/virtualenvs/openCryptoBot-D8P4_yx3/lib/python3.7/site-packages/telegram/bot.py", line 65, in decorator
    result = func(self, *args, **kwargs)
  File "/Users/ahmetcnd/.local/share/virtualenvs/openCryptoBot-D8P4_yx3/lib/python3.7/site-packages/telegram/bot.py", line 90, in decorator
    result = self._request.post(url, data, timeout=kwargs.get('timeout'))
  File "/Users/ahmetcnd/.local/share/virtualenvs/openCryptoBot-D8P4_yx3/lib/python3.7/site-packages/telegram/utils/request.py", line 309, in post
    headers={'Content-Type': 'application/json'})
  File "/Users/ahmetcnd/.local/share/virtualenvs/openCryptoBot-D8P4_yx3/lib/python3.7/site-packages/telegram/utils/request.py", line 223, in _request_wrapper
    raise BadRequest(message)
telegram.error.BadRequest: Replied message not found

During handling of the above exception, another exception occurred:

Traceback (most recent call last):
  File "/Users/ahmetcnd/.local/share/virtualenvs/openCryptoBot-D8P4_yx3/lib/python3.7/site-packages/telegram/ext/jobqueue.py", line 245, in tick
    job.run(self.bot)
  File "/Users/ahmetcnd/.local/share/virtualenvs/openCryptoBot-D8P4_yx3/lib/python3.7/site-packages/telegram/ext/jobqueue.py", line 372, in run
    self.callback(bot, self)
  File "/Users/ahmetcnd/Documents/telegrambot/openCryptoBot/opencryptobot/plugins/repeat.py", line 172, in _send_msg
    self.tgb.db.delete_rep(rep)
  File "/Users/ahmetcnd/Documents/telegrambot/openCryptoBot/opencryptobot/database.py", line 194, in delete_rep
    [repeater_id])
sqlite3.InterfaceError: Error binding parameter 0 - probably unsupported type.
2021-05-19 16:10:41,835 - ERROR - root - Replied message not found - {'update_id': 406256827, 'message': {'message_id': 7920, 'date': 1620332268, 'chat': {'id': -1001216334216, 'type': 'supergroup', 'title': 'KRİPTO PUSULA', 'username': 'kriptopusulasi'}, 'text': '/p eth', 'entities': [{'type': 'bot_command', 'offset': 0, 'length': 3}, {'type': 'bot_command', 'offset': 9, 'length': 2}], 'caption_entities': [], 'photo': [], 'new_chat_members': [], 'new_chat_photo': [], 'delete_chat_photo': False, 'group_chat_created': False, 'supergroup_chat_created': False, 'channel_chat_created': False, 'from': {'id': 1087968824, 'first_name': 'Group', 'is_bot': True, 'username': 'GroupAnonymousBot'}}}
2021-05-19 16:10:41,837 - ERROR - JobQueue - An uncaught error was raised while executing job _send_msg
Traceback (most recent call last):
  File "/Users/ahmetcnd/Documents/telegrambot/openCryptoBot/opencryptobot/plugins/repeat.py", line 169, in _send_msg
    plgn.get_action(bot, updt, args=args)
  File "/Users/ahmetcnd/Documents/telegrambot/openCryptoBot/opencryptobot/plugin.py", line 106, in _save_data
    return func(self, bot, update, **kwargs)
  File "/Users/ahmetcnd/Documents/telegrambot/openCryptoBot/opencryptobot/plugin.py", line 73, in _send_typing_action
    return func(self, bot, update, **kwargs)
  File "/Users/ahmetcnd/Documents/telegrambot/openCryptoBot/opencryptobot/plugins/price.py", line 149, in get_action
    self.send_msg(msg, update, keywords)
  File "/Users/ahmetcnd/Documents/telegrambot/openCryptoBot/opencryptobot/plugin.py", line 144, in send_msg
    disable_notification=not notify)
  File "/Users/ahmetcnd/.local/share/virtualenvs/openCryptoBot-D8P4_yx3/lib/python3.7/site-packages/telegram/message.py", line 455, in reply_text
    return self.bot.send_message(self.chat_id, *args, **kwargs)
  File "/Users/ahmetcnd/.local/share/virtualenvs/openCryptoBot-D8P4_yx3/lib/python3.7/site-packages/telegram/bot.py", line 65, in decorator
    result = func(self, *args, **kwargs)
  File "/Users/ahmetcnd/.local/share/virtualenvs/openCryptoBot-D8P4_yx3/lib/python3.7/site-packages/telegram/bot.py", line 90, in decorator
    result = self._request.post(url, data, timeout=kwargs.get('timeout'))
  File "/Users/ahmetcnd/.local/share/virtualenvs/openCryptoBot-D8P4_yx3/lib/python3.7/site-packages/telegram/utils/request.py", line 309, in post
    headers={'Content-Type': 'application/json'})
  File "/Users/ahmetcnd/.local/share/virtualenvs/openCryptoBot-D8P4_yx3/lib/python3.7/site-packages/telegram/utils/request.py", line 223, in _request_wrapper
    raise BadRequest(message)
telegram.error.BadRequest: Replied message not found

During handling of the above exception, another exception occurred:

Traceback (most recent call last):
  File "/Users/ahmetcnd/.local/share/virtualenvs/openCryptoBot-D8P4_yx3/lib/python3.7/site-packages/telegram/ext/jobqueue.py", line 245, in tick
    job.run(self.bot)
  File "/Users/ahmetcnd/.local/share/virtualenvs/openCryptoBot-D8P4_yx3/lib/python3.7/site-packages/telegram/ext/jobqueue.py", line 372, in run
    self.callback(bot, self)
  File "/Users/ahmetcnd/Documents/telegrambot/openCryptoBot/opencryptobot/plugins/repeat.py", line 172, in _send_msg
    self.tgb.db.delete_rep(rep)
  File "/Users/ahmetcnd/Documents/telegrambot/openCryptoBot/opencryptobot/database.py", line 194, in delete_rep
    [repeater_id])
sqlite3.InterfaceError: Error binding parameter 0 - probably unsupported type.
2021-05-19 16:10:43,949 - ERROR - root - Replied message not found - {'update_id': 406256828, 'message': {'message_id': 7922, 'date': 1620332306, 'chat': {'id': -1001216334216, 'type': 'supergroup', 'title': 'KRİPTO PUSULA', 'username': 'kriptopusulasi'}, 'text': '/p doge', 'entities': [{'type': 'bot_command', 'offset': 0, 'length': 3}, {'type': 'bot_command', 'offset': 9, 'length': 2}], 'caption_entities': [], 'photo': [], 'new_chat_members': [], 'new_chat_photo': [], 'delete_chat_photo': False, 'group_chat_created': False, 'supergroup_chat_created': False, 'channel_chat_created': False, 'from': {'id': 1087968824, 'first_name': 'Group', 'is_bot': True, 'username': 'GroupAnonymousBot'}}}
2021-05-19 16:10:43,950 - ERROR - JobQueue - An uncaught error was raised while executing job _send_msg
Traceback (most recent call last):
  File "/Users/ahmetcnd/Documents/telegrambot/openCryptoBot/opencryptobot/plugins/repeat.py", line 169, in _send_msg
    plgn.get_action(bot, updt, args=args)
  File "/Users/ahmetcnd/Documents/telegrambot/openCryptoBot/opencryptobot/plugin.py", line 106, in _save_data
    return func(self, bot, update, **kwargs)
  File "/Users/ahmetcnd/Documents/telegrambot/openCryptoBot/opencryptobot/plugin.py", line 73, in _send_typing_action
    return func(self, bot, update, **kwargs)
  File "/Users/ahmetcnd/Documents/telegrambot/openCryptoBot/opencryptobot/plugins/price.py", line 149, in get_action
    self.send_msg(msg, update, keywords)
  File "/Users/ahmetcnd/Documents/telegrambot/openCryptoBot/opencryptobot/plugin.py", line 144, in send_msg
    disable_notification=not notify)
  File "/Users/ahmetcnd/.local/share/virtualenvs/openCryptoBot-D8P4_yx3/lib/python3.7/site-packages/telegram/message.py", line 455, in reply_text
    return self.bot.send_message(self.chat_id, *args, **kwargs)
  File "/Users/ahmetcnd/.local/share/virtualenvs/openCryptoBot-D8P4_yx3/lib/python3.7/site-packages/telegram/bot.py", line 65, in decorator
    result = func(self, *args, **kwargs)
  File "/Users/ahmetcnd/.local/share/virtualenvs/openCryptoBot-D8P4_yx3/lib/python3.7/site-packages/telegram/bot.py", line 90, in decorator
    result = self._request.post(url, data, timeout=kwargs.get('timeout'))
  File "/Users/ahmetcnd/.local/share/virtualenvs/openCryptoBot-D8P4_yx3/lib/python3.7/site-packages/telegram/utils/request.py", line 309, in post
    headers={'Content-Type': 'application/json'})
  File "/Users/ahmetcnd/.local/share/virtualenvs/openCryptoBot-D8P4_yx3/lib/python3.7/site-packages/telegram/utils/request.py", line 223, in _request_wrapper
    raise BadRequest(message)
telegram.error.BadRequest: Replied message not found

During handling of the above exception, another exception occurred:

Traceback (most recent call last):
  File "/Users/ahmetcnd/.local/share/virtualenvs/openCryptoBot-D8P4_yx3/lib/python3.7/site-packages/telegram/ext/jobqueue.py", line 245, in tick
    job.run(self.bot)
  File "/Users/ahmetcnd/.local/share/virtualenvs/openCryptoBot-D8P4_yx3/lib/python3.7/site-packages/telegram/ext/jobqueue.py", line 372, in run
    self.callback(bot, self)
  File "/Users/ahmetcnd/Documents/telegrambot/openCryptoBot/opencryptobot/plugins/repeat.py", line 172, in _send_msg
    self.tgb.db.delete_rep(rep)
  File "/Users/ahmetcnd/Documents/telegrambot/openCryptoBot/opencryptobot/database.py", line 194, in delete_rep
    [repeater_id])
sqlite3.InterfaceError: Error binding parameter 0 - probably unsupported type.
2021-05-19 16:10:44,907 - ERROR - telegram.ext.updater - Error while getting Updates: Conflict: terminated by other getUpdates request; make sure that only one bot instance is running (409)
2021-05-19 16:10:44,907 - ERROR - root - Conflict: terminated by other getUpdates request; make sure that only one bot instance is running (409) - Class: TelegramBot - None
2021-05-19 16:10:45,919 - ERROR - root - Replied message not found - {'update_id': 406256829, 'message': {'message_id': 7924, 'date': 1620332356, 'chat': {'id': -1001216334216, 'type': 'supergroup', 'title': 'KRİPTO PUSULA', 'username': 'kriptopusulasi'}, 'text': '/p btt', 'entities': [{'type': 'bot_command', 'offset': 0, 'length': 3}, {'type': 'bot_command', 'offset': 9, 'length': 2}], 'caption_entities': [], 'photo': [], 'new_chat_members': [], 'new_chat_photo': [], 'delete_chat_photo': False, 'group_chat_created': False, 'supergroup_chat_created': False, 'channel_chat_created': False, 'from': {'id': 1087968824, 'first_name': 'Group', 'is_bot': True, 'username': 'GroupAnonymousBot'}}}
2021-05-19 16:10:45,920 - ERROR - JobQueue - An uncaught error was raised while executing job _send_msg
Traceback (most recent call last):
  File "/Users/ahmetcnd/Documents/telegrambot/openCryptoBot/opencryptobot/plugins/repeat.py", line 169, in _send_msg
    plgn.get_action(bot, updt, args=args)
  File "/Users/ahmetcnd/Documents/telegrambot/openCryptoBot/opencryptobot/plugin.py", line 106, in _save_data
    return func(self, bot, update, **kwargs)
  File "/Users/ahmetcnd/Documents/telegrambot/openCryptoBot/opencryptobot/plugin.py", line 73, in _send_typing_action
    return func(self, bot, update, **kwargs)
  File "/Users/ahmetcnd/Documents/telegrambot/openCryptoBot/opencryptobot/plugins/price.py", line 62, in get_action
    if RateLimit.limit_reached(update):
  File "/Users/ahmetcnd/Documents/telegrambot/openCryptoBot/opencryptobot/ratelimit.py", line 33, in limit_reached
    update.message.reply_text(msg)
  File "/Users/ahmetcnd/.local/share/virtualenvs/openCryptoBot-D8P4_yx3/lib/python3.7/site-packages/telegram/message.py", line 455, in reply_text
    return self.bot.send_message(self.chat_id, *args, **kwargs)
  File "/Users/ahmetcnd/.local/share/virtualenvs/openCryptoBot-D8P4_yx3/lib/python3.7/site-packages/telegram/bot.py", line 65, in decorator
    result = func(self, *args, **kwargs)
  File "/Users/ahmetcnd/.local/share/virtualenvs/openCryptoBot-D8P4_yx3/lib/python3.7/site-packages/telegram/bot.py", line 90, in decorator
    result = self._request.post(url, data, timeout=kwargs.get('timeout'))
  File "/Users/ahmetcnd/.local/share/virtualenvs/openCryptoBot-D8P4_yx3/lib/python3.7/site-packages/telegram/utils/request.py", line 309, in post
    headers={'Content-Type': 'application/json'})
  File "/Users/ahmetcnd/.local/share/virtualenvs/openCryptoBot-D8P4_yx3/lib/python3.7/site-packages/telegram/utils/request.py", line 223, in _request_wrapper
    raise BadRequest(message)
telegram.error.BadRequest: Replied message not found

During handling of the above exception, another exception occurred:

Traceback (most recent call last):
  File "/Users/ahmetcnd/.local/share/virtualenvs/openCryptoBot-D8P4_yx3/lib/python3.7/site-packages/telegram/ext/jobqueue.py", line 245, in tick
    job.run(self.bot)
  File "/Users/ahmetcnd/.local/share/virtualenvs/openCryptoBot-D8P4_yx3/lib/python3.7/site-packages/telegram/ext/jobqueue.py", line 372, in run
    self.callback(bot, self)
  File "/Users/ahmetcnd/Documents/telegrambot/openCryptoBot/opencryptobot/plugins/repeat.py", line 172, in _send_msg
    self.tgb.db.delete_rep(rep)
  File "/Users/ahmetcnd/Documents/telegrambot/openCryptoBot/opencryptobot/database.py", line 194, in delete_rep
    [repeater_id])
sqlite3.InterfaceError: Error binding parameter 0 - probably unsupported type.
2021-05-19 16:10:45,923 - INFO - root - Starting Caching
2021-05-19 16:10:49,056 - ERROR - telegram.ext.updater - Error while getting Updates: Conflict: terminated by other getUpdates request; make sure that only one bot instance is running (409)
2021-05-19 16:10:49,056 - ERROR - root - Conflict: terminated by other getUpdates request; make sure that only one bot instance is running (409) - Class: TelegramBot - None
2021-05-19 16:11:19,779 - ERROR - telegram.ext.updater - Error while getting Updates: Conflict: terminated by other getUpdates request; make sure that only one bot instance is running (409)
2021-05-19 16:11:19,780 - ERROR - root - Conflict: terminated by other getUpdates request; make sure that only one bot instance is running (409) - Class: TelegramBot - None
2021-05-19 16:11:23,857 - ERROR - telegram.ext.updater - Error while getting Updates: Conflict: terminated by other getUpdates request; make sure that only one bot instance is running (409)
2021-05-19 16:11:23,857 - ERROR - root - Conflict: terminated by other getUpdates request; make sure that only one bot instance is running (409) - Class: TelegramBot - None
2021-05-19 16:11:23,915 - ERROR - JobQueue - An uncaught error was raised while executing job refresh
Traceback (most recent call last):
  File "/Users/ahmetcnd/.local/share/virtualenvs/openCryptoBot-D8P4_yx3/lib/python3.7/site-packages/telegram/ext/jobqueue.py", line 245, in tick
    job.run(self.bot)
  File "/Users/ahmetcnd/.local/share/virtualenvs/openCryptoBot-D8P4_yx3/lib/python3.7/site-packages/telegram/ext/jobqueue.py", line 372, in run
    self.callback(bot, self)
  File "/Users/ahmetcnd/Documents/telegrambot/openCryptoBot/opencryptobot/api/apicache.py", line 23, in refresh
    APICache.refresh_coinmarketcap_coin_list()
  File "/Users/ahmetcnd/Documents/telegrambot/openCryptoBot/opencryptobot/api/apicache.py", line 39, in refresh_coinmarketcap_coin_list
    APICache.cmc_coin_list = Market().listings()["data"]
TypeError: 'JSONDecodeError' object is not subscriptable
2021-05-19 16:11:33,171 - ERROR - root - Replied message not found - {'update_id': 406256827, 'message': {'message_id': 7920, 'date': 1620332268, 'chat': {'id': -1001216334216, 'type': 'supergroup', 'title': 'KRİPTO PUSULA', 'username': 'kriptopusulasi'}, 'text': '/p eth', 'entities': [{'type': 'bot_command', 'offset': 0, 'length': 3}, {'type': 'bot_command', 'offset': 9, 'length': 2}], 'caption_entities': [], 'photo': [], 'new_chat_members': [], 'new_chat_photo': [], 'delete_chat_photo': False, 'group_chat_created': False, 'supergroup_chat_created': False, 'channel_chat_created': False, 'from': {'id': 1087968824, 'first_name': 'Group', 'is_bot': True, 'username': 'GroupAnonymousBot'}}}
2021-05-19 16:11:33,173 - ERROR - JobQueue - An uncaught error was raised while executing job _send_msg
Traceback (most recent call last):
  File "/Users/ahmetcnd/Documents/telegrambot/openCryptoBot/opencryptobot/plugins/repeat.py", line 169, in _send_msg
    plgn.get_action(bot, updt, args=args)
  File "/Users/ahmetcnd/Documents/telegrambot/openCryptoBot/opencryptobot/plugin.py", line 106, in _save_data
    return func(self, bot, update, **kwargs)
  File "/Users/ahmetcnd/Documents/telegrambot/openCryptoBot/opencryptobot/plugin.py", line 73, in _send_typing_action
    return func(self, bot, update, **kwargs)
  File "/Users/ahmetcnd/Documents/telegrambot/openCryptoBot/opencryptobot/plugins/price.py", line 149, in get_action
    self.send_msg(msg, update, keywords)
  File "/Users/ahmetcnd/Documents/telegrambot/openCryptoBot/opencryptobot/plugin.py", line 144, in send_msg
    disable_notification=not notify)
  File "/Users/ahmetcnd/.local/share/virtualenvs/openCryptoBot-D8P4_yx3/lib/python3.7/site-packages/telegram/message.py", line 455, in reply_text
    return self.bot.send_message(self.chat_id, *args, **kwargs)
  File "/Users/ahmetcnd/.local/share/virtualenvs/openCryptoBot-D8P4_yx3/lib/python3.7/site-packages/telegram/bot.py", line 65, in decorator
    result = func(self, *args, **kwargs)
  File "/Users/ahmetcnd/.local/share/virtualenvs/openCryptoBot-D8P4_yx3/lib/python3.7/site-packages/telegram/bot.py", line 90, in decorator
    result = self._request.post(url, data, timeout=kwargs.get('timeout'))
  File "/Users/ahmetcnd/.local/share/virtualenvs/openCryptoBot-D8P4_yx3/lib/python3.7/site-packages/telegram/utils/request.py", line 309, in post
    headers={'Content-Type': 'application/json'})
  File "/Users/ahmetcnd/.local/share/virtualenvs/openCryptoBot-D8P4_yx3/lib/python3.7/site-packages/telegram/utils/request.py", line 223, in _request_wrapper
    raise BadRequest(message)
telegram.error.BadRequest: Replied message not found

During handling of the above exception, another exception occurred:

Traceback (most recent call last):
  File "/Users/ahmetcnd/.local/share/virtualenvs/openCryptoBot-D8P4_yx3/lib/python3.7/site-packages/telegram/ext/jobqueue.py", line 245, in tick
    job.run(self.bot)
  File "/Users/ahmetcnd/.local/share/virtualenvs/openCryptoBot-D8P4_yx3/lib/python3.7/site-packages/telegram/ext/jobqueue.py", line 372, in run
    self.callback(bot, self)
  File "/Users/ahmetcnd/Documents/telegrambot/openCryptoBot/opencryptobot/plugins/repeat.py", line 172, in _send_msg
    self.tgb.db.delete_rep(rep)
  File "/Users/ahmetcnd/Documents/telegrambot/openCryptoBot/opencryptobot/database.py", line 194, in delete_rep
    [repeater_id])
sqlite3.InterfaceError: Error binding parameter 0 - probably unsupported type.
2021-05-19 16:11:42,347 - ERROR - root - ConnectionError(ProtocolError('Connection aborted.', ConnectionResetError(54, 'Connection reset by peer'))) - ('Connection aborted.', ConnectionResetError(54, 'Connection reset by peer')) - Class: Price - {'update_id': 406256825, 'message': {'message_id': 7917, 'date': 1620332165, 'chat': {'id': -1001216334216, 'type': 'supergroup', 'title': 'KRİPTO PUSULA', 'username': 'kriptopusulasi'}, 'text': '/p btc', 'entities': [{'type': 'bot_command', 'offset': 0, 'length': 3}, {'type': 'bot_command', 'offset': 9, 'length': 2}], 'caption_entities': [], 'photo': [], 'new_chat_members': [], 'new_chat_photo': [], 'delete_chat_photo': False, 'group_chat_created': False, 'supergroup_chat_created': False, 'channel_chat_created': False, 'from': {'id': 1087968824, 'first_name': 'Group', 'is_bot': True, 'username': 'GroupAnonymousBot'}}}
2021-05-19 16:11:48,446 - ERROR - root - Replied message not found - {'update_id': 406256828, 'message': {'message_id': 7922, 'date': 1620332306, 'chat': {'id': -1001216334216, 'type': 'supergroup', 'title': 'KRİPTO PUSULA', 'username': 'kriptopusulasi'}, 'text': '/p doge', 'entities': [{'type': 'bot_command', 'offset': 0, 'length': 3}, {'type': 'bot_command', 'offset': 9, 'length': 2}], 'caption_entities': [], 'photo': [], 'new_chat_members': [], 'new_chat_photo': [], 'delete_chat_photo': False, 'group_chat_created': False, 'supergroup_chat_created': False, 'channel_chat_created': False, 'from': {'id': 1087968824, 'first_name': 'Group', 'is_bot': True, 'username': 'GroupAnonymousBot'}}}
2021-05-19 16:11:48,447 - ERROR - JobQueue - An uncaught error was raised while executing job _send_msg
Traceback (most recent call last):
  File "/Users/ahmetcnd/Documents/telegrambot/openCryptoBot/opencryptobot/plugins/repeat.py", line 169, in _send_msg
    plgn.get_action(bot, updt, args=args)
  File "/Users/ahmetcnd/Documents/telegrambot/openCryptoBot/opencryptobot/plugin.py", line 106, in _save_data
    return func(self, bot, update, **kwargs)
  File "/Users/ahmetcnd/Documents/telegrambot/openCryptoBot/opencryptobot/plugin.py", line 73, in _send_typing_action
    return func(self, bot, update, **kwargs)
  File "/Users/ahmetcnd/Documents/telegrambot/openCryptoBot/opencryptobot/plugins/price.py", line 149, in get_action
    self.send_msg(msg, update, keywords)
  File "/Users/ahmetcnd/Documents/telegrambot/openCryptoBot/opencryptobot/plugin.py", line 144, in send_msg
    disable_notification=not notify)
  File "/Users/ahmetcnd/.local/share/virtualenvs/openCryptoBot-D8P4_yx3/lib/python3.7/site-packages/telegram/message.py", line 455, in reply_text
    return self.bot.send_message(self.chat_id, *args, **kwargs)
  File "/Users/ahmetcnd/.local/share/virtualenvs/openCryptoBot-D8P4_yx3/lib/python3.7/site-packages/telegram/bot.py", line 65, in decorator
    result = func(self, *args, **kwargs)
  File "/Users/ahmetcnd/.local/share/virtualenvs/openCryptoBot-D8P4_yx3/lib/python3.7/site-packages/telegram/bot.py", line 90, in decorator
    result = self._request.post(url, data, timeout=kwargs.get('timeout'))
  File "/Users/ahmetcnd/.local/share/virtualenvs/openCryptoBot-D8P4_yx3/lib/python3.7/site-packages/telegram/utils/request.py", line 309, in post
    headers={'Content-Type': 'application/json'})
  File "/Users/ahmetcnd/.local/share/virtualenvs/openCryptoBot-D8P4_yx3/lib/python3.7/site-packages/telegram/utils/request.py", line 223, in _request_wrapper
    raise BadRequest(message)
telegram.error.BadRequest: Replied message not found

During handling of the above exception, another exception occurred:

Traceback (most recent call last):
  File "/Users/ahmetcnd/.local/share/virtualenvs/openCryptoBot-D8P4_yx3/lib/python3.7/site-packages/telegram/ext/jobqueue.py", line 245, in tick
    job.run(self.bot)
  File "/Users/ahmetcnd/.local/share/virtualenvs/openCryptoBot-D8P4_yx3/lib/python3.7/site-packages/telegram/ext/jobqueue.py", line 372, in run
    self.callback(bot, self)
  File "/Users/ahmetcnd/Documents/telegrambot/openCryptoBot/opencryptobot/plugins/repeat.py", line 172, in _send_msg
    self.tgb.db.delete_rep(rep)
  File "/Users/ahmetcnd/Documents/telegrambot/openCryptoBot/opencryptobot/database.py", line 194, in delete_rep
    [repeater_id])
sqlite3.InterfaceError: Error binding parameter 0 - probably unsupported type.
2021-05-19 16:11:50,492 - ERROR - root - Replied message not found - {'update_id': 406256827, 'message': {'message_id': 7920, 'date': 1620332268, 'chat': {'id': -1001216334216, 'type': 'supergroup', 'title': 'KRİPTO PUSULA', 'username': 'kriptopusulasi'}, 'text': '/p eth', 'entities': [{'type': 'bot_command', 'offset': 0, 'length': 3}, {'type': 'bot_command', 'offset': 9, 'length': 2}], 'caption_entities': [], 'photo': [], 'new_chat_members': [], 'new_chat_photo': [], 'delete_chat_photo': False, 'group_chat_created': False, 'supergroup_chat_created': False, 'channel_chat_created': False, 'from': {'id': 1087968824, 'first_name': 'Group', 'is_bot': True, 'username': 'GroupAnonymousBot'}}}
2021-05-19 16:11:50,493 - ERROR - JobQueue - An uncaught error was raised while executing job _send_msg
Traceback (most recent call last):
  File "/Users/ahmetcnd/Documents/telegrambot/openCryptoBot/opencryptobot/plugins/repeat.py", line 169, in _send_msg
    plgn.get_action(bot, updt, args=args)
  File "/Users/ahmetcnd/Documents/telegrambot/openCryptoBot/opencryptobot/plugin.py", line 106, in _save_data
    return func(self, bot, update, **kwargs)
  File "/Users/ahmetcnd/Documents/telegrambot/openCryptoBot/opencryptobot/plugin.py", line 73, in _send_typing_action
    return func(self, bot, update, **kwargs)
  File "/Users/ahmetcnd/Documents/telegrambot/openCryptoBot/opencryptobot/plugins/price.py", line 62, in get_action
    if RateLimit.limit_reached(update):
  File "/Users/ahmetcnd/Documents/telegrambot/openCryptoBot/opencryptobot/ratelimit.py", line 33, in limit_reached
    update.message.reply_text(msg)
  File "/Users/ahmetcnd/.local/share/virtualenvs/openCryptoBot-D8P4_yx3/lib/python3.7/site-packages/telegram/message.py", line 455, in reply_text
    return self.bot.send_message(self.chat_id, *args, **kwargs)
  File "/Users/ahmetcnd/.local/share/virtualenvs/openCryptoBot-D8P4_yx3/lib/python3.7/site-packages/telegram/bot.py", line 65, in decorator
    result = func(self, *args, **kwargs)
  File "/Users/ahmetcnd/.local/share/virtualenvs/openCryptoBot-D8P4_yx3/lib/python3.7/site-packages/telegram/bot.py", line 90, in decorator
    result = self._request.post(url, data, timeout=kwargs.get('timeout'))
  File "/Users/ahmetcnd/.local/share/virtualenvs/openCryptoBot-D8P4_yx3/lib/python3.7/site-packages/telegram/utils/request.py", line 309, in post
    headers={'Content-Type': 'application/json'})
  File "/Users/ahmetcnd/.local/share/virtualenvs/openCryptoBot-D8P4_yx3/lib/python3.7/site-packages/telegram/utils/request.py", line 223, in _request_wrapper
    raise BadRequest(message)
telegram.error.BadRequest: Replied message not found

During handling of the above exception, another exception occurred:

Traceback (most recent call last):
  File "/Users/ahmetcnd/.local/share/virtualenvs/openCryptoBot-D8P4_yx3/lib/python3.7/site-packages/telegram/ext/jobqueue.py", line 245, in tick
    job.run(self.bot)
  File "/Users/ahmetcnd/.local/share/virtualenvs/openCryptoBot-D8P4_yx3/lib/python3.7/site-packages/telegram/ext/jobqueue.py", line 372, in run
    self.callback(bot, self)
  File "/Users/ahmetcnd/Documents/telegrambot/openCryptoBot/opencryptobot/plugins/repeat.py", line 172, in _send_msg
    self.tgb.db.delete_rep(rep)
  File "/Users/ahmetcnd/Documents/telegrambot/openCryptoBot/opencryptobot/database.py", line 194, in delete_rep
    [repeater_id])
sqlite3.InterfaceError: Error binding parameter 0 - probably unsupported type.
2021-05-19 16:11:51,442 - ERROR - root - Replied message not found - {'update_id': 406256829, 'message': {'message_id': 7924, 'date': 1620332356, 'chat': {'id': -1001216334216, 'type': 'supergroup', 'title': 'KRİPTO PUSULA', 'username': 'kriptopusulasi'}, 'text': '/p btt', 'entities': [{'type': 'bot_command', 'offset': 0, 'length': 3}, {'type': 'bot_command', 'offset': 9, 'length': 2}], 'caption_entities': [], 'photo': [], 'new_chat_members': [], 'new_chat_photo': [], 'delete_chat_photo': False, 'group_chat_created': False, 'supergroup_chat_created': False, 'channel_chat_created': False, 'from': {'id': 1087968824, 'first_name': 'Group', 'is_bot': True, 'username': 'GroupAnonymousBot'}}}
2021-05-19 16:11:51,443 - ERROR - JobQueue - An uncaught error was raised while executing job _send_msg
Traceback (most recent call last):
  File "/Users/ahmetcnd/Documents/telegrambot/openCryptoBot/opencryptobot/plugins/repeat.py", line 169, in _send_msg
    plgn.get_action(bot, updt, args=args)
  File "/Users/ahmetcnd/Documents/telegrambot/openCryptoBot/opencryptobot/plugin.py", line 106, in _save_data
    return func(self, bot, update, **kwargs)
  File "/Users/ahmetcnd/Documents/telegrambot/openCryptoBot/opencryptobot/plugin.py", line 73, in _send_typing_action
    return func(self, bot, update, **kwargs)
  File "/Users/ahmetcnd/Documents/telegrambot/openCryptoBot/opencryptobot/plugins/price.py", line 62, in get_action
    if RateLimit.limit_reached(update):
  File "/Users/ahmetcnd/Documents/telegrambot/openCryptoBot/opencryptobot/ratelimit.py", line 33, in limit_reached
    update.message.reply_text(msg)
  File "/Users/ahmetcnd/.local/share/virtualenvs/openCryptoBot-D8P4_yx3/lib/python3.7/site-packages/telegram/message.py", line 455, in reply_text
    return self.bot.send_message(self.chat_id, *args, **kwargs)
  File "/Users/ahmetcnd/.local/share/virtualenvs/openCryptoBot-D8P4_yx3/lib/python3.7/site-packages/telegram/bot.py", line 65, in decorator
    result = func(self, *args, **kwargs)
  File "/Users/ahmetcnd/.local/share/virtualenvs/openCryptoBot-D8P4_yx3/lib/python3.7/site-packages/telegram/bot.py", line 90, in decorator
    result = self._request.post(url, data, timeout=kwargs.get('timeout'))
  File "/Users/ahmetcnd/.local/share/virtualenvs/openCryptoBot-D8P4_yx3/lib/python3.7/site-packages/telegram/utils/request.py", line 309, in post
    headers={'Content-Type': 'application/json'})
  File "/Users/ahmetcnd/.local/share/virtualenvs/openCryptoBot-D8P4_yx3/lib/python3.7/site-packages/telegram/utils/request.py", line 223, in _request_wrapper
    raise BadRequest(message)
telegram.error.BadRequest: Replied message not found

During handling of the above exception, another exception occurred:

Traceback (most recent call last):
  File "/Users/ahmetcnd/.local/share/virtualenvs/openCryptoBot-D8P4_yx3/lib/python3.7/site-packages/telegram/ext/jobqueue.py", line 245, in tick
    job.run(self.bot)
  File "/Users/ahmetcnd/.local/share/virtualenvs/openCryptoBot-D8P4_yx3/lib/python3.7/site-packages/telegram/ext/jobqueue.py", line 372, in run
    self.callback(bot, self)
  File "/Users/ahmetcnd/Documents/telegrambot/openCryptoBot/opencryptobot/plugins/repeat.py", line 172, in _send_msg
    self.tgb.db.delete_rep(rep)
  File "/Users/ahmetcnd/Documents/telegrambot/openCryptoBot/opencryptobot/database.py", line 194, in delete_rep
    [repeater_id])
sqlite3.InterfaceError: Error binding parameter 0 - probably unsupported type.
2021-05-19 16:11:54,521 - ERROR - telegram.ext.updater - Error while getting Updates: Conflict: terminated by other getUpdates request; make sure that only one bot instance is running (409)
2021-05-19 16:11:54,522 - ERROR - root - Conflict: terminated by other getUpdates request; make sure that only one bot instance is running (409) - Class: TelegramBot - None
2021-05-19 16:11:58,687 - ERROR - telegram.ext.updater - Error while getting Updates: Conflict: terminated by other getUpdates request; make sure that only one bot instance is running (409)
2021-05-19 16:11:58,687 - ERROR - root - Conflict: terminated by other getUpdates request; make sure that only one bot instance is running (409) - Class: TelegramBot - None
2021-05-19 16:12:05,551 - ERROR - root - Timed out - {'update_id': 406256827, 'message': {'message_id': 7920, 'date': 1620332268, 'chat': {'id': -1001216334216, 'type': 'supergroup', 'title': 'KRİPTO PUSULA', 'username': 'kriptopusulasi'}, 'text': '/p eth', 'entities': [{'type': 'bot_command', 'offset': 0, 'length': 3}, {'type': 'bot_command', 'offset': 9, 'length': 2}], 'caption_entities': [], 'photo': [], 'new_chat_members': [], 'new_chat_photo': [], 'delete_chat_photo': False, 'group_chat_created': False, 'supergroup_chat_created': False, 'channel_chat_created': False, 'from': {'id': 1087968824, 'first_name': 'Group', 'is_bot': True, 'username': 'GroupAnonymousBot'}}}
2021-05-19 16:12:06,867 - ERROR - root - Replied message not found - {'update_id': 406256827, 'message': {'message_id': 7920, 'date': 1620332268, 'chat': {'id': -1001216334216, 'type': 'supergroup', 'title': 'KRİPTO PUSULA', 'username': 'kriptopusulasi'}, 'text': '/p eth', 'entities': [{'type': 'bot_command', 'offset': 0, 'length': 3}, {'type': 'bot_command', 'offset': 9, 'length': 2}], 'caption_entities': [], 'photo': [], 'new_chat_members': [], 'new_chat_photo': [], 'delete_chat_photo': False, 'group_chat_created': False, 'supergroup_chat_created': False, 'channel_chat_created': False, 'from': {'id': 1087968824, 'first_name': 'Group', 'is_bot': True, 'username': 'GroupAnonymousBot'}}}
2021-05-19 16:12:06,868 - ERROR - JobQueue - An uncaught error was raised while executing job _send_msg
Traceback (most recent call last):
  File "/Users/ahmetcnd/Documents/telegrambot/openCryptoBot/opencryptobot/plugins/repeat.py", line 169, in _send_msg
    plgn.get_action(bot, updt, args=args)
  File "/Users/ahmetcnd/Documents/telegrambot/openCryptoBot/opencryptobot/plugin.py", line 106, in _save_data
    return func(self, bot, update, **kwargs)
  File "/Users/ahmetcnd/Documents/telegrambot/openCryptoBot/opencryptobot/plugin.py", line 73, in _send_typing_action
    return func(self, bot, update, **kwargs)
  File "/Users/ahmetcnd/Documents/telegrambot/openCryptoBot/opencryptobot/plugins/price.py", line 149, in get_action
    self.send_msg(msg, update, keywords)
  File "/Users/ahmetcnd/Documents/telegrambot/openCryptoBot/opencryptobot/plugin.py", line 144, in send_msg
    disable_notification=not notify)
  File "/Users/ahmetcnd/.local/share/virtualenvs/openCryptoBot-D8P4_yx3/lib/python3.7/site-packages/telegram/message.py", line 455, in reply_text
    return self.bot.send_message(self.chat_id, *args, **kwargs)
  File "/Users/ahmetcnd/.local/share/virtualenvs/openCryptoBot-D8P4_yx3/lib/python3.7/site-packages/telegram/bot.py", line 65, in decorator
    result = func(self, *args, **kwargs)
  File "/Users/ahmetcnd/.local/share/virtualenvs/openCryptoBot-D8P4_yx3/lib/python3.7/site-packages/telegram/bot.py", line 90, in decorator
    result = self._request.post(url, data, timeout=kwargs.get('timeout'))
  File "/Users/ahmetcnd/.local/share/virtualenvs/openCryptoBot-D8P4_yx3/lib/python3.7/site-packages/telegram/utils/request.py", line 309, in post
    headers={'Content-Type': 'application/json'})
  File "/Users/ahmetcnd/.local/share/virtualenvs/openCryptoBot-D8P4_yx3/lib/python3.7/site-packages/telegram/utils/request.py", line 223, in _request_wrapper
    raise BadRequest(message)
telegram.error.BadRequest: Replied message not found

During handling of the above exception, another exception occurred:

Traceback (most recent call last):
  File "/Users/ahmetcnd/.local/share/virtualenvs/openCryptoBot-D8P4_yx3/lib/python3.7/site-packages/telegram/ext/jobqueue.py", line 245, in tick
    job.run(self.bot)
  File "/Users/ahmetcnd/.local/share/virtualenvs/openCryptoBot-D8P4_yx3/lib/python3.7/site-packages/telegram/ext/jobqueue.py", line 372, in run
    self.callback(bot, self)
  File "/Users/ahmetcnd/Documents/telegrambot/openCryptoBot/opencryptobot/plugins/repeat.py", line 172, in _send_msg
    self.tgb.db.delete_rep(rep)
  File "/Users/ahmetcnd/Documents/telegrambot/openCryptoBot/opencryptobot/database.py", line 194, in delete_rep
    [repeater_id])
sqlite3.InterfaceError: Error binding parameter 0 - probably unsupported type.
2021-05-19 16:12:08,993 - ERROR - root - Replied message not found - {'update_id': 406256828, 'message': {'message_id': 7922, 'date': 1620332306, 'chat': {'id': -1001216334216, 'type': 'supergroup', 'title': 'KRİPTO PUSULA', 'username': 'kriptopusulasi'}, 'text': '/p doge', 'entities': [{'type': 'bot_command', 'offset': 0, 'length': 3}, {'type': 'bot_command', 'offset': 9, 'length': 2}], 'caption_entities': [], 'photo': [], 'new_chat_members': [], 'new_chat_photo': [], 'delete_chat_photo': False, 'group_chat_created': False, 'supergroup_chat_created': False, 'channel_chat_created': False, 'from': {'id': 1087968824, 'first_name': 'Group', 'is_bot': True, 'username': 'GroupAnonymousBot'}}}
2021-05-19 16:12:08,994 - ERROR - JobQueue - An uncaught error was raised while executing job _send_msg
Traceback (most recent call last):
  File "/Users/ahmetcnd/Documents/telegrambot/openCryptoBot/opencryptobot/plugins/repeat.py", line 169, in _send_msg
    plgn.get_action(bot, updt, args=args)
  File "/Users/ahmetcnd/Documents/telegrambot/openCryptoBot/opencryptobot/plugin.py", line 106, in _save_data
    return func(self, bot, update, **kwargs)
  File "/Users/ahmetcnd/Documents/telegrambot/openCryptoBot/opencryptobot/plugin.py", line 73, in _send_typing_action
    return func(self, bot, update, **kwargs)
  File "/Users/ahmetcnd/Documents/telegrambot/openCryptoBot/opencryptobot/plugins/price.py", line 149, in get_action
    self.send_msg(msg, update, keywords)
  File "/Users/ahmetcnd/Documents/telegrambot/openCryptoBot/opencryptobot/plugin.py", line 144, in send_msg
    disable_notification=not notify)
  File "/Users/ahmetcnd/.local/share/virtualenvs/openCryptoBot-D8P4_yx3/lib/python3.7/site-packages/telegram/message.py", line 455, in reply_text
    return self.bot.send_message(self.chat_id, *args, **kwargs)
  File "/Users/ahmetcnd/.local/share/virtualenvs/openCryptoBot-D8P4_yx3/lib/python3.7/site-packages/telegram/bot.py", line 65, in decorator
    result = func(self, *args, **kwargs)
  File "/Users/ahmetcnd/.local/share/virtualenvs/openCryptoBot-D8P4_yx3/lib/python3.7/site-packages/telegram/bot.py", line 90, in decorator
    result = self._request.post(url, data, timeout=kwargs.get('timeout'))
  File "/Users/ahmetcnd/.local/share/virtualenvs/openCryptoBot-D8P4_yx3/lib/python3.7/site-packages/telegram/utils/request.py", line 309, in post
    headers={'Content-Type': 'application/json'})
  File "/Users/ahmetcnd/.local/share/virtualenvs/openCryptoBot-D8P4_yx3/lib/python3.7/site-packages/telegram/utils/request.py", line 223, in _request_wrapper
    raise BadRequest(message)
telegram.error.BadRequest: Replied message not found

During handling of the above exception, another exception occurred:

Traceback (most recent call last):
  File "/Users/ahmetcnd/.local/share/virtualenvs/openCryptoBot-D8P4_yx3/lib/python3.7/site-packages/telegram/ext/jobqueue.py", line 245, in tick
    job.run(self.bot)
  File "/Users/ahmetcnd/.local/share/virtualenvs/openCryptoBot-D8P4_yx3/lib/python3.7/site-packages/telegram/ext/jobqueue.py", line 372, in run
    self.callback(bot, self)
  File "/Users/ahmetcnd/Documents/telegrambot/openCryptoBot/opencryptobot/plugins/repeat.py", line 172, in _send_msg
    self.tgb.db.delete_rep(rep)
  File "/Users/ahmetcnd/Documents/telegrambot/openCryptoBot/opencryptobot/database.py", line 194, in delete_rep
    [repeater_id])
sqlite3.InterfaceError: Error binding parameter 0 - probably unsupported type.
2021-05-19 16:12:08,996 - INFO - root - Starting Caching
2021-05-19 16:12:28,468 - ERROR - JobQueue - An uncaught error was raised while executing job refresh
Traceback (most recent call last):
  File "/Users/ahmetcnd/.local/share/virtualenvs/openCryptoBot-D8P4_yx3/lib/python3.7/site-packages/telegram/ext/jobqueue.py", line 245, in tick
    job.run(self.bot)
  File "/Users/ahmetcnd/.local/share/virtualenvs/openCryptoBot-D8P4_yx3/lib/python3.7/site-packages/telegram/ext/jobqueue.py", line 372, in run
    self.callback(bot, self)
  File "/Users/ahmetcnd/Documents/telegrambot/openCryptoBot/opencryptobot/api/apicache.py", line 23, in refresh
    APICache.refresh_coinmarketcap_coin_list()
  File "/Users/ahmetcnd/Documents/telegrambot/openCryptoBot/opencryptobot/api/apicache.py", line 39, in refresh_coinmarketcap_coin_list
    APICache.cmc_coin_list = Market().listings()["data"]
TypeError: 'JSONDecodeError' object is not subscriptable
2021-05-19 16:12:29,373 - ERROR - telegram.ext.updater - Error while getting Updates: Conflict: terminated by other getUpdates request; make sure that only one bot instance is running (409)
2021-05-19 16:12:29,376 - ERROR - root - Conflict: terminated by other getUpdates request; make sure that only one bot instance is running (409) - Class: TelegramBot - None
2021-05-19 16:12:33,455 - ERROR - telegram.ext.updater - Error while getting Updates: Conflict: terminated by other getUpdates request; make sure that only one bot instance is running (409)
2021-05-19 16:12:33,456 - ERROR - root - Conflict: terminated by other getUpdates request; make sure that only one bot instance is running (409) - Class: TelegramBot - None
2021-05-19 16:12:39,713 - ERROR - root - Replied message not found - {'update_id': 406256827, 'message': {'message_id': 7920, 'date': 1620332268, 'chat': {'id': -1001216334216, 'type': 'supergroup', 'title': 'KRİPTO PUSULA', 'username': 'kriptopusulasi'}, 'text': '/p eth', 'entities': [{'type': 'bot_command', 'offset': 0, 'length': 3}, {'type': 'bot_command', 'offset': 9, 'length': 2}], 'caption_entities': [], 'photo': [], 'new_chat_members': [], 'new_chat_photo': [], 'delete_chat_photo': False, 'group_chat_created': False, 'supergroup_chat_created': False, 'channel_chat_created': False, 'from': {'id': 1087968824, 'first_name': 'Group', 'is_bot': True, 'username': 'GroupAnonymousBot'}}}
2021-05-19 16:12:39,714 - ERROR - JobQueue - An uncaught error was raised while executing job _send_msg
Traceback (most recent call last):
  File "/Users/ahmetcnd/Documents/telegrambot/openCryptoBot/opencryptobot/plugins/repeat.py", line 169, in _send_msg
    plgn.get_action(bot, updt, args=args)
  File "/Users/ahmetcnd/Documents/telegrambot/openCryptoBot/opencryptobot/plugin.py", line 106, in _save_data
    return func(self, bot, update, **kwargs)
  File "/Users/ahmetcnd/Documents/telegrambot/openCryptoBot/opencryptobot/plugin.py", line 73, in _send_typing_action
    return func(self, bot, update, **kwargs)
  File "/Users/ahmetcnd/Documents/telegrambot/openCryptoBot/opencryptobot/plugins/price.py", line 149, in get_action
    self.send_msg(msg, update, keywords)
  File "/Users/ahmetcnd/Documents/telegrambot/openCryptoBot/opencryptobot/plugin.py", line 144, in send_msg
    disable_notification=not notify)
  File "/Users/ahmetcnd/.local/share/virtualenvs/openCryptoBot-D8P4_yx3/lib/python3.7/site-packages/telegram/message.py", line 455, in reply_text
    return self.bot.send_message(self.chat_id, *args, **kwargs)
  File "/Users/ahmetcnd/.local/share/virtualenvs/openCryptoBot-D8P4_yx3/lib/python3.7/site-packages/telegram/bot.py", line 65, in decorator
    result = func(self, *args, **kwargs)
  File "/Users/ahmetcnd/.local/share/virtualenvs/openCryptoBot-D8P4_yx3/lib/python3.7/site-packages/telegram/bot.py", line 90, in decorator
    result = self._request.post(url, data, timeout=kwargs.get('timeout'))
  File "/Users/ahmetcnd/.local/share/virtualenvs/openCryptoBot-D8P4_yx3/lib/python3.7/site-packages/telegram/utils/request.py", line 309, in post
    headers={'Content-Type': 'application/json'})
  File "/Users/ahmetcnd/.local/share/virtualenvs/openCryptoBot-D8P4_yx3/lib/python3.7/site-packages/telegram/utils/request.py", line 223, in _request_wrapper
    raise BadRequest(message)
telegram.error.BadRequest: Replied message not found

During handling of the above exception, another exception occurred:

Traceback (most recent call last):
  File "/Users/ahmetcnd/.local/share/virtualenvs/openCryptoBot-D8P4_yx3/lib/python3.7/site-packages/telegram/ext/jobqueue.py", line 245, in tick
    job.run(self.bot)
  File "/Users/ahmetcnd/.local/share/virtualenvs/openCryptoBot-D8P4_yx3/lib/python3.7/site-packages/telegram/ext/jobqueue.py", line 372, in run
    self.callback(bot, self)
  File "/Users/ahmetcnd/Documents/telegrambot/openCryptoBot/opencryptobot/plugins/repeat.py", line 172, in _send_msg
    self.tgb.db.delete_rep(rep)
  File "/Users/ahmetcnd/Documents/telegrambot/openCryptoBot/opencryptobot/database.py", line 194, in delete_rep
    [repeater_id])
sqlite3.InterfaceError: Error binding parameter 0 - probably unsupported type.
2021-05-19 16:12:41,760 - ERROR - root - Replied message not found - {'update_id': 406256829, 'message': {'message_id': 7924, 'date': 1620332356, 'chat': {'id': -1001216334216, 'type': 'supergroup', 'title': 'KRİPTO PUSULA', 'username': 'kriptopusulasi'}, 'text': '/p btt', 'entities': [{'type': 'bot_command', 'offset': 0, 'length': 3}, {'type': 'bot_command', 'offset': 9, 'length': 2}], 'caption_entities': [], 'photo': [], 'new_chat_members': [], 'new_chat_photo': [], 'delete_chat_photo': False, 'group_chat_created': False, 'supergroup_chat_created': False, 'channel_chat_created': False, 'from': {'id': 1087968824, 'first_name': 'Group', 'is_bot': True, 'username': 'GroupAnonymousBot'}}}
2021-05-19 16:12:41,761 - ERROR - JobQueue - An uncaught error was raised while executing job _send_msg
Traceback (most recent call last):
  File "/Users/ahmetcnd/Documents/telegrambot/openCryptoBot/opencryptobot/plugins/repeat.py", line 169, in _send_msg
    plgn.get_action(bot, updt, args=args)
  File "/Users/ahmetcnd/Documents/telegrambot/openCryptoBot/opencryptobot/plugin.py", line 106, in _save_data
    return func(self, bot, update, **kwargs)
  File "/Users/ahmetcnd/Documents/telegrambot/openCryptoBot/opencryptobot/plugin.py", line 73, in _send_typing_action
    return func(self, bot, update, **kwargs)
  File "/Users/ahmetcnd/Documents/telegrambot/openCryptoBot/opencryptobot/plugins/price.py", line 149, in get_action
    self.send_msg(msg, update, keywords)
  File "/Users/ahmetcnd/Documents/telegrambot/openCryptoBot/opencryptobot/plugin.py", line 144, in send_msg
    disable_notification=not notify)
  File "/Users/ahmetcnd/.local/share/virtualenvs/openCryptoBot-D8P4_yx3/lib/python3.7/site-packages/telegram/message.py", line 455, in reply_text
    return self.bot.send_message(self.chat_id, *args, **kwargs)
  File "/Users/ahmetcnd/.local/share/virtualenvs/openCryptoBot-D8P4_yx3/lib/python3.7/site-packages/telegram/bot.py", line 65, in decorator
    result = func(self, *args, **kwargs)
  File "/Users/ahmetcnd/.local/share/virtualenvs/openCryptoBot-D8P4_yx3/lib/python3.7/site-packages/telegram/bot.py", line 90, in decorator
    result = self._request.post(url, data, timeout=kwargs.get('timeout'))
  File "/Users/ahmetcnd/.local/share/virtualenvs/openCryptoBot-D8P4_yx3/lib/python3.7/site-packages/telegram/utils/request.py", line 309, in post
    headers={'Content-Type': 'application/json'})
  File "/Users/ahmetcnd/.local/share/virtualenvs/openCryptoBot-D8P4_yx3/lib/python3.7/site-packages/telegram/utils/request.py", line 223, in _request_wrapper
    raise BadRequest(message)
telegram.error.BadRequest: Replied message not found

During handling of the above exception, another exception occurred:

Traceback (most recent call last):
  File "/Users/ahmetcnd/.local/share/virtualenvs/openCryptoBot-D8P4_yx3/lib/python3.7/site-packages/telegram/ext/jobqueue.py", line 245, in tick
    job.run(self.bot)
  File "/Users/ahmetcnd/.local/share/virtualenvs/openCryptoBot-D8P4_yx3/lib/python3.7/site-packages/telegram/ext/jobqueue.py", line 372, in run
    self.callback(bot, self)
  File "/Users/ahmetcnd/Documents/telegrambot/openCryptoBot/opencryptobot/plugins/repeat.py", line 172, in _send_msg
    self.tgb.db.delete_rep(rep)
  File "/Users/ahmetcnd/Documents/telegrambot/openCryptoBot/opencryptobot/database.py", line 194, in delete_rep
    [repeater_id])
sqlite3.InterfaceError: Error binding parameter 0 - probably unsupported type.
2021-05-19 16:12:47,909 - ERROR - root - Replied message not found - {'update_id': 406256828, 'message': {'message_id': 7922, 'date': 1620332306, 'chat': {'id': -1001216334216, 'type': 'supergroup', 'title': 'KRİPTO PUSULA', 'username': 'kriptopusulasi'}, 'text': '/p doge', 'entities': [{'type': 'bot_command', 'offset': 0, 'length': 3}, {'type': 'bot_command', 'offset': 9, 'length': 2}], 'caption_entities': [], 'photo': [], 'new_chat_members': [], 'new_chat_photo': [], 'delete_chat_photo': False, 'group_chat_created': False, 'supergroup_chat_created': False, 'channel_chat_created': False, 'from': {'id': 1087968824, 'first_name': 'Group', 'is_bot': True, 'username': 'GroupAnonymousBot'}}}
2021-05-19 16:12:47,910 - ERROR - JobQueue - An uncaught error was raised while executing job _send_msg
Traceback (most recent call last):
  File "/Users/ahmetcnd/Documents/telegrambot/openCryptoBot/opencryptobot/plugins/repeat.py", line 169, in _send_msg
    plgn.get_action(bot, updt, args=args)
  File "/Users/ahmetcnd/Documents/telegrambot/openCryptoBot/opencryptobot/plugin.py", line 106, in _save_data
    return func(self, bot, update, **kwargs)
  File "/Users/ahmetcnd/Documents/telegrambot/openCryptoBot/opencryptobot/plugin.py", line 73, in _send_typing_action
    return func(self, bot, update, **kwargs)
  File "/Users/ahmetcnd/Documents/telegrambot/openCryptoBot/opencryptobot/plugins/price.py", line 149, in get_action
    self.send_msg(msg, update, keywords)
  File "/Users/ahmetcnd/Documents/telegrambot/openCryptoBot/opencryptobot/plugin.py", line 144, in send_msg
    disable_notification=not notify)
  File "/Users/ahmetcnd/.local/share/virtualenvs/openCryptoBot-D8P4_yx3/lib/python3.7/site-packages/telegram/message.py", line 455, in reply_text
    return self.bot.send_message(self.chat_id, *args, **kwargs)
  File "/Users/ahmetcnd/.local/share/virtualenvs/openCryptoBot-D8P4_yx3/lib/python3.7/site-packages/telegram/bot.py", line 65, in decorator
    result = func(self, *args, **kwargs)
  File "/Users/ahmetcnd/.local/share/virtualenvs/openCryptoBot-D8P4_yx3/lib/python3.7/site-packages/telegram/bot.py", line 90, in decorator
    result = self._request.post(url, data, timeout=kwargs.get('timeout'))
  File "/Users/ahmetcnd/.local/share/virtualenvs/openCryptoBot-D8P4_yx3/lib/python3.7/site-packages/telegram/utils/request.py", line 309, in post
    headers={'Content-Type': 'application/json'})
  File "/Users/ahmetcnd/.local/share/virtualenvs/openCryptoBot-D8P4_yx3/lib/python3.7/site-packages/telegram/utils/request.py", line 223, in _request_wrapper
    raise BadRequest(message)
telegram.error.BadRequest: Replied message not found

During handling of the above exception, another exception occurred:

Traceback (most recent call last):
  File "/Users/ahmetcnd/.local/share/virtualenvs/openCryptoBot-D8P4_yx3/lib/python3.7/site-packages/telegram/ext/jobqueue.py", line 245, in tick
    job.run(self.bot)
  File "/Users/ahmetcnd/.local/share/virtualenvs/openCryptoBot-D8P4_yx3/lib/python3.7/site-packages/telegram/ext/jobqueue.py", line 372, in run
    self.callback(bot, self)
  File "/Users/ahmetcnd/Documents/telegrambot/openCryptoBot/opencryptobot/plugins/repeat.py", line 172, in _send_msg
    self.tgb.db.delete_rep(rep)
  File "/Users/ahmetcnd/Documents/telegrambot/openCryptoBot/opencryptobot/database.py", line 194, in delete_rep
    [repeater_id])
sqlite3.InterfaceError: Error binding parameter 0 - probably unsupported type.
2021-05-19 16:12:55,034 - ERROR - root - HTTPError('502 Server Error: Bad Gateway for url: https://api.coingecko.com/api/v3/simple/price?ids=bitcoin&vs_currencies=ETH,USD,EUR,TRY') - 502 Server Error: Bad Gateway for url: https://api.coingecko.com/api/v3/simple/price?ids=bitcoin&vs_currencies=ETH,USD,EUR,TRY - Class: Price - {'update_id': 406256825, 'message': {'message_id': 7917, 'date': 1620332165, 'chat': {'id': -1001216334216, 'type': 'supergroup', 'title': 'KRİPTO PUSULA', 'username': 'kriptopusulasi'}, 'text': '/p btc', 'entities': [{'type': 'bot_command', 'offset': 0, 'length': 3}, {'type': 'bot_command', 'offset': 9, 'length': 2}], 'caption_entities': [], 'photo': [], 'new_chat_members': [], 'new_chat_photo': [], 'delete_chat_photo': False, 'group_chat_created': False, 'supergroup_chat_created': False, 'channel_chat_created': False, 'from': {'id': 1087968824, 'first_name': 'Group', 'is_bot': True, 'username': 'GroupAnonymousBot'}}}
2021-05-19 16:12:56,994 - ERROR - root - Replied message not found - {'update_id': 406256827, 'message': {'message_id': 7920, 'date': 1620332268, 'chat': {'id': -1001216334216, 'type': 'supergroup', 'title': 'KRİPTO PUSULA', 'username': 'kriptopusulasi'}, 'text': '/p eth', 'entities': [{'type': 'bot_command', 'offset': 0, 'length': 3}, {'type': 'bot_command', 'offset': 9, 'length': 2}], 'caption_entities': [], 'photo': [], 'new_chat_members': [], 'new_chat_photo': [], 'delete_chat_photo': False, 'group_chat_created': False, 'supergroup_chat_created': False, 'channel_chat_created': False, 'from': {'id': 1087968824, 'first_name': 'Group', 'is_bot': True, 'username': 'GroupAnonymousBot'}}}
2021-05-19 16:12:56,996 - ERROR - JobQueue - An uncaught error was raised while executing job _send_msg
Traceback (most recent call last):
  File "/Users/ahmetcnd/Documents/telegrambot/openCryptoBot/opencryptobot/plugins/repeat.py", line 169, in _send_msg
    plgn.get_action(bot, updt, args=args)
  File "/Users/ahmetcnd/Documents/telegrambot/openCryptoBot/opencryptobot/plugin.py", line 106, in _save_data
    return func(self, bot, update, **kwargs)
  File "/Users/ahmetcnd/Documents/telegrambot/openCryptoBot/opencryptobot/plugin.py", line 73, in _send_typing_action
    return func(self, bot, update, **kwargs)
  File "/Users/ahmetcnd/Documents/telegrambot/openCryptoBot/opencryptobot/plugins/price.py", line 62, in get_action
    if RateLimit.limit_reached(update):
  File "/Users/ahmetcnd/Documents/telegrambot/openCryptoBot/opencryptobot/ratelimit.py", line 33, in limit_reached
    update.message.reply_text(msg)
  File "/Users/ahmetcnd/.local/share/virtualenvs/openCryptoBot-D8P4_yx3/lib/python3.7/site-packages/telegram/message.py", line 455, in reply_text
    return self.bot.send_message(self.chat_id, *args, **kwargs)
  File "/Users/ahmetcnd/.local/share/virtualenvs/openCryptoBot-D8P4_yx3/lib/python3.7/site-packages/telegram/bot.py", line 65, in decorator
    result = func(self, *args, **kwargs)
  File "/Users/ahmetcnd/.local/share/virtualenvs/openCryptoBot-D8P4_yx3/lib/python3.7/site-packages/telegram/bot.py", line 90, in decorator
    result = self._request.post(url, data, timeout=kwargs.get('timeout'))
  File "/Users/ahmetcnd/.local/share/virtualenvs/openCryptoBot-D8P4_yx3/lib/python3.7/site-packages/telegram/utils/request.py", line 309, in post
    headers={'Content-Type': 'application/json'})
  File "/Users/ahmetcnd/.local/share/virtualenvs/openCryptoBot-D8P4_yx3/lib/python3.7/site-packages/telegram/utils/request.py", line 223, in _request_wrapper
    raise BadRequest(message)
telegram.error.BadRequest: Replied message not found

During handling of the above exception, another exception occurred:

Traceback (most recent call last):
  File "/Users/ahmetcnd/.local/share/virtualenvs/openCryptoBot-D8P4_yx3/lib/python3.7/site-packages/telegram/ext/jobqueue.py", line 245, in tick
    job.run(self.bot)
  File "/Users/ahmetcnd/.local/share/virtualenvs/openCryptoBot-D8P4_yx3/lib/python3.7/site-packages/telegram/ext/jobqueue.py", line 372, in run
    self.callback(bot, self)
  File "/Users/ahmetcnd/Documents/telegrambot/openCryptoBot/opencryptobot/plugins/repeat.py", line 172, in _send_msg
    self.tgb.db.delete_rep(rep)
  File "/Users/ahmetcnd/Documents/telegrambot/openCryptoBot/opencryptobot/database.py", line 194, in delete_rep
    [repeater_id])
sqlite3.InterfaceError: Error binding parameter 0 - probably unsupported type.
2021-05-19 16:13:00,133 - ERROR - root - Replied message not found - {'update_id': 406256827, 'message': {'message_id': 7920, 'date': 1620332268, 'chat': {'id': -1001216334216, 'type': 'supergroup', 'title': 'KRİPTO PUSULA', 'username': 'kriptopusulasi'}, 'text': '/p eth', 'entities': [{'type': 'bot_command', 'offset': 0, 'length': 3}, {'type': 'bot_command', 'offset': 9, 'length': 2}], 'caption_entities': [], 'photo': [], 'new_chat_members': [], 'new_chat_photo': [], 'delete_chat_photo': False, 'group_chat_created': False, 'supergroup_chat_created': False, 'channel_chat_created': False, 'from': {'id': 1087968824, 'first_name': 'Group', 'is_bot': True, 'username': 'GroupAnonymousBot'}}}
2021-05-19 16:13:00,135 - ERROR - JobQueue - An uncaught error was raised while executing job _send_msg
Traceback (most recent call last):
  File "/Users/ahmetcnd/Documents/telegrambot/openCryptoBot/opencryptobot/plugins/repeat.py", line 169, in _send_msg
    plgn.get_action(bot, updt, args=args)
  File "/Users/ahmetcnd/Documents/telegrambot/openCryptoBot/opencryptobot/plugin.py", line 106, in _save_data
    return func(self, bot, update, **kwargs)
  File "/Users/ahmetcnd/Documents/telegrambot/openCryptoBot/opencryptobot/plugin.py", line 73, in _send_typing_action
    return func(self, bot, update, **kwargs)
  File "/Users/ahmetcnd/Documents/telegrambot/openCryptoBot/opencryptobot/plugins/price.py", line 62, in get_action
    if RateLimit.limit_reached(update):
  File "/Users/ahmetcnd/Documents/telegrambot/openCryptoBot/opencryptobot/ratelimit.py", line 33, in limit_reached
    update.message.reply_text(msg)
  File "/Users/ahmetcnd/.local/share/virtualenvs/openCryptoBot-D8P4_yx3/lib/python3.7/site-packages/telegram/message.py", line 455, in reply_text
    return self.bot.send_message(self.chat_id, *args, **kwargs)
  File "/Users/ahmetcnd/.local/share/virtualenvs/openCryptoBot-D8P4_yx3/lib/python3.7/site-packages/telegram/bot.py", line 65, in decorator
    result = func(self, *args, **kwargs)
  File "/Users/ahmetcnd/.local/share/virtualenvs/openCryptoBot-D8P4_yx3/lib/python3.7/site-packages/telegram/bot.py", line 90, in decorator
    result = self._request.post(url, data, timeout=kwargs.get('timeout'))
  File "/Users/ahmetcnd/.local/share/virtualenvs/openCryptoBot-D8P4_yx3/lib/python3.7/site-packages/telegram/utils/request.py", line 309, in post
    headers={'Content-Type': 'application/json'})
  File "/Users/ahmetcnd/.local/share/virtualenvs/openCryptoBot-D8P4_yx3/lib/python3.7/site-packages/telegram/utils/request.py", line 223, in _request_wrapper
    raise BadRequest(message)
telegram.error.BadRequest: Replied message not found

During handling of the above exception, another exception occurred:

Traceback (most recent call last):
  File "/Users/ahmetcnd/.local/share/virtualenvs/openCryptoBot-D8P4_yx3/lib/python3.7/site-packages/telegram/ext/jobqueue.py", line 245, in tick
    job.run(self.bot)
  File "/Users/ahmetcnd/.local/share/virtualenvs/openCryptoBot-D8P4_yx3/lib/python3.7/site-packages/telegram/ext/jobqueue.py", line 372, in run
    self.callback(bot, self)
  File "/Users/ahmetcnd/Documents/telegrambot/openCryptoBot/opencryptobot/plugins/repeat.py", line 172, in _send_msg
    self.tgb.db.delete_rep(rep)
  File "/Users/ahmetcnd/Documents/telegrambot/openCryptoBot/opencryptobot/database.py", line 194, in delete_rep
    [repeater_id])
sqlite3.InterfaceError: Error binding parameter 0 - probably unsupported type.
2021-05-19 16:13:01,077 - ERROR - root - Replied message not found - {'update_id': 406256828, 'message': {'message_id': 7922, 'date': 1620332306, 'chat': {'id': -1001216334216, 'type': 'supergroup', 'title': 'KRİPTO PUSULA', 'username': 'kriptopusulasi'}, 'text': '/p doge', 'entities': [{'type': 'bot_command', 'offset': 0, 'length': 3}, {'type': 'bot_command', 'offset': 9, 'length': 2}], 'caption_entities': [], 'photo': [], 'new_chat_members': [], 'new_chat_photo': [], 'delete_chat_photo': False, 'group_chat_created': False, 'supergroup_chat_created': False, 'channel_chat_created': False, 'from': {'id': 1087968824, 'first_name': 'Group', 'is_bot': True, 'username': 'GroupAnonymousBot'}}}
2021-05-19 16:13:01,079 - ERROR - JobQueue - An uncaught error was raised while executing job _send_msg
Traceback (most recent call last):
  File "/Users/ahmetcnd/Documents/telegrambot/openCryptoBot/opencryptobot/plugins/repeat.py", line 169, in _send_msg
    plgn.get_action(bot, updt, args=args)
  File "/Users/ahmetcnd/Documents/telegrambot/openCryptoBot/opencryptobot/plugin.py", line 106, in _save_data
    return func(self, bot, update, **kwargs)
  File "/Users/ahmetcnd/Documents/telegrambot/openCryptoBot/opencryptobot/plugin.py", line 73, in _send_typing_action
    return func(self, bot, update, **kwargs)
  File "/Users/ahmetcnd/Documents/telegrambot/openCryptoBot/opencryptobot/plugins/price.py", line 62, in get_action
    if RateLimit.limit_reached(update):
  File "/Users/ahmetcnd/Documents/telegrambot/openCryptoBot/opencryptobot/ratelimit.py", line 33, in limit_reached
    update.message.reply_text(msg)
  File "/Users/ahmetcnd/.local/share/virtualenvs/openCryptoBot-D8P4_yx3/lib/python3.7/site-packages/telegram/message.py", line 455, in reply_text
    return self.bot.send_message(self.chat_id, *args, **kwargs)
  File "/Users/ahmetcnd/.local/share/virtualenvs/openCryptoBot-D8P4_yx3/lib/python3.7/site-packages/telegram/bot.py", line 65, in decorator
    result = func(self, *args, **kwargs)
  File "/Users/ahmetcnd/.local/share/virtualenvs/openCryptoBot-D8P4_yx3/lib/python3.7/site-packages/telegram/bot.py", line 90, in decorator
    result = self._request.post(url, data, timeout=kwargs.get('timeout'))
  File "/Users/ahmetcnd/.local/share/virtualenvs/openCryptoBot-D8P4_yx3/lib/python3.7/site-packages/telegram/utils/request.py", line 309, in post
    headers={'Content-Type': 'application/json'})
  File "/Users/ahmetcnd/.local/share/virtualenvs/openCryptoBot-D8P4_yx3/lib/python3.7/site-packages/telegram/utils/request.py", line 223, in _request_wrapper
    raise BadRequest(message)
telegram.error.BadRequest: Replied message not found

During handling of the above exception, another exception occurred:

Traceback (most recent call last):
  File "/Users/ahmetcnd/.local/share/virtualenvs/openCryptoBot-D8P4_yx3/lib/python3.7/site-packages/telegram/ext/jobqueue.py", line 245, in tick
    job.run(self.bot)
  File "/Users/ahmetcnd/.local/share/virtualenvs/openCryptoBot-D8P4_yx3/lib/python3.7/site-packages/telegram/ext/jobqueue.py", line 372, in run
    self.callback(bot, self)
  File "/Users/ahmetcnd/Documents/telegrambot/openCryptoBot/opencryptobot/plugins/repeat.py", line 172, in _send_msg
    self.tgb.db.delete_rep(rep)
  File "/Users/ahmetcnd/Documents/telegrambot/openCryptoBot/opencryptobot/database.py", line 194, in delete_rep
    [repeater_id])
sqlite3.InterfaceError: Error binding parameter 0 - probably unsupported type.
2021-05-19 16:13:02,172 - ERROR - root - Replied message not found - {'update_id': 406256829, 'message': {'message_id': 7924, 'date': 1620332356, 'chat': {'id': -1001216334216, 'type': 'supergroup', 'title': 'KRİPTO PUSULA', 'username': 'kriptopusulasi'}, 'text': '/p btt', 'entities': [{'type': 'bot_command', 'offset': 0, 'length': 3}, {'type': 'bot_command', 'offset': 9, 'length': 2}], 'caption_entities': [], 'photo': [], 'new_chat_members': [], 'new_chat_photo': [], 'delete_chat_photo': False, 'group_chat_created': False, 'supergroup_chat_created': False, 'channel_chat_created': False, 'from': {'id': 1087968824, 'first_name': 'Group', 'is_bot': True, 'username': 'GroupAnonymousBot'}}}
2021-05-19 16:13:02,174 - ERROR - JobQueue - An uncaught error was raised while executing job _send_msg
Traceback (most recent call last):
  File "/Users/ahmetcnd/Documents/telegrambot/openCryptoBot/opencryptobot/plugins/repeat.py", line 169, in _send_msg
    plgn.get_action(bot, updt, args=args)
  File "/Users/ahmetcnd/Documents/telegrambot/openCryptoBot/opencryptobot/plugin.py", line 106, in _save_data
    return func(self, bot, update, **kwargs)
  File "/Users/ahmetcnd/Documents/telegrambot/openCryptoBot/opencryptobot/plugin.py", line 73, in _send_typing_action
    return func(self, bot, update, **kwargs)
  File "/Users/ahmetcnd/Documents/telegrambot/openCryptoBot/opencryptobot/plugins/price.py", line 62, in get_action
    if RateLimit.limit_reached(update):
  File "/Users/ahmetcnd/Documents/telegrambot/openCryptoBot/opencryptobot/ratelimit.py", line 33, in limit_reached
    update.message.reply_text(msg)
  File "/Users/ahmetcnd/.local/share/virtualenvs/openCryptoBot-D8P4_yx3/lib/python3.7/site-packages/telegram/message.py", line 455, in reply_text
    return self.bot.send_message(self.chat_id, *args, **kwargs)
  File "/Users/ahmetcnd/.local/share/virtualenvs/openCryptoBot-D8P4_yx3/lib/python3.7/site-packages/telegram/bot.py", line 65, in decorator
    result = func(self, *args, **kwargs)
  File "/Users/ahmetcnd/.local/share/virtualenvs/openCryptoBot-D8P4_yx3/lib/python3.7/site-packages/telegram/bot.py", line 90, in decorator
    result = self._request.post(url, data, timeout=kwargs.get('timeout'))
  File "/Users/ahmetcnd/.local/share/virtualenvs/openCryptoBot-D8P4_yx3/lib/python3.7/site-packages/telegram/utils/request.py", line 309, in post
    headers={'Content-Type': 'application/json'})
  File "/Users/ahmetcnd/.local/share/virtualenvs/openCryptoBot-D8P4_yx3/lib/python3.7/site-packages/telegram/utils/request.py", line 223, in _request_wrapper
    raise BadRequest(message)
telegram.error.BadRequest: Replied message not found

During handling of the above exception, another exception occurred:

Traceback (most recent call last):
  File "/Users/ahmetcnd/.local/share/virtualenvs/openCryptoBot-D8P4_yx3/lib/python3.7/site-packages/telegram/ext/jobqueue.py", line 245, in tick
    job.run(self.bot)
  File "/Users/ahmetcnd/.local/share/virtualenvs/openCryptoBot-D8P4_yx3/lib/python3.7/site-packages/telegram/ext/jobqueue.py", line 372, in run
    self.callback(bot, self)
  File "/Users/ahmetcnd/Documents/telegrambot/openCryptoBot/opencryptobot/plugins/repeat.py", line 172, in _send_msg
    self.tgb.db.delete_rep(rep)
  File "/Users/ahmetcnd/Documents/telegrambot/openCryptoBot/opencryptobot/database.py", line 194, in delete_rep
    [repeater_id])
sqlite3.InterfaceError: Error binding parameter 0 - probably unsupported type.
2021-05-19 16:13:02,176 - INFO - root - Starting Caching
2021-05-19 16:13:04,169 - ERROR - telegram.ext.updater - Error while getting Updates: Conflict: terminated by other getUpdates request; make sure that only one bot instance is running (409)
2021-05-19 16:13:04,171 - ERROR - root - Conflict: terminated by other getUpdates request; make sure that only one bot instance is running (409) - Class: TelegramBot - None
2021-05-19 16:13:09,344 - ERROR - telegram.ext.updater - Error while getting Updates: Conflict: terminated by other getUpdates request; make sure that only one bot instance is running (409)
2021-05-19 16:13:09,346 - ERROR - root - Conflict: terminated by other getUpdates request; make sure that only one bot instance is running (409) - Class: TelegramBot - None
2021-05-19 16:13:11,507 - ERROR - JobQueue - An uncaught error was raised while executing job refresh
Traceback (most recent call last):
  File "/Users/ahmetcnd/.local/share/virtualenvs/openCryptoBot-D8P4_yx3/lib/python3.7/site-packages/telegram/ext/jobqueue.py", line 245, in tick
    job.run(self.bot)
  File "/Users/ahmetcnd/.local/share/virtualenvs/openCryptoBot-D8P4_yx3/lib/python3.7/site-packages/telegram/ext/jobqueue.py", line 372, in run
    self.callback(bot, self)
  File "/Users/ahmetcnd/Documents/telegrambot/openCryptoBot/opencryptobot/api/apicache.py", line 23, in refresh
    APICache.refresh_coinmarketcap_coin_list()
  File "/Users/ahmetcnd/Documents/telegrambot/openCryptoBot/opencryptobot/api/apicache.py", line 39, in refresh_coinmarketcap_coin_list
    APICache.cmc_coin_list = Market().listings()["data"]
TypeError: 'JSONDecodeError' object is not subscriptable
2021-05-19 16:13:13,444 - ERROR - root - HTTPError('404 Client Error: Not Found for url: https://api.github.com/repos/None/None/releases/latest')
2021-05-19 16:13:40,026 - ERROR - telegram.ext.updater - Error while getting Updates: Conflict: terminated by other getUpdates request; make sure that only one bot instance is running (409)
2021-05-19 16:13:40,027 - ERROR - root - Conflict: terminated by other getUpdates request; make sure that only one bot instance is running (409) - Class: TelegramBot - None
2021-05-19 16:13:44,156 - ERROR - telegram.ext.updater - Error while getting Updates: Conflict: terminated by other getUpdates request; make sure that only one bot instance is running (409)
2021-05-19 16:13:44,156 - ERROR - root - Conflict: terminated by other getUpdates request; make sure that only one bot instance is running (409) - Class: TelegramBot - None
2021-05-19 16:14:14,920 - ERROR - telegram.ext.updater - Error while getting Updates: Conflict: terminated by other getUpdates request; make sure that only one bot instance is running (409)
2021-05-19 16:14:14,921 - ERROR - root - Conflict: terminated by other getUpdates request; make sure that only one bot instance is running (409) - Class: TelegramBot - None
2021-05-19 16:14:48,715 - ERROR - telegram.ext.updater - Error while getting Updates: Conflict: terminated by other getUpdates request; make sure that only one bot instance is running (409)
2021-05-19 16:14:48,716 - ERROR - root - Conflict: terminated by other getUpdates request; make sure that only one bot instance is running (409) - Class: TelegramBot - None
2021-05-19 16:15:19,333 - ERROR - telegram.ext.updater - Error while getting Updates: Conflict: terminated by other getUpdates request; make sure that only one bot instance is running (409)
2021-05-19 16:15:19,334 - ERROR - root - Conflict: terminated by other getUpdates request; make sure that only one bot instance is running (409) - Class: TelegramBot - None
2021-05-19 16:15:23,501 - ERROR - telegram.ext.updater - Error while getting Updates: Conflict: terminated by other getUpdates request; make sure that only one bot instance is running (409)
2021-05-19 16:15:23,502 - ERROR - root - Conflict: terminated by other getUpdates request; make sure that only one bot instance is running (409) - Class: TelegramBot - None
2021-05-19 16:15:54,210 - ERROR - telegram.ext.updater - Error while getting Updates: Conflict: terminated by other getUpdates request; make sure that only one bot instance is running (409)
2021-05-19 16:15:54,211 - ERROR - root - Conflict: terminated by other getUpdates request; make sure that only one bot instance is running (409) - Class: TelegramBot - None
2021-05-19 16:15:58,336 - ERROR - telegram.ext.updater - Error while getting Updates: Conflict: terminated by other getUpdates request; make sure that only one bot instance is running (409)
2021-05-19 16:15:58,337 - ERROR - root - Conflict: terminated by other getUpdates request; make sure that only one bot instance is running (409) - Class: TelegramBot - None
2021-05-19 16:16:29,108 - ERROR - telegram.ext.updater - Error while getting Updates: Conflict: terminated by other getUpdates request; make sure that only one bot instance is running (409)
2021-05-19 16:16:29,110 - ERROR - root - Conflict: terminated by other getUpdates request; make sure that only one bot instance is running (409) - Class: TelegramBot - None
2021-05-19 16:16:33,245 - ERROR - telegram.ext.updater - Error while getting Updates: Conflict: terminated by other getUpdates request; make sure that only one bot instance is running (409)
2021-05-19 16:16:33,245 - ERROR - root - Conflict: terminated by other getUpdates request; make sure that only one bot instance is running (409) - Class: TelegramBot - None
2021-05-19 16:17:03,837 - ERROR - telegram.ext.updater - Error while getting Updates: Conflict: terminated by other getUpdates request; make sure that only one bot instance is running (409)
2021-05-19 16:17:03,838 - ERROR - root - Conflict: terminated by other getUpdates request; make sure that only one bot instance is running (409) - Class: TelegramBot - None
2021-05-19 16:17:07,947 - ERROR - telegram.ext.updater - Error while getting Updates: Conflict: terminated by other getUpdates request; make sure that only one bot instance is running (409)
2021-05-19 16:17:07,948 - ERROR - root - Conflict: terminated by other getUpdates request; make sure that only one bot instance is running (409) - Class: TelegramBot - None
2021-05-19 16:17:38,689 - ERROR - telegram.ext.updater - Error while getting Updates: Conflict: terminated by other getUpdates request; make sure that only one bot instance is running (409)
2021-05-19 16:17:38,690 - ERROR - root - Conflict: terminated by other getUpdates request; make sure that only one bot instance is running (409) - Class: TelegramBot - None
2021-05-19 16:17:42,854 - ERROR - telegram.ext.updater - Error while getting Updates: Conflict: terminated by other getUpdates request; make sure that only one bot instance is running (409)
2021-05-19 16:17:42,854 - ERROR - root - Conflict: terminated by other getUpdates request; make sure that only one bot instance is running (409) - Class: TelegramBot - None
2021-05-19 16:17:44,749 - ERROR - telegram.ext.updater - Error while getting Updates: Conflict: terminated by other getUpdates request; make sure that only one bot instance is running (409)
2021-05-19 16:17:44,750 - ERROR - root - Conflict: terminated by other getUpdates request; make sure that only one bot instance is running (409) - Class: TelegramBot - None
2021-05-19 16:17:49,925 - ERROR - telegram.ext.updater - Error while getting Updates: Conflict: terminated by other getUpdates request; make sure that only one bot instance is running (409)
2021-05-19 16:17:49,925 - ERROR - root - Conflict: terminated by other getUpdates request; make sure that only one bot instance is running (409) - Class: TelegramBot - None
2021-05-19 16:17:51,963 - ERROR - telegram.ext.updater - Error while getting Updates: Conflict: terminated by other getUpdates request; make sure that only one bot instance is running (409)
2021-05-19 16:17:51,964 - ERROR - root - Conflict: terminated by other getUpdates request; make sure that only one bot instance is running (409) - Class: TelegramBot - None
2021-05-19 16:17:58,029 - ERROR - telegram.ext.updater - Error while getting Updates: Conflict: terminated by other getUpdates request; make sure that only one bot instance is running (409)
2021-05-19 16:17:58,030 - ERROR - root - Conflict: terminated by other getUpdates request; make sure that only one bot instance is running (409) - Class: TelegramBot - None
2021-05-19 16:18:01,100 - ERROR - telegram.ext.updater - Error while getting Updates: Conflict: terminated by other getUpdates request; make sure that only one bot instance is running (409)
2021-05-19 16:18:01,101 - ERROR - root - Conflict: terminated by other getUpdates request; make sure that only one bot instance is running (409) - Class: TelegramBot - None
2021-05-19 16:18:05,228 - ERROR - telegram.ext.updater - Error while getting Updates: Conflict: terminated by other getUpdates request; make sure that only one bot instance is running (409)
2021-05-19 16:18:05,229 - ERROR - root - Conflict: terminated by other getUpdates request; make sure that only one bot instance is running (409) - Class: TelegramBot - None
2021-05-19 16:18:10,315 - ERROR - telegram.ext.updater - Error while getting Updates: Conflict: terminated by other getUpdates request; make sure that only one bot instance is running (409)
2021-05-19 16:18:10,316 - ERROR - root - Conflict: terminated by other getUpdates request; make sure that only one bot instance is running (409) - Class: TelegramBot - None
2021-05-19 16:18:15,453 - ERROR - telegram.ext.updater - Error while getting Updates: Conflict: terminated by other getUpdates request; make sure that only one bot instance is running (409)
2021-05-19 16:18:15,453 - ERROR - root - Conflict: terminated by other getUpdates request; make sure that only one bot instance is running (409) - Class: TelegramBot - None
2021-05-19 16:18:20,613 - ERROR - telegram.ext.updater - Error while getting Updates: Conflict: terminated by other getUpdates request; make sure that only one bot instance is running (409)
2021-05-19 16:18:20,613 - ERROR - root - Conflict: terminated by other getUpdates request; make sure that only one bot instance is running (409) - Class: TelegramBot - None
2021-05-19 16:18:28,745 - ERROR - telegram.ext.updater - Error while getting Updates: Conflict: terminated by other getUpdates request; make sure that only one bot instance is running (409)
2021-05-19 16:18:28,746 - ERROR - root - Conflict: terminated by other getUpdates request; make sure that only one bot instance is running (409) - Class: TelegramBot - None
2021-05-19 16:18:36,949 - ERROR - telegram.ext.updater - Error while getting Updates: Conflict: terminated by other getUpdates request; make sure that only one bot instance is running (409)
2021-05-19 16:18:36,951 - ERROR - root - Conflict: terminated by other getUpdates request; make sure that only one bot instance is running (409) - Class: TelegramBot - None
2021-05-19 16:18:50,353 - ERROR - telegram.ext.updater - Error while getting Updates: Conflict: terminated by other getUpdates request; make sure that only one bot instance is running (409)
2021-05-19 16:18:50,354 - ERROR - root - Conflict: terminated by other getUpdates request; make sure that only one bot instance is running (409) - Class: TelegramBot - None
2021-05-19 16:19:07,786 - ERROR - telegram.ext.updater - Error while getting Updates: Conflict: terminated by other getUpdates request; make sure that only one bot instance is running (409)
2021-05-19 16:19:07,787 - ERROR - root - Conflict: terminated by other getUpdates request; make sure that only one bot instance is running (409) - Class: TelegramBot - None
2021-05-19 16:19:11,862 - ERROR - telegram.ext.updater - Error while getting Updates: Conflict: terminated by other getUpdates request; make sure that only one bot instance is running (409)
2021-05-19 16:19:11,863 - ERROR - root - Conflict: terminated by other getUpdates request; make sure that only one bot instance is running (409) - Class: TelegramBot - None
2021-05-19 16:19:38,461 - ERROR - telegram.ext.updater - Error while getting Updates: Conflict: terminated by other getUpdates request; make sure that only one bot instance is running (409)
2021-05-19 16:19:38,464 - ERROR - root - Conflict: terminated by other getUpdates request; make sure that only one bot instance is running (409) - Class: TelegramBot - None
2021-05-19 16:19:42,554 - ERROR - telegram.ext.updater - Error while getting Updates: Conflict: terminated by other getUpdates request; make sure that only one bot instance is running (409)
2021-05-19 16:19:42,554 - ERROR - root - Conflict: terminated by other getUpdates request; make sure that only one bot instance is running (409) - Class: TelegramBot - None
2021-05-19 16:20:22,531 - ERROR - telegram.ext.updater - Error while getting Updates: Conflict: terminated by other getUpdates request; make sure that only one bot instance is running (409)
2021-05-19 16:20:22,532 - ERROR - root - Conflict: terminated by other getUpdates request; make sure that only one bot instance is running (409) - Class: TelegramBot - None
2021-05-19 16:20:26,603 - ERROR - telegram.ext.updater - Error while getting Updates: Conflict: terminated by other getUpdates request; make sure that only one bot instance is running (409)
2021-05-19 16:20:26,604 - ERROR - root - Conflict: terminated by other getUpdates request; make sure that only one bot instance is running (409) - Class: TelegramBot - None
2021-05-19 16:20:58,302 - ERROR - telegram.ext.updater - Error while getting Updates: Conflict: terminated by other getUpdates request; make sure that only one bot instance is running (409)
2021-05-19 16:20:58,303 - ERROR - root - Conflict: terminated by other getUpdates request; make sure that only one bot instance is running (409) - Class: TelegramBot - None
2021-05-19 16:21:29,054 - ERROR - telegram.ext.updater - Error while getting Updates: Conflict: terminated by other getUpdates request; make sure that only one bot instance is running (409)
2021-05-19 16:21:29,057 - ERROR - root - Conflict: terminated by other getUpdates request; make sure that only one bot instance is running (409) - Class: TelegramBot - None
2021-05-19 16:21:33,146 - ERROR - telegram.ext.updater - Error while getting Updates: Conflict: terminated by other getUpdates request; make sure that only one bot instance is running (409)
2021-05-19 16:21:33,147 - ERROR - root - Conflict: terminated by other getUpdates request; make sure that only one bot instance is running (409) - Class: TelegramBot - None
2021-05-19 16:22:03,868 - ERROR - telegram.ext.updater - Error while getting Updates: Conflict: terminated by other getUpdates request; make sure that only one bot instance is running (409)
2021-05-19 16:22:03,868 - ERROR - root - Conflict: terminated by other getUpdates request; make sure that only one bot instance is running (409) - Class: TelegramBot - None
2021-05-19 16:22:07,960 - ERROR - telegram.ext.updater - Error while getting Updates: Conflict: terminated by other getUpdates request; make sure that only one bot instance is running (409)
2021-05-19 16:22:07,960 - ERROR - root - Conflict: terminated by other getUpdates request; make sure that only one bot instance is running (409) - Class: TelegramBot - None
2021-05-19 16:22:38,791 - ERROR - telegram.ext.updater - Error while getting Updates: Conflict: terminated by other getUpdates request; make sure that only one bot instance is running (409)
2021-05-19 16:22:38,792 - ERROR - root - Conflict: terminated by other getUpdates request; make sure that only one bot instance is running (409) - Class: TelegramBot - None
2021-05-19 16:22:42,911 - ERROR - telegram.ext.updater - Error while getting Updates: Conflict: terminated by other getUpdates request; make sure that only one bot instance is running (409)
2021-05-19 16:22:42,912 - ERROR - root - Conflict: terminated by other getUpdates request; make sure that only one bot instance is running (409) - Class: TelegramBot - None
2021-05-19 16:23:13,505 - ERROR - telegram.ext.updater - Error while getting Updates: Conflict: terminated by other getUpdates request; make sure that only one bot instance is running (409)
2021-05-19 16:23:13,506 - ERROR - root - Conflict: terminated by other getUpdates request; make sure that only one bot instance is running (409) - Class: TelegramBot - None
2021-05-19 16:23:17,656 - ERROR - telegram.ext.updater - Error while getting Updates: Conflict: terminated by other getUpdates request; make sure that only one bot instance is running (409)
2021-05-19 16:23:17,657 - ERROR - root - Conflict: terminated by other getUpdates request; make sure that only one bot instance is running (409) - Class: TelegramBot - None
2021-05-19 16:23:48,316 - ERROR - telegram.ext.updater - Error while getting Updates: Conflict: terminated by other getUpdates request; make sure that only one bot instance is running (409)
2021-05-19 16:23:48,316 - ERROR - root - Conflict: terminated by other getUpdates request; make sure that only one bot instance is running (409) - Class: TelegramBot - None
2021-05-19 16:23:52,419 - ERROR - telegram.ext.updater - Error while getting Updates: Conflict: terminated by other getUpdates request; make sure that only one bot instance is running (409)
2021-05-19 16:23:52,419 - ERROR - root - Conflict: terminated by other getUpdates request; make sure that only one bot instance is running (409) - Class: TelegramBot - None
2021-05-19 16:24:22,524 - ERROR - telegram.ext.updater - Error while getting Updates: Conflict: terminated by other getUpdates request; make sure that only one bot instance is running (409)
2021-05-19 16:24:22,524 - ERROR - root - Conflict: terminated by other getUpdates request; make sure that only one bot instance is running (409) - Class: TelegramBot - None
2021-05-19 16:24:27,260 - ERROR - telegram.ext.updater - Error while getting Updates: Conflict: terminated by other getUpdates request; make sure that only one bot instance is running (409)
2021-05-19 16:24:27,261 - ERROR - root - Conflict: terminated by other getUpdates request; make sure that only one bot instance is running (409) - Class: TelegramBot - None
2021-05-19 16:24:59,124 - ERROR - telegram.ext.updater - Error while getting Updates: Conflict: terminated by other getUpdates request; make sure that only one bot instance is running (409)
2021-05-19 16:24:59,124 - ERROR - root - Conflict: terminated by other getUpdates request; make sure that only one bot instance is running (409) - Class: TelegramBot - None
2021-05-19 16:25:29,661 - ERROR - telegram.ext.updater - Error while getting Updates: Conflict: terminated by other getUpdates request; make sure that only one bot instance is running (409)
2021-05-19 16:25:29,661 - ERROR - root - Conflict: terminated by other getUpdates request; make sure that only one bot instance is running (409) - Class: TelegramBot - None
2021-05-19 16:25:34,810 - ERROR - telegram.ext.updater - Error while getting Updates: Conflict: terminated by other getUpdates request; make sure that only one bot instance is running (409)
2021-05-19 16:25:34,812 - ERROR - root - Conflict: terminated by other getUpdates request; make sure that only one bot instance is running (409) - Class: TelegramBot - None
2021-05-19 16:26:05,534 - ERROR - telegram.ext.updater - Error while getting Updates: Conflict: terminated by other getUpdates request; make sure that only one bot instance is running (409)
2021-05-19 16:26:05,535 - ERROR - root - Conflict: terminated by other getUpdates request; make sure that only one bot instance is running (409) - Class: TelegramBot - None
2021-05-19 16:26:09,621 - ERROR - telegram.ext.updater - Error while getting Updates: Conflict: terminated by other getUpdates request; make sure that only one bot instance is running (409)
2021-05-19 16:26:09,621 - ERROR - root - Conflict: terminated by other getUpdates request; make sure that only one bot instance is running (409) - Class: TelegramBot - None
2021-05-19 16:26:40,371 - ERROR - telegram.ext.updater - Error while getting Updates: Conflict: terminated by other getUpdates request; make sure that only one bot instance is running (409)
2021-05-19 16:26:40,372 - ERROR - root - Conflict: terminated by other getUpdates request; make sure that only one bot instance is running (409) - Class: TelegramBot - None
2021-05-19 16:26:45,479 - ERROR - telegram.ext.updater - Error while getting Updates: Conflict: terminated by other getUpdates request; make sure that only one bot instance is running (409)
2021-05-19 16:26:45,480 - ERROR - root - Conflict: terminated by other getUpdates request; make sure that only one bot instance is running (409) - Class: TelegramBot - None
2021-05-19 16:27:05,733 - WARNING - telegram.vendor.ptb_urllib3.urllib3.connectionpool - Retrying (Retry(total=2, connect=None, read=None, redirect=None)) after connection broken by 'ConnectTimeoutError(<telegram.vendor.ptb_urllib3.urllib3.connectionpool.HTTPSConnectionPool object at 0x107aadd10>, 'Connect timed out. (connect timeout=10)')': /bot1836642794:AAFZGQTSM4Z4zoNUoqf5uYXhofjg0V9i9bI/getUpdates
2021-05-19 16:27:16,249 - ERROR - telegram.ext.updater - Error while getting Updates: Conflict: terminated by other getUpdates request; make sure that only one bot instance is running (409)
2021-05-19 16:27:16,250 - ERROR - root - Conflict: terminated by other getUpdates request; make sure that only one bot instance is running (409) - Class: TelegramBot - None
2021-05-19 16:27:46,936 - ERROR - telegram.ext.updater - Error while getting Updates: Conflict: terminated by other getUpdates request; make sure that only one bot instance is running (409)
2021-05-19 16:27:46,937 - ERROR - root - Conflict: terminated by other getUpdates request; make sure that only one bot instance is running (409) - Class: TelegramBot - None
2021-05-19 16:27:51,081 - ERROR - telegram.ext.updater - Error while getting Updates: Conflict: terminated by other getUpdates request; make sure that only one bot instance is running (409)
2021-05-19 16:27:51,082 - ERROR - root - Conflict: terminated by other getUpdates request; make sure that only one bot instance is running (409) - Class: TelegramBot - None
2021-05-19 16:28:23,724 - ERROR - telegram.ext.updater - Error while getting Updates: Conflict: terminated by other getUpdates request; make sure that only one bot instance is running (409)
2021-05-19 16:28:23,725 - ERROR - root - Conflict: terminated by other getUpdates request; make sure that only one bot instance is running (409) - Class: TelegramBot - None
2021-05-19 16:28:54,489 - ERROR - telegram.ext.updater - Error while getting Updates: Conflict: terminated by other getUpdates request; make sure that only one bot instance is running (409)
2021-05-19 16:28:54,489 - ERROR - root - Conflict: terminated by other getUpdates request; make sure that only one bot instance is running (409) - Class: TelegramBot - None
2021-05-19 16:28:58,583 - ERROR - telegram.ext.updater - Error while getting Updates: Conflict: terminated by other getUpdates request; make sure that only one bot instance is running (409)
2021-05-19 16:28:58,583 - ERROR - root - Conflict: terminated by other getUpdates request; make sure that only one bot instance is running (409) - Class: TelegramBot - None
2021-05-19 16:29:28,671 - ERROR - telegram.ext.updater - Error while getting Updates: Conflict: terminated by other getUpdates request; make sure that only one bot instance is running (409)
2021-05-19 16:29:28,672 - ERROR - root - Conflict: terminated by other getUpdates request; make sure that only one bot instance is running (409) - Class: TelegramBot - None
2021-05-19 16:29:33,326 - ERROR - telegram.ext.updater - Error while getting Updates: Conflict: terminated by other getUpdates request; make sure that only one bot instance is running (409)
2021-05-19 16:29:33,328 - ERROR - root - Conflict: terminated by other getUpdates request; make sure that only one bot instance is running (409) - Class: TelegramBot - None
2021-05-19 16:30:03,401 - ERROR - telegram.ext.updater - Error while getting Updates: Conflict: terminated by other getUpdates request; make sure that only one bot instance is running (409)
2021-05-19 16:30:03,402 - ERROR - root - Conflict: terminated by other getUpdates request; make sure that only one bot instance is running (409) - Class: TelegramBot - None
2021-05-19 16:30:07,572 - ERROR - telegram.ext.updater - Error while getting Updates: Conflict: terminated by other getUpdates request; make sure that only one bot instance is running (409)
2021-05-19 16:30:07,572 - ERROR - root - Conflict: terminated by other getUpdates request; make sure that only one bot instance is running (409) - Class: TelegramBot - None
2021-05-19 16:30:42,069 - ERROR - telegram.ext.updater - Error while getting Updates: Conflict: terminated by other getUpdates request; make sure that only one bot instance is running (409)
2021-05-19 16:30:42,069 - ERROR - root - Conflict: terminated by other getUpdates request; make sure that only one bot instance is running (409) - Class: TelegramBot - None
2021-05-19 16:31:12,167 - ERROR - telegram.ext.updater - Error while getting Updates: Conflict: terminated by other getUpdates request; make sure that only one bot instance is running (409)
2021-05-19 16:31:12,168 - ERROR - root - Conflict: terminated by other getUpdates request; make sure that only one bot instance is running (409) - Class: TelegramBot - None
2021-05-19 16:31:16,292 - ERROR - telegram.ext.updater - Error while getting Updates: Conflict: terminated by other getUpdates request; make sure that only one bot instance is running (409)
2021-05-19 16:31:16,292 - ERROR - root - Conflict: terminated by other getUpdates request; make sure that only one bot instance is running (409) - Class: TelegramBot - None
2021-05-19 16:31:47,544 - ERROR - telegram.ext.updater - Error while getting Updates: Conflict: terminated by other getUpdates request; make sure that only one bot instance is running (409)
2021-05-19 16:31:47,545 - ERROR - root - Conflict: terminated by other getUpdates request; make sure that only one bot instance is running (409) - Class: TelegramBot - None
2021-05-19 16:32:22,299 - ERROR - telegram.ext.updater - Error while getting Updates: Conflict: terminated by other getUpdates request; make sure that only one bot instance is running (409)
2021-05-19 16:32:22,300 - ERROR - root - Conflict: terminated by other getUpdates request; make sure that only one bot instance is running (409) - Class: TelegramBot - None
2021-05-19 16:32:54,146 - ERROR - telegram.ext.updater - Error while getting Updates: Conflict: terminated by other getUpdates request; make sure that only one bot instance is running (409)
2021-05-19 16:32:54,146 - ERROR - root - Conflict: terminated by other getUpdates request; make sure that only one bot instance is running (409) - Class: TelegramBot - None
2021-05-19 16:33:24,822 - ERROR - telegram.ext.updater - Error while getting Updates: Conflict: terminated by other getUpdates request; make sure that only one bot instance is running (409)
2021-05-19 16:33:24,823 - ERROR - root - Conflict: terminated by other getUpdates request; make sure that only one bot instance is running (409) - Class: TelegramBot - None
2021-05-19 16:33:28,892 - ERROR - telegram.ext.updater - Error while getting Updates: Conflict: terminated by other getUpdates request; make sure that only one bot instance is running (409)
2021-05-19 16:33:28,892 - ERROR - root - Conflict: terminated by other getUpdates request; make sure that only one bot instance is running (409) - Class: TelegramBot - None
2021-05-19 16:33:59,067 - ERROR - telegram.ext.updater - Error while getting Updates: Conflict: terminated by other getUpdates request; make sure that only one bot instance is running (409)
2021-05-19 16:33:59,068 - ERROR - root - Conflict: terminated by other getUpdates request; make sure that only one bot instance is running (409) - Class: TelegramBot - None
2021-05-19 16:34:03,187 - ERROR - telegram.ext.updater - Error while getting Updates: Conflict: terminated by other getUpdates request; make sure that only one bot instance is running (409)
2021-05-19 16:34:03,188 - ERROR - root - Conflict: terminated by other getUpdates request; make sure that only one bot instance is running (409) - Class: TelegramBot - None
2021-05-19 16:34:36,593 - ERROR - telegram.ext.updater - Error while getting Updates: Conflict: terminated by other getUpdates request; make sure that only one bot instance is running (409)
2021-05-19 16:34:36,594 - ERROR - root - Conflict: terminated by other getUpdates request; make sure that only one bot instance is running (409) - Class: TelegramBot - None
2021-05-19 16:35:07,263 - ERROR - telegram.ext.updater - Error while getting Updates: Conflict: terminated by other getUpdates request; make sure that only one bot instance is running (409)
2021-05-19 16:35:07,263 - ERROR - root - Conflict: terminated by other getUpdates request; make sure that only one bot instance is running (409) - Class: TelegramBot - None
2021-05-19 16:35:11,370 - ERROR - telegram.ext.updater - Error while getting Updates: Conflict: terminated by other getUpdates request; make sure that only one bot instance is running (409)
2021-05-19 16:35:11,370 - ERROR - root - Conflict: terminated by other getUpdates request; make sure that only one bot instance is running (409) - Class: TelegramBot - None
2021-05-19 16:35:45,192 - ERROR - telegram.ext.updater - Error while getting Updates: Conflict: terminated by other getUpdates request; make sure that only one bot instance is running (409)
2021-05-19 16:35:45,194 - ERROR - root - Conflict: terminated by other getUpdates request; make sure that only one bot instance is running (409) - Class: TelegramBot - None
2021-05-19 16:35:47,097 - ERROR - telegram.ext.updater - Error while getting Updates: Conflict: terminated by other getUpdates request; make sure that only one bot instance is running (409)
2021-05-19 16:35:47,097 - ERROR - root - Conflict: terminated by other getUpdates request; make sure that only one bot instance is running (409) - Class: TelegramBot - None
2021-05-19 16:36:22,066 - ERROR - telegram.ext.updater - Error while getting Updates: Conflict: terminated by other getUpdates request; make sure that only one bot instance is running (409)
2021-05-19 16:36:22,067 - ERROR - root - Conflict: terminated by other getUpdates request; make sure that only one bot instance is running (409) - Class: TelegramBot - None
2021-05-19 16:37:00,989 - ERROR - telegram.ext.updater - Error while getting Updates: Conflict: terminated by other getUpdates request; make sure that only one bot instance is running (409)
2021-05-19 16:37:00,990 - ERROR - root - Conflict: terminated by other getUpdates request; make sure that only one bot instance is running (409) - Class: TelegramBot - None
2021-05-19 16:37:32,575 - ERROR - telegram.ext.updater - Error while getting Updates: Conflict: terminated by other getUpdates request; make sure that only one bot instance is running (409)
2021-05-19 16:37:32,576 - ERROR - root - Conflict: terminated by other getUpdates request; make sure that only one bot instance is running (409) - Class: TelegramBot - None
2021-05-19 16:37:32,981 - ERROR - root - Timed out - {'update_id': 406256825, 'message': {'message_id': 7917, 'date': 1620332165, 'chat': {'id': -1001216334216, 'type': 'supergroup', 'title': 'KRİPTO PUSULA', 'username': 'kriptopusulasi'}, 'text': '/p btc', 'entities': [{'type': 'bot_command', 'offset': 0, 'length': 3}, {'type': 'bot_command', 'offset': 9, 'length': 2}], 'caption_entities': [], 'photo': [], 'new_chat_members': [], 'new_chat_photo': [], 'delete_chat_photo': False, 'group_chat_created': False, 'supergroup_chat_created': False, 'channel_chat_created': False, 'from': {'id': 1087968824, 'first_name': 'Group', 'is_bot': True, 'username': 'GroupAnonymousBot'}}}
2021-05-19 16:37:35,700 - ERROR - telegram.ext.updater - Error while getting Updates: Conflict: terminated by other getUpdates request; make sure that only one bot instance is running (409)
2021-05-19 16:37:35,701 - ERROR - root - Conflict: terminated by other getUpdates request; make sure that only one bot instance is running (409) - Class: TelegramBot - None
2021-05-19 16:37:41,786 - ERROR - root - Timed out - {'update_id': 406256825, 'message': {'message_id': 7917, 'date': 1620332165, 'chat': {'id': -1001216334216, 'type': 'supergroup', 'title': 'KRİPTO PUSULA', 'username': 'kriptopusulasi'}, 'text': '/p btc', 'entities': [{'type': 'bot_command', 'offset': 0, 'length': 3}, {'type': 'bot_command', 'offset': 9, 'length': 2}], 'caption_entities': [], 'photo': [], 'new_chat_members': [], 'new_chat_photo': [], 'delete_chat_photo': False, 'group_chat_created': False, 'supergroup_chat_created': False, 'channel_chat_created': False, 'from': {'id': 1087968824, 'first_name': 'Group', 'is_bot': True, 'username': 'GroupAnonymousBot'}}}
2021-05-19 16:37:41,788 - ERROR - JobQueue - An uncaught error was raised while executing job _send_msg
Traceback (most recent call last):
  File "/Users/ahmetcnd/.local/share/virtualenvs/openCryptoBot-D8P4_yx3/lib/python3.7/site-packages/telegram/vendor/ptb_urllib3/urllib3/connectionpool.py", line 402, in _make_request
    six.raise_from(e, None)
  File "<string>", line 2, in raise_from
  File "/Users/ahmetcnd/.local/share/virtualenvs/openCryptoBot-D8P4_yx3/lib/python3.7/site-packages/telegram/vendor/ptb_urllib3/urllib3/connectionpool.py", line 398, in _make_request
    httplib_response = conn.getresponse()
  File "/Users/ahmetcnd/.pyenv/versions/3.7.10/lib/python3.7/http/client.py", line 1369, in getresponse
    response.begin()
  File "/Users/ahmetcnd/.pyenv/versions/3.7.10/lib/python3.7/http/client.py", line 310, in begin
    version, status, reason = self._read_status()
  File "/Users/ahmetcnd/.pyenv/versions/3.7.10/lib/python3.7/http/client.py", line 271, in _read_status
    line = str(self.fp.readline(_MAXLINE + 1), "iso-8859-1")
  File "/Users/ahmetcnd/.pyenv/versions/3.7.10/lib/python3.7/socket.py", line 589, in readinto
    return self._sock.recv_into(b)
  File "/Users/ahmetcnd/.pyenv/versions/3.7.10/lib/python3.7/ssl.py", line 1071, in recv_into
    return self.read(nbytes, buffer)
  File "/Users/ahmetcnd/.pyenv/versions/3.7.10/lib/python3.7/ssl.py", line 929, in read
    return self._sslobj.read(len, buffer)
socket.timeout: The read operation timed out

During handling of the above exception, another exception occurred:

Traceback (most recent call last):
  File "/Users/ahmetcnd/.local/share/virtualenvs/openCryptoBot-D8P4_yx3/lib/python3.7/site-packages/telegram/utils/request.py", line 203, in _request_wrapper
    resp = self._con_pool.request(*args, **kwargs)
  File "/Users/ahmetcnd/.local/share/virtualenvs/openCryptoBot-D8P4_yx3/lib/python3.7/site-packages/telegram/vendor/ptb_urllib3/urllib3/request.py", line 70, in request
    **urlopen_kw)
  File "/Users/ahmetcnd/.local/share/virtualenvs/openCryptoBot-D8P4_yx3/lib/python3.7/site-packages/telegram/vendor/ptb_urllib3/urllib3/request.py", line 148, in request_encode_body
    return self.urlopen(method, url, **extra_kw)
  File "/Users/ahmetcnd/.local/share/virtualenvs/openCryptoBot-D8P4_yx3/lib/python3.7/site-packages/telegram/vendor/ptb_urllib3/urllib3/poolmanager.py", line 244, in urlopen
    response = conn.urlopen(method, u.request_uri, **kw)
  File "/Users/ahmetcnd/.local/share/virtualenvs/openCryptoBot-D8P4_yx3/lib/python3.7/site-packages/telegram/vendor/ptb_urllib3/urllib3/connectionpool.py", line 666, in urlopen
    _stacktrace=sys.exc_info()[2])
  File "/Users/ahmetcnd/.local/share/virtualenvs/openCryptoBot-D8P4_yx3/lib/python3.7/site-packages/telegram/vendor/ptb_urllib3/urllib3/util/retry.py", line 347, in increment
    raise six.reraise(type(error), error, _stacktrace)
  File "/Users/ahmetcnd/.local/share/virtualenvs/openCryptoBot-D8P4_yx3/lib/python3.7/site-packages/telegram/vendor/ptb_urllib3/urllib3/packages/six.py", line 686, in reraise
    raise value
  File "/Users/ahmetcnd/.local/share/virtualenvs/openCryptoBot-D8P4_yx3/lib/python3.7/site-packages/telegram/vendor/ptb_urllib3/urllib3/connectionpool.py", line 617, in urlopen
    chunked=chunked)
  File "/Users/ahmetcnd/.local/share/virtualenvs/openCryptoBot-D8P4_yx3/lib/python3.7/site-packages/telegram/vendor/ptb_urllib3/urllib3/connectionpool.py", line 405, in _make_request
    exc_cls=ReadTimeoutError)
  File "/Users/ahmetcnd/.local/share/virtualenvs/openCryptoBot-D8P4_yx3/lib/python3.7/site-packages/telegram/vendor/ptb_urllib3/urllib3/connectionpool.py", line 321, in _raise_timeout
    raise exc_cls(*args)
telegram.vendor.ptb_urllib3.urllib3.exceptions.ReadTimeoutError: HTTPSConnectionPool(host='api.telegram.org', port=443): Read timed out. (read timeout=5.0)

During handling of the above exception, another exception occurred:

Traceback (most recent call last):
  File "/Users/ahmetcnd/Documents/telegrambot/openCryptoBot/opencryptobot/plugins/repeat.py", line 169, in _send_msg
    plgn.get_action(bot, updt, args=args)
  File "/Users/ahmetcnd/Documents/telegrambot/openCryptoBot/opencryptobot/plugin.py", line 106, in _save_data
    return func(self, bot, update, **kwargs)
  File "/Users/ahmetcnd/Documents/telegrambot/openCryptoBot/opencryptobot/plugin.py", line 73, in _send_typing_action
    return func(self, bot, update, **kwargs)
  File "/Users/ahmetcnd/Documents/telegrambot/openCryptoBot/opencryptobot/plugins/price.py", line 149, in get_action
    self.send_msg(msg, update, keywords)
  File "/Users/ahmetcnd/Documents/telegrambot/openCryptoBot/opencryptobot/plugin.py", line 144, in send_msg
    disable_notification=not notify)
  File "/Users/ahmetcnd/.local/share/virtualenvs/openCryptoBot-D8P4_yx3/lib/python3.7/site-packages/telegram/message.py", line 455, in reply_text
    return self.bot.send_message(self.chat_id, *args, **kwargs)
  File "/Users/ahmetcnd/.local/share/virtualenvs/openCryptoBot-D8P4_yx3/lib/python3.7/site-packages/telegram/bot.py", line 65, in decorator
    result = func(self, *args, **kwargs)
  File "/Users/ahmetcnd/.local/share/virtualenvs/openCryptoBot-D8P4_yx3/lib/python3.7/site-packages/telegram/bot.py", line 90, in decorator
    result = self._request.post(url, data, timeout=kwargs.get('timeout'))
  File "/Users/ahmetcnd/.local/share/virtualenvs/openCryptoBot-D8P4_yx3/lib/python3.7/site-packages/telegram/utils/request.py", line 309, in post
    headers={'Content-Type': 'application/json'})
  File "/Users/ahmetcnd/.local/share/virtualenvs/openCryptoBot-D8P4_yx3/lib/python3.7/site-packages/telegram/utils/request.py", line 205, in _request_wrapper
    raise TimedOut()
telegram.error.TimedOut: Timed out

During handling of the above exception, another exception occurred:

Traceback (most recent call last):
  File "/Users/ahmetcnd/.local/share/virtualenvs/openCryptoBot-D8P4_yx3/lib/python3.7/site-packages/telegram/ext/jobqueue.py", line 245, in tick
    job.run(self.bot)
  File "/Users/ahmetcnd/.local/share/virtualenvs/openCryptoBot-D8P4_yx3/lib/python3.7/site-packages/telegram/ext/jobqueue.py", line 372, in run
    self.callback(bot, self)
  File "/Users/ahmetcnd/Documents/telegrambot/openCryptoBot/opencryptobot/plugins/repeat.py", line 172, in _send_msg
    self.tgb.db.delete_rep(rep)
  File "/Users/ahmetcnd/Documents/telegrambot/openCryptoBot/opencryptobot/database.py", line 194, in delete_rep
    [repeater_id])
sqlite3.InterfaceError: Error binding parameter 0 - probably unsupported type.
2021-05-19 16:38:06,437 - ERROR - telegram.ext.updater - Error while getting Updates: Conflict: terminated by other getUpdates request; make sure that only one bot instance is running (409)
2021-05-19 16:38:06,437 - ERROR - root - Conflict: terminated by other getUpdates request; make sure that only one bot instance is running (409) - Class: TelegramBot - None
2021-05-19 16:38:10,575 - ERROR - telegram.ext.updater - Error while getting Updates: Conflict: terminated by other getUpdates request; make sure that only one bot instance is running (409)
2021-05-19 16:38:10,576 - ERROR - root - Conflict: terminated by other getUpdates request; make sure that only one bot instance is running (409) - Class: TelegramBot - None
2021-05-19 16:38:41,212 - ERROR - telegram.ext.updater - Error while getting Updates: Conflict: terminated by other getUpdates request; make sure that only one bot instance is running (409)
2021-05-19 16:38:41,212 - ERROR - root - Conflict: terminated by other getUpdates request; make sure that only one bot instance is running (409) - Class: TelegramBot - None
2021-05-19 16:38:45,334 - ERROR - telegram.ext.updater - Error while getting Updates: Conflict: terminated by other getUpdates request; make sure that only one bot instance is running (409)
2021-05-19 16:38:45,335 - ERROR - root - Conflict: terminated by other getUpdates request; make sure that only one bot instance is running (409) - Class: TelegramBot - None
2021-05-19 16:39:17,170 - ERROR - telegram.ext.updater - Error while getting Updates: Conflict: terminated by other getUpdates request; make sure that only one bot instance is running (409)
2021-05-19 16:39:17,170 - ERROR - root - Conflict: terminated by other getUpdates request; make sure that only one bot instance is running (409) - Class: TelegramBot - None
2021-05-19 16:39:22,203 - ERROR - telegram.ext.updater - Error while getting Updates: Conflict: terminated by other getUpdates request; make sure that only one bot instance is running (409)
2021-05-19 16:39:22,204 - ERROR - root - Conflict: terminated by other getUpdates request; make sure that only one bot instance is running (409) - Class: TelegramBot - None
2021-05-19 16:39:52,919 - ERROR - telegram.ext.updater - Error while getting Updates: Conflict: terminated by other getUpdates request; make sure that only one bot instance is running (409)
2021-05-19 16:39:52,919 - ERROR - root - Conflict: terminated by other getUpdates request; make sure that only one bot instance is running (409) - Class: TelegramBot - None
2021-05-19 16:39:57,014 - ERROR - telegram.ext.updater - Error while getting Updates: Conflict: terminated by other getUpdates request; make sure that only one bot instance is running (409)
2021-05-19 16:39:57,014 - ERROR - root - Conflict: terminated by other getUpdates request; make sure that only one bot instance is running (409) - Class: TelegramBot - None
2021-05-19 16:40:32,735 - WARNING - telegram.vendor.ptb_urllib3.urllib3.connectionpool - Retrying (Retry(total=2, connect=None, read=None, redirect=None)) after connection broken by 'ConnectTimeoutError(<telegram.vendor.ptb_urllib3.urllib3.connectionpool.HTTPSConnectionPool object at 0x107aadd10>, 'Connect timed out. (connect timeout=10)')': /bot1836642794:AAFZGQTSM4Z4zoNUoqf5uYXhofjg0V9i9bI/getUpdates
2021-05-19 16:40:38,104 - ERROR - telegram.ext.updater - Error while getting Updates: Conflict: terminated by other getUpdates request; make sure that only one bot instance is running (409)
2021-05-19 16:40:38,105 - ERROR - root - Conflict: terminated by other getUpdates request; make sure that only one bot instance is running (409) - Class: TelegramBot - None
2021-05-19 16:40:44,041 - ERROR - telegram.ext.updater - Error while getting Updates: Conflict: terminated by other getUpdates request; make sure that only one bot instance is running (409)
2021-05-19 16:40:44,042 - ERROR - root - Conflict: terminated by other getUpdates request; make sure that only one bot instance is running (409) - Class: TelegramBot - None
2021-05-19 16:40:45,113 - ERROR - telegram.ext.updater - Error while getting Updates: Conflict: terminated by other getUpdates request; make sure that only one bot instance is running (409)
2021-05-19 16:40:45,113 - ERROR - root - Conflict: terminated by other getUpdates request; make sure that only one bot instance is running (409) - Class: TelegramBot - None
2021-05-19 16:40:50,301 - ERROR - telegram.ext.updater - Error while getting Updates: Conflict: terminated by other getUpdates request; make sure that only one bot instance is running (409)
2021-05-19 16:40:50,302 - ERROR - root - Conflict: terminated by other getUpdates request; make sure that only one bot instance is running (409) - Class: TelegramBot - None
2021-05-19 16:40:52,326 - ERROR - telegram.ext.updater - Error while getting Updates: Conflict: terminated by other getUpdates request; make sure that only one bot instance is running (409)
2021-05-19 16:40:52,327 - ERROR - root - Conflict: terminated by other getUpdates request; make sure that only one bot instance is running (409) - Class: TelegramBot - None
2021-05-19 16:41:01,530 - ERROR - telegram.ext.updater - Error while getting Updates: Conflict: terminated by other getUpdates request; make sure that only one bot instance is running (409)
2021-05-19 16:41:01,531 - ERROR - root - Conflict: terminated by other getUpdates request; make sure that only one bot instance is running (409) - Class: TelegramBot - None
2021-05-19 16:41:08,803 - ERROR - telegram.ext.updater - Error while getting Updates: Conflict: terminated by other getUpdates request; make sure that only one bot instance is running (409)
2021-05-19 16:41:08,804 - ERROR - root - Conflict: terminated by other getUpdates request; make sure that only one bot instance is running (409) - Class: TelegramBot - None
2021-05-19 16:41:12,861 - ERROR - telegram.ext.updater - Error while getting Updates: Conflict: terminated by other getUpdates request; make sure that only one bot instance is running (409)
2021-05-19 16:41:12,862 - ERROR - root - Conflict: terminated by other getUpdates request; make sure that only one bot instance is running (409) - Class: TelegramBot - None
2021-05-19 16:41:17,497 - ERROR - telegram.ext.updater - Error while getting Updates: Conflict: terminated by other getUpdates request; make sure that only one bot instance is running (409)
2021-05-19 16:41:17,497 - ERROR - root - Conflict: terminated by other getUpdates request; make sure that only one bot instance is running (409) - Class: TelegramBot - None
2021-05-19 16:41:23,050 - ERROR - telegram.ext.updater - Error while getting Updates: Conflict: terminated by other getUpdates request; make sure that only one bot instance is running (409)
2021-05-19 16:41:23,051 - ERROR - root - Conflict: terminated by other getUpdates request; make sure that only one bot instance is running (409) - Class: TelegramBot - None
2021-05-19 16:41:28,198 - ERROR - telegram.ext.updater - Error while getting Updates: Conflict: terminated by other getUpdates request; make sure that only one bot instance is running (409)
2021-05-19 16:41:28,199 - ERROR - root - Conflict: terminated by other getUpdates request; make sure that only one bot instance is running (409) - Class: TelegramBot - None
2021-05-19 16:41:38,452 - ERROR - telegram.ext.updater - Error while getting Updates: Conflict: terminated by other getUpdates request; make sure that only one bot instance is running (409)
2021-05-19 16:41:38,452 - ERROR - root - Conflict: terminated by other getUpdates request; make sure that only one bot instance is running (409) - Class: TelegramBot - None
2021-05-19 16:41:51,755 - ERROR - telegram.ext.updater - Error while getting Updates: Conflict: terminated by other getUpdates request; make sure that only one bot instance is running (409)
2021-05-19 16:41:51,756 - ERROR - root - Conflict: terminated by other getUpdates request; make sure that only one bot instance is running (409) - Class: TelegramBot - None
2021-05-19 16:42:23,462 - ERROR - telegram.ext.updater - Error while getting Updates: Conflict: terminated by other getUpdates request; make sure that only one bot instance is running (409)
2021-05-19 16:42:23,462 - ERROR - root - Conflict: terminated by other getUpdates request; make sure that only one bot instance is running (409) - Class: TelegramBot - None
2021-05-19 16:42:28,659 - ERROR - telegram.ext.updater - Error while getting Updates: Conflict: terminated by other getUpdates request; make sure that only one bot instance is running (409)
2021-05-19 16:42:28,660 - ERROR - root - Conflict: terminated by other getUpdates request; make sure that only one bot instance is running (409) - Class: TelegramBot - None
2021-05-19 16:42:31,717 - ERROR - telegram.ext.updater - Error while getting Updates: Conflict: terminated by other getUpdates request; make sure that only one bot instance is running (409)
2021-05-19 16:42:31,718 - ERROR - root - Conflict: terminated by other getUpdates request; make sure that only one bot instance is running (409) - Class: TelegramBot - None
2021-05-19 16:42:35,770 - ERROR - telegram.ext.updater - Error while getting Updates: Conflict: terminated by other getUpdates request; make sure that only one bot instance is running (409)
2021-05-19 16:42:35,771 - ERROR - root - Conflict: terminated by other getUpdates request; make sure that only one bot instance is running (409) - Class: TelegramBot - None
2021-05-19 16:42:37,779 - ERROR - telegram.ext.updater - Error while getting Updates: Conflict: terminated by other getUpdates request; make sure that only one bot instance is running (409)
2021-05-19 16:42:37,780 - ERROR - root - Conflict: terminated by other getUpdates request; make sure that only one bot instance is running (409) - Class: TelegramBot - None
2021-05-19 16:42:43,925 - ERROR - telegram.ext.updater - Error while getting Updates: Conflict: terminated by other getUpdates request; make sure that only one bot instance is running (409)
2021-05-19 16:42:43,925 - ERROR - root - Conflict: terminated by other getUpdates request; make sure that only one bot instance is running (409) - Class: TelegramBot - None
2021-05-19 16:42:48,022 - ERROR - telegram.ext.updater - Error while getting Updates: Conflict: terminated by other getUpdates request; make sure that only one bot instance is running (409)
2021-05-19 16:42:48,023 - ERROR - root - Conflict: terminated by other getUpdates request; make sure that only one bot instance is running (409) - Class: TelegramBot - None
2021-05-19 16:42:52,230 - ERROR - telegram.ext.updater - Error while getting Updates: Conflict: terminated by other getUpdates request; make sure that only one bot instance is running (409)
2021-05-19 16:42:52,230 - ERROR - root - Conflict: terminated by other getUpdates request; make sure that only one bot instance is running (409) - Class: TelegramBot - None
2021-05-19 16:42:56,313 - ERROR - telegram.ext.updater - Error while getting Updates: Conflict: terminated by other getUpdates request; make sure that only one bot instance is running (409)
2021-05-19 16:42:56,314 - ERROR - root - Conflict: terminated by other getUpdates request; make sure that only one bot instance is running (409) - Class: TelegramBot - None
2021-05-19 16:43:02,355 - ERROR - telegram.ext.updater - Error while getting Updates: Conflict: terminated by other getUpdates request; make sure that only one bot instance is running (409)
2021-05-19 16:43:02,355 - ERROR - root - Conflict: terminated by other getUpdates request; make sure that only one bot instance is running (409) - Class: TelegramBot - None
2021-05-19 16:43:07,590 - ERROR - telegram.ext.updater - Error while getting Updates: Conflict: terminated by other getUpdates request; make sure that only one bot instance is running (409)
2021-05-19 16:43:07,590 - ERROR - root - Conflict: terminated by other getUpdates request; make sure that only one bot instance is running (409) - Class: TelegramBot - None
2021-05-19 16:43:16,779 - ERROR - telegram.ext.updater - Error while getting Updates: Conflict: terminated by other getUpdates request; make sure that only one bot instance is running (409)
2021-05-19 16:43:16,780 - ERROR - root - Conflict: terminated by other getUpdates request; make sure that only one bot instance is running (409) - Class: TelegramBot - None
2021-05-19 16:43:29,081 - ERROR - telegram.ext.updater - Error while getting Updates: Conflict: terminated by other getUpdates request; make sure that only one bot instance is running (409)
2021-05-19 16:43:29,081 - ERROR - root - Conflict: terminated by other getUpdates request; make sure that only one bot instance is running (409) - Class: TelegramBot - None
2021-05-19 16:43:41,356 - ERROR - telegram.ext.updater - Error while getting Updates: Conflict: terminated by other getUpdates request; make sure that only one bot instance is running (409)
2021-05-19 16:43:41,356 - ERROR - root - Conflict: terminated by other getUpdates request; make sure that only one bot instance is running (409) - Class: TelegramBot - None
2021-05-19 16:43:45,465 - ERROR - telegram.ext.updater - Error while getting Updates: Conflict: terminated by other getUpdates request; make sure that only one bot instance is running (409)
2021-05-19 16:43:45,465 - ERROR - root - Conflict: terminated by other getUpdates request; make sure that only one bot instance is running (409) - Class: TelegramBot - None
2021-05-19 16:44:02,759 - ERROR - telegram.ext.updater - Error while getting Updates: Conflict: terminated by other getUpdates request; make sure that only one bot instance is running (409)
2021-05-19 16:44:02,760 - ERROR - root - Conflict: terminated by other getUpdates request; make sure that only one bot instance is running (409) - Class: TelegramBot - None
2021-05-19 16:44:28,462 - ERROR - telegram.ext.updater - Error while getting Updates: Conflict: terminated by other getUpdates request; make sure that only one bot instance is running (409)
2021-05-19 16:44:28,462 - ERROR - root - Conflict: terminated by other getUpdates request; make sure that only one bot instance is running (409) - Class: TelegramBot - None
2021-05-19 16:44:32,573 - ERROR - telegram.ext.updater - Error while getting Updates: Conflict: terminated by other getUpdates request; make sure that only one bot instance is running (409)
2021-05-19 16:44:32,573 - ERROR - root - Conflict: terminated by other getUpdates request; make sure that only one bot instance is running (409) - Class: TelegramBot - None
2021-05-19 16:45:11,386 - ERROR - telegram.ext.updater - Error while getting Updates: Conflict: terminated by other getUpdates request; make sure that only one bot instance is running (409)
2021-05-19 16:45:11,386 - ERROR - root - Conflict: terminated by other getUpdates request; make sure that only one bot instance is running (409) - Class: TelegramBot - None
2021-05-19 16:45:15,489 - ERROR - telegram.ext.updater - Error while getting Updates: Conflict: terminated by other getUpdates request; make sure that only one bot instance is running (409)
2021-05-19 16:45:15,489 - ERROR - root - Conflict: terminated by other getUpdates request; make sure that only one bot instance is running (409) - Class: TelegramBot - None
2021-05-19 16:45:46,173 - ERROR - telegram.ext.updater - Error while getting Updates: Conflict: terminated by other getUpdates request; make sure that only one bot instance is running (409)
2021-05-19 16:45:46,174 - ERROR - root - Conflict: terminated by other getUpdates request; make sure that only one bot instance is running (409) - Class: TelegramBot - None
2021-05-19 16:45:50,322 - ERROR - telegram.ext.updater - Error while getting Updates: Conflict: terminated by other getUpdates request; make sure that only one bot instance is running (409)
2021-05-19 16:45:50,323 - ERROR - root - Conflict: terminated by other getUpdates request; make sure that only one bot instance is running (409) - Class: TelegramBot - None
2021-05-19 16:46:21,019 - ERROR - telegram.ext.updater - Error while getting Updates: Conflict: terminated by other getUpdates request; make sure that only one bot instance is running (409)
2021-05-19 16:46:21,020 - ERROR - root - Conflict: terminated by other getUpdates request; make sure that only one bot instance is running (409) - Class: TelegramBot - None
2021-05-19 16:46:25,099 - ERROR - telegram.ext.updater - Error while getting Updates: Conflict: terminated by other getUpdates request; make sure that only one bot instance is running (409)
2021-05-19 16:46:25,099 - ERROR - root - Conflict: terminated by other getUpdates request; make sure that only one bot instance is running (409) - Class: TelegramBot - None
2021-05-19 16:46:55,286 - ERROR - telegram.ext.updater - Error while getting Updates: Conflict: terminated by other getUpdates request; make sure that only one bot instance is running (409)
2021-05-19 16:46:55,287 - ERROR - root - Conflict: terminated by other getUpdates request; make sure that only one bot instance is running (409) - Class: TelegramBot - None
2021-05-19 16:46:59,929 - ERROR - telegram.ext.updater - Error while getting Updates: Conflict: terminated by other getUpdates request; make sure that only one bot instance is running (409)
2021-05-19 16:46:59,929 - ERROR - root - Conflict: terminated by other getUpdates request; make sure that only one bot instance is running (409) - Class: TelegramBot - None
2021-05-19 16:47:30,713 - ERROR - telegram.ext.updater - Error while getting Updates: Conflict: terminated by other getUpdates request; make sure that only one bot instance is running (409)
2021-05-19 16:47:30,714 - ERROR - root - Conflict: terminated by other getUpdates request; make sure that only one bot instance is running (409) - Class: TelegramBot - None
2021-05-19 16:47:34,865 - ERROR - telegram.ext.updater - Error while getting Updates: Conflict: terminated by other getUpdates request; make sure that only one bot instance is running (409)
2021-05-19 16:47:34,866 - ERROR - root - Conflict: terminated by other getUpdates request; make sure that only one bot instance is running (409) - Class: TelegramBot - None
2021-05-19 16:48:10,526 - ERROR - telegram.ext.updater - Error while getting Updates: Conflict: terminated by other getUpdates request; make sure that only one bot instance is running (409)
2021-05-19 16:48:10,526 - ERROR - root - Conflict: terminated by other getUpdates request; make sure that only one bot instance is running (409) - Class: TelegramBot - None
2021-05-19 16:48:43,245 - ERROR - telegram.ext.updater - Error while getting Updates: Conflict: terminated by other getUpdates request; make sure that only one bot instance is running (409)
2021-05-19 16:48:43,246 - ERROR - root - Conflict: terminated by other getUpdates request; make sure that only one bot instance is running (409) - Class: TelegramBot - None
2021-05-19 16:49:20,086 - ERROR - telegram.ext.updater - Error while getting Updates: Conflict: terminated by other getUpdates request; make sure that only one bot instance is running (409)
2021-05-19 16:49:20,087 - ERROR - root - Conflict: terminated by other getUpdates request; make sure that only one bot instance is running (409) - Class: TelegramBot - None
2021-05-19 16:49:50,864 - ERROR - telegram.ext.updater - Error while getting Updates: Conflict: terminated by other getUpdates request; make sure that only one bot instance is running (409)
2021-05-19 16:49:50,865 - ERROR - root - Conflict: terminated by other getUpdates request; make sure that only one bot instance is running (409) - Class: TelegramBot - None
2021-05-19 16:50:27,650 - ERROR - telegram.ext.updater - Error while getting Updates: Conflict: terminated by other getUpdates request; make sure that only one bot instance is running (409)
2021-05-19 16:50:27,651 - ERROR - root - Conflict: terminated by other getUpdates request; make sure that only one bot instance is running (409) - Class: TelegramBot - None
2021-05-19 16:51:02,181 - ERROR - telegram.ext.updater - Error while getting Updates: Conflict: terminated by other getUpdates request; make sure that only one bot instance is running (409)
2021-05-19 16:51:02,182 - ERROR - root - Conflict: terminated by other getUpdates request; make sure that only one bot instance is running (409) - Class: TelegramBot - None
2021-05-19 16:51:36,342 - ERROR - telegram.ext.updater - Error while getting Updates: Conflict: terminated by other getUpdates request; make sure that only one bot instance is running (409)
2021-05-19 16:51:36,343 - ERROR - root - Conflict: terminated by other getUpdates request; make sure that only one bot instance is running (409) - Class: TelegramBot - None
2021-05-19 16:52:11,053 - ERROR - telegram.ext.updater - Error while getting Updates: Conflict: terminated by other getUpdates request; make sure that only one bot instance is running (409)
2021-05-19 16:52:11,053 - ERROR - root - Conflict: terminated by other getUpdates request; make sure that only one bot instance is running (409) - Class: TelegramBot - None
2021-05-19 16:52:45,889 - ERROR - telegram.ext.updater - Error while getting Updates: Conflict: terminated by other getUpdates request; make sure that only one bot instance is running (409)
2021-05-19 16:52:45,890 - ERROR - root - Conflict: terminated by other getUpdates request; make sure that only one bot instance is running (409) - Class: TelegramBot - None
2021-05-19 16:53:20,699 - ERROR - telegram.ext.updater - Error while getting Updates: Conflict: terminated by other getUpdates request; make sure that only one bot instance is running (409)
2021-05-19 16:53:20,700 - ERROR - root - Conflict: terminated by other getUpdates request; make sure that only one bot instance is running (409) - Class: TelegramBot - None
2021-05-19 16:53:55,560 - ERROR - telegram.ext.updater - Error while getting Updates: Conflict: terminated by other getUpdates request; make sure that only one bot instance is running (409)
2021-05-19 16:53:55,560 - ERROR - root - Conflict: terminated by other getUpdates request; make sure that only one bot instance is running (409) - Class: TelegramBot - None
2021-05-19 16:54:30,315 - ERROR - telegram.ext.updater - Error while getting Updates: Conflict: terminated by other getUpdates request; make sure that only one bot instance is running (409)
2021-05-19 16:54:30,316 - ERROR - root - Conflict: terminated by other getUpdates request; make sure that only one bot instance is running (409) - Class: TelegramBot - None
2021-05-19 16:55:04,036 - ERROR - telegram.ext.updater - Error while getting Updates: Conflict: terminated by other getUpdates request; make sure that only one bot instance is running (409)
2021-05-19 16:55:04,038 - ERROR - root - Conflict: terminated by other getUpdates request; make sure that only one bot instance is running (409) - Class: TelegramBot - None
2021-05-19 16:55:38,917 - ERROR - telegram.ext.updater - Error while getting Updates: Conflict: terminated by other getUpdates request; make sure that only one bot instance is running (409)
2021-05-19 16:55:38,918 - ERROR - root - Conflict: terminated by other getUpdates request; make sure that only one bot instance is running (409) - Class: TelegramBot - None
2021-05-19 16:56:13,757 - ERROR - telegram.ext.updater - Error while getting Updates: Conflict: terminated by other getUpdates request; make sure that only one bot instance is running (409)
2021-05-19 16:56:13,757 - ERROR - root - Conflict: terminated by other getUpdates request; make sure that only one bot instance is running (409) - Class: TelegramBot - None
2021-05-19 16:56:48,556 - ERROR - telegram.ext.updater - Error while getting Updates: Conflict: terminated by other getUpdates request; make sure that only one bot instance is running (409)
2021-05-19 16:56:48,557 - ERROR - root - Conflict: terminated by other getUpdates request; make sure that only one bot instance is running (409) - Class: TelegramBot - None
2021-05-19 16:57:23,379 - ERROR - telegram.ext.updater - Error while getting Updates: Conflict: terminated by other getUpdates request; make sure that only one bot instance is running (409)
2021-05-19 16:57:23,381 - ERROR - root - Conflict: terminated by other getUpdates request; make sure that only one bot instance is running (409) - Class: TelegramBot - None
2021-05-19 16:57:57,672 - ERROR - telegram.ext.updater - Error while getting Updates: Conflict: terminated by other getUpdates request; make sure that only one bot instance is running (409)
2021-05-19 16:57:57,676 - ERROR - root - Conflict: terminated by other getUpdates request; make sure that only one bot instance is running (409) - Class: TelegramBot - None
2021-05-19 16:58:31,947 - ERROR - telegram.ext.updater - Error while getting Updates: Conflict: terminated by other getUpdates request; make sure that only one bot instance is running (409)
2021-05-19 16:58:31,950 - ERROR - root - Conflict: terminated by other getUpdates request; make sure that only one bot instance is running (409) - Class: TelegramBot - None
2021-05-19 16:59:06,813 - ERROR - telegram.ext.updater - Error while getting Updates: Conflict: terminated by other getUpdates request; make sure that only one bot instance is running (409)
2021-05-19 16:59:06,815 - ERROR - root - Conflict: terminated by other getUpdates request; make sure that only one bot instance is running (409) - Class: TelegramBot - None
2021-05-19 16:59:41,695 - ERROR - telegram.ext.updater - Error while getting Updates: Conflict: terminated by other getUpdates request; make sure that only one bot instance is running (409)
2021-05-19 16:59:41,695 - ERROR - root - Conflict: terminated by other getUpdates request; make sure that only one bot instance is running (409) - Class: TelegramBot - None
2021-05-19 17:00:17,321 - ERROR - telegram.ext.updater - Error while getting Updates: Conflict: terminated by other getUpdates request; make sure that only one bot instance is running (409)
2021-05-19 17:00:17,322 - ERROR - root - Conflict: terminated by other getUpdates request; make sure that only one bot instance is running (409) - Class: TelegramBot - None
2021-05-19 17:00:52,208 - ERROR - telegram.ext.updater - Error while getting Updates: Conflict: terminated by other getUpdates request; make sure that only one bot instance is running (409)
2021-05-19 17:00:52,209 - ERROR - root - Conflict: terminated by other getUpdates request; make sure that only one bot instance is running (409) - Class: TelegramBot - None
2021-05-19 17:01:27,074 - ERROR - telegram.ext.updater - Error while getting Updates: Conflict: terminated by other getUpdates request; make sure that only one bot instance is running (409)
2021-05-19 17:01:27,075 - ERROR - root - Conflict: terminated by other getUpdates request; make sure that only one bot instance is running (409) - Class: TelegramBot - None
2021-05-19 17:02:05,041 - ERROR - telegram.ext.updater - Error while getting Updates: Conflict: terminated by other getUpdates request; make sure that only one bot instance is running (409)
2021-05-19 17:02:05,049 - ERROR - root - Conflict: terminated by other getUpdates request; make sure that only one bot instance is running (409) - Class: TelegramBot - None
2021-05-19 17:02:39,768 - ERROR - telegram.ext.updater - Error while getting Updates: Conflict: terminated by other getUpdates request; make sure that only one bot instance is running (409)
2021-05-19 17:02:39,770 - ERROR - root - Conflict: terminated by other getUpdates request; make sure that only one bot instance is running (409) - Class: TelegramBot - None
2021-05-19 17:03:14,544 - ERROR - telegram.ext.updater - Error while getting Updates: Conflict: terminated by other getUpdates request; make sure that only one bot instance is running (409)
2021-05-19 17:03:14,545 - ERROR - root - Conflict: terminated by other getUpdates request; make sure that only one bot instance is running (409) - Class: TelegramBot - None
